File: CouponData/1-0T-2.txt
File Path: C:\Users\MTS\Desktop\SE171\Test Run 9 2-3-2017 3 06 01 PM\DAQ- Crosshead, … - (Timed).txt
Test: MTS EM Tension (Extensometer-Crosshead) 171-2017-W
Test Run: Test Run 9
Date: 2/3/2017 1:20:20 PM


Crosshead 	Load 	Time 	Extensometer
in	lbf	sec	in
0.000274344744157563	6.82657348977267	0.230000004172325	-8.72827832057465E-05
0.000801930768579413	19.6434103446887	0.629999995231628	-7.43913123577961E-06
0.00133655130483694	32.4601082719587	1.02999997138977	7.43579235630051E-05
0.00187117176948071	45.0567602446774	1.42999994754791	0.000149565696520717
0.00240110267892363	57.5610716421505	1.83000004291534	0.000226307060160696
0.00293337822273946	69.9769907537685	2.23000001907349	0.000300939300216232
0.00347034360821117	82.2490700124497	2.63000011444092	0.000377783868230392
0.00400027451765409	94.30261093881	3.02999997138977	0.000452603807940524
0.00453255034792492	106.233868094363	3.4300000667572	0.000526349433889342
0.0050671705261137	118.203551607652	3.82999992370605	0.000600809765123492
0.00559710143555661	129.89025494284	4.23000001907349	0.000669993451584724
0.00613172218665539	141.732255373853	4.63000011444092	0.00074286617746111
0.00666634236484413	153.415693051786	5.03000020980835	0.000815199508526965
0.00719627327428705	165.086040658203	5.42999982833862	0.000887093131130701
0.00773089402538587	176.415387785256	5.82999992370605	0.000960018851186559
0.00826316985565669	187.772218573992	6.23000001907349	0.00103304432920459
0.00879310076509961	198.927786082858	6.63000011444092	0.00110195165818124
0.00932772094328835	210.167711830383	7.03000020980835	0.00117141893511642
0.00985999620064917	221.157993174175	7.42999982833862	0.00124198677225449
0.01039227203092	232.010375965834	7.82999992370605	0.00131335560925393
0.0109268933549289	242.905020204317	8.22999954223633	0.00138556691047948
0.0114591691851997	253.726255760817	8.63000011444092	0.00145687086541594
0.0119890995217326	264.241068385352	9.02999973297119	0.00152800738739077
0.0125237196999213	275.068999911349	9.43000030517578	0.00159578765907479
0.0130559955301922	285.563066007446	9.82999992370605	0.00166996719277148
0.0135859270125452	295.881856869216	10.2299995422363	0.00174131211077641
0.0141205471907339	306.186953924518	10.6300001144409	0.0018092840208716
0.0146575128626606	316.61268820075	11.0299997329712	0.00188164184384202
0.0151850988512756	326.679803913942	11.4300003051758	0.00195120200381878
0.0157197190294644	336.769943882904	11.8299999237061	0.00202430102916427
0.0162519948597352	346.7971033191	12.2299995422363	0.00209348263882658
0.0167819251962681	356.683345528389	12.6300001144409	0.00215651935853768
0.0173165465202769	366.489922166169	13.0299997329712	0.00222840782495098
0.0178511666984657	376.299627248712	13.4300003051758	0.00229561762145434
0.0183810970349985	385.824671300156	13.8299999237061	0.00236554587613718
0.0189157183590074	395.390741886013	14.2299995422363	0.00242850553944678
0.0194479930434582	404.747590867602	14.6300001144409	0.00249678753710565
0.019977923379991	413.902023984405	15.0299997329712	0.00256232615499794
0.0205125447039998	423.071550475075	15.4300003051758	0.00262949412906777
0.0210471660280087	431.88558684747	15.8299999237061	0.00268902435282788
0.0215794407124594	440.335324059748	16.2299995422363	0.0027501564330832
0.0221140620364683	448.867608305824	16.6299991607666	0.00281121288921215
0.0226463367209191	457.051702138075	17.0300006866455	0.00286988747181503
0.02317861369701	464.860437483543	17.4300003051758	0.00292757664913473
0.0237108883814607	472.895436224504	17.8299999237061	0.00298818537606088
0.0242455097054696	480.578512371918	18.2299995422363	0.0030441985050341
0.0247777843899204	488.114167420417	18.6299991607666	0.00309803887264891
0.0253124057139292	495.7777045093	19.0300006866455	0.00315440090384158
0.02584468039838	503.136081021126	19.4300003051758	0.00320888951917611
0.026374613026553	510.43754179223	19.8299999237061	0.0032601990566523
0.0269115764068396	517.642624510579	20.2299995422363	0.00331400991939961
0.0274415090350126	524.786620228519	20.6299991607666	0.00336697058363517
0.0279737837194634	531.588737307161	21.0300006866455	0.00341918073570737
0.0285084050434722	538.535147039957	21.4300003051758	0.00346697461067178
0.029040679727923	545.588637399703	21.8299999237061	0.00351935004729294
0.0295729567040139	552.241083094596	22.2299995422363	0.00357496930060791
0.0301075757363826	559.17102732863	22.6299991607666	0.00362372910191386
0.0306375060729154	565.892957428299	23.0300006866455	0.00367299306406236
0.0311697830490064	572.641561635966	23.4300003051758	0.00372521811179582
0.0317044043730152	579.374907814777	23.8299999237061	0.00377301914813584
0.032236679057466	585.973291788735	24.2299995422363	0.00382067724341879
0.0327689537419168	592.591873441175	24.6299991607666	0.00387147946904714
0.0333035750659256	599.218193878035	25.0300006866455	0.0039193449577676
0.0338381963899344	605.768827905583	25.4300003051758	0.00397206127586752
0.0343681267264673	612.194763222505	25.8299999237061	0.00402201817271953
0.0349027480504761	618.622674399279	26.2299995422363	0.00406340404879303
0.0354350227349269	625.132528874891	26.6299991607666	0.00411656236699528
0.0359672974193777	631.60094517862	27.0300006866455	0.00416519784682071
0.0365019187433865	638.157012820761	27.4300003051758	0.00421606738937976
0.0370341957194775	644.39035668716	27.8299999237061	0.0042581673978285
0.0375664704039282	650.457399016064	28.2299995422363	0.00430956401763205
0.038103436075855	656.526142779839	28.6299991607666	0.00434958808652059
0.0386310220644699	662.459869453764	29.0300006866455	0.00439759537047803
0.0391632967489207	668.132563087312	29.4300003051758	0.00444058482177689
0.0397002647124878	673.869856361003	29.8299999237061	0.00448356682524512
0.0402325393969382	679.574053982183	30.2299995422363	0.00452501056523346
0.040764814081389	685.081763318134	30.6299991607666	0.00456424602344047
0.041299435405398	690.541942247658	31.0300006866455	0.00460885451853598
0.0418317100898488	695.869025062189	31.4300003051758	0.00464667317019335
0.0423639847742996	701.295833914222	31.8299999237061	0.00468615555263118
0.0428986060983083	706.756067728741	32.2299995422363	0.00472824868615937
0.0434332274223173	712.178485781104	32.6300010681152	0.00476908113112614
0.0439655021067681	717.787348164452	33.0299987792969	0.00480837101578772
0.0444977767912185	723.544674461638	33.4300003051758	0.00485367330495181
0.0450323981152276	729.074118255955	33.8300018310547	0.00489170250105197
0.0455623307434008	734.595658610867	34.2299995422363	0.00493633964164988
0.0460969520674095	740.386354985544	34.6300010681152	0.00497827780301
0.0466292267518602	746.047467884962	35.0299987792969	0.00502388889069016
0.047161501436311	751.820710830951	35.4300003051758	0.00506778411277547
0.0476984648165976	757.583306087741	35.8300018310547	0.00511437086626799
0.0482283974447705	763.327350215925	36.2299995422363	0.00515438863314598
0.0487606721292213	768.815959573312	36.6300010681152	0.00519985133712362
0.0492952934532303	774.624987536611	37.0299987792969	0.00524235667943161
0.0498252260814032	780.234398769918	37.4300003051758	0.00528339078873543
0.0503575007658539	785.756872169758	37.8300018310547	0.00532443120004976
0.050892122089863	791.433462638015	38.2299995422363	0.00536809553938559
0.0514267434138716	797.006046039089	38.6300010681152	0.0054142726621935
0.0519566714587642	802.544545857724	39.0299987792969	0.00545103171671646
0.0524912927827732	808.202420542386	39.4300003051758	0.00549664223148658
0.053023567467224	813.706233043632	39.8300018310547	0.00554248592064634
0.0535558421516748	819.2589480762	40.2299995422363	0.00558044235717035
0.0540904634756835	824.850411915854	40.6300010681152	0.00562142375874972
0.0546250847996925	830.345497702755	41.0299987792969	0.00564451890861925
0.0551573594841433	836.017971796319	41.4300003051758	0.00493136964698036
0.055691980808152	841.356251150006	41.8300018310547	0.00772449920342606
0.0562242554926028	847.04206229757	42.2299995422363	0.0878541976008126
0.0567565347603339	852.726611090227	42.6300010681152	0.101091783845753
0.0572911515010622	858.1927724843	43.0299987792969	0.123004429042339
0.0578210841292354	863.688901086123	43.4300003051758	0.235905144803637
0.0583533588136862	869.399410481827	43.8300018310547	0.224639276614574
0.0588903267772532	875.126659801274	44.2299995422363	0.161054217821266
0.0594226014617039	880.787882470686	44.6300010681152	0.190087850755594
0.0599548761461547	886.271387523456	45.0299987792969	0.187791260619332
0.0604871508306055	892.043203459552	45.4300003051758	0.198207058628478
0.0610194300983366	897.70420658898	45.8300018310547	0.196837922778186
0.061554046839065	903.190071696574	46.2299995422363	0.19380146285563
0.0620863261067961	909.044928631427	46.6300010681152	0.197081459964824
0.0626209428475244	914.658072044453	47.0299987792969	0.196546737808646
0.0631532221152559	920.338669117407	47.4300003051758	0.196918900176061
0.0636878388559843	925.867399406777	47.8300018310547	0.196171312145596
0.0642201181237154	931.447117857314	48.2299995422363	0.197000885895622
0.0647523928081662	937.074366714279	48.6300010681152	0.197382251490054
0.0652870141321748	942.743986788058	49.0299987792969	0.196962991333383
0.0658192888166256	948.168270930281	49.4300003051758	0.197099133093995
0.0663515635010764	953.870712231593	49.8300018310547	0.196884653905011
0.0668885314646433	959.440112302907	50.2299995422363	0.197277056038614
0.0674161174532583	964.949687728717	50.6300010681152	0.197357538442208
0.067948392137709	970.533357898958	51.0299987792969	0.197158129079135
0.0684830134617181	976.031846555602	51.4300003051758	0.197157670751097
0.0690129415066106	981.67369482147	51.8300018310547	0.197100434745625
0.0695475628306193	987.401602760867	52.2299995422363	0.197237328164221
0.0700821841546284	993.054757335884	52.6300010681152	0.197291649203366
0.0706144588390791	998.713400410489	53.0299987792969	0.197262334542012
0.0711467335235299	1004.30629126004	53.4300003051758	0.197179047170821
0.0716813548475386	1009.94265102632	53.8300018310547	0.197166452316318
0.0722136295319894	1015.52873613638	54.2299995422363	0.197219013375795
0.0727459087997205	1021.26718199498	54.6300010681152	0.197222606667618
0.0732805255404492	1026.99761464419	55.0299987792969	0.197296745811156
0.0738128048081803	1032.63386464048	55.4300003051758	0.197229609920049
0.0743427328530728	1038.30930252382	55.8300018310547	0.197168945620848
0.0748797008166398	1044.05971331152	56.2299995422363	0.197242314773282
0.0754096288615323	1049.68937710831	56.6300010681152	0.197218848377701
0.0759419081292634	1055.47678038323	57.0299987792969	0.197267156152979
0.07647887150955	1061.07680628224	57.4300003051758	0.197242461438254
0.0770087995544429	1066.61195811613	57.8300018310547	0.197237951490354
0.0775410742388937	1072.33558502585	58.2299995422363	0.197233184878751
0.0780780422024606	1078.0387947171	58.6300010681152	0.197193090341926
0.0786079702473532	1083.66450679418	59.0299987792969	0.197242974765657
0.0791402540983646	1089.26672809303	59.4300003051758	0.197231498231569
0.0796748662558126	1094.96796192443	59.8300018310547	0.19724383642237
0.0802071501068244	1100.5365936058	60.2299995422363	0.197251004672895
0.0807394247912752	1106.19490737043	60.6300010681152	0.197214595093502
0.0812740461152839	1111.78318788033	61.0299987792969	0.197235861514497
0.0818063207997347	1117.31844948421	61.4300003051758	0.197217785056651
0.0823409421237433	1123.05459017299	61.8300018310547	0.197246403059387
0.0828732168081941	1128.63156437373	62.2299995422363	0.19721529175212
0.083403144853087	1134.07220424472	62.6300010681152	0.19723696150179
0.0839354195375378	1139.69583069196	63.0299987792969	0.197226841618696
0.0844700408615465	1145.29135602131	63.4300003051758	0.197211790125905
0.0850023155459973	1150.9728312542	63.8300018310547	0.197235806515132
0.085534590230448	1156.59316460168	64.2300033569336	0.197229481588198
0.0860715581940149	1162.13600033499	64.629997253418	0.19723672317121
0.0866014862389075	1167.69069122741	65.0299987792969	0.197217620058557
0.0871337609233583	1173.33210041331	65.4300003051758	0.197237951490354
0.0876683822473673	1178.93959067176	65.8300018310547	0.197236099845077
0.088203003571376	1184.54697116022	66.2300033569336	0.197221396681596
0.088737624895385	1190.12515283087	66.629997253418	0.19723032491179
0.0892698995798358	1195.76392753697	67.0299987792969	0.197217601725436
0.0898021742642866	1201.27558859263	67.4300003051758	0.197231149902259
0.0903344489487374	1206.89789779996	67.8300018310547	0.19721457676038
0.0908690702727461	1212.44380709304	68.2300033569336	0.197229389922591
0.0914013449571969	1217.94723539931	68.629997253418	0.197219746700657
0.0919336288082083	1223.55143255801	69.0299987792969	0.197232946548171
0.0924682409656563	1228.98296151969	69.4300003051758	0.197233221544994
0.0929981781771098	1234.38781637337	69.8300018310547	0.197213421773723
0.0935304528615606	1239.92637107701	70.2300033569336	0.197236154844442
0.0940674208251276	1245.35954658856	70.629997253418	0.197198883608335
0.0945973488700201	1250.60962575388	71.0299987792969	0.197228968260795
0.0951319701940291	1255.76047284666	71.4300003051758	0.197224751642839
0.0956665915180378	1261.28091550165	71.8300018310547	0.197226383290657
0.0961965195629307	1266.69883298435	72.2300033569336	0.197226071627591
0.0967311408869394	1272.14419296499	72.629997253418	0.197220003364358
0.0972657622109484	1277.73038784504	73.0299987792969	0.197220296694303
0.097795690255841	1283.08946861217	73.4300003051758	0.197212688448861
0.0983303115798496	1288.59904403798	73.8300018310547	0.197204933538446
0.0988625862643004	1293.88622546051	74.2300033569336	0.197219160040767
0.0993948609487512	1299.13915864561	74.629997253418	0.197226621621237
0.0999294822727602	1304.53797614975	75.0299987792969	0.197219160040767
0.100461756957211	1309.94447755331	75.4300003051758	0.197214796757839
0.100994031641662	1315.18654350923	75.8300018310547	0.197217125064276
0.10152865296567	1320.43256118485	76.2300033569336	0.197203943549883
0.102060927650121	1325.65234383245	76.629997253418	0.197220315027425
0.102593211501133	1329.84489889727	77.0299987792969	0.197218646713364
0.103127823658581	1335.18301359597	77.4300003051758	0.197217308395491
0.10366244498259	1340.50367486598	77.8300018310547	0.197214173431706
0.104192382194043	1345.75177817145	78.2300033569336	0.19722026002806
0.104727003518052	1351.08495322052	78.629997253418	0.197216391739413
0.105261624842061	1356.42054320941	79.0299987792969	0.197208050169109
0.105789206247395	1361.61101726921	79.4300003051758	0.197208618495877
0.106323827571404	1366.83453209653	79.8300018310547	0.197209516818833
0.106858448895413	1372.21073698237	80.2300033569336	0.197209810148778
0.107390723579864	1377.34314271653	80.629997253418	0.197205831861402
0.107925344903873	1382.55238744492	81.0299987792969	0.197218371716541
0.108457619588324	1387.88984352367	81.4300003051758	0.197210965135435
0.108989894272774	1392.92257810533	81.8300018310547	0.197208251833446
0.109522168957225	1398.10317286587	82.2300033569336	0.197208270166568
0.110056790281234	1403.32471183333	82.629997253418	0.197210763471098
0.110589064965685	1408.40739176124	83.0299987792969	0.197223303326237
0.111123686289693	1413.70203754321	83.4300003051758	0.197216648403115
0.111655960974144	1418.71995317598	83.8300018310547	0.197212780114468
0.112188235658595	1423.80801183348	84.2300033569336	0.197207555174828
0.112720510343046	1428.98663073417	84.629997253418	0.197216520071264
0.113257478306613	1433.94263609159	85.0299987792969	0.197210726804855
0.113787406351505	1438.93925634597	85.4300003051758	0.197207573507949
0.114322027675514	1444.06628335054	85.8300018310547	0.19720343022248
0.114856648999523	1448.90713998662	86.2300033569336	0.197198663610877
0.115384239571419	1453.96819522615	86.629997253418	0.197208618495877
0.115918860895427	1458.99456314828	87.0299987792969	0.197201138582286
0.116453482219436	1464.10578327404	87.4300003051758	0.197206913515573
0.116983410264329	1468.9443347403	87.8300018310547	0.197205721862673
0.117518031588337	1473.89979124777	88.2300033569336	0.197204585209137
0.118052652912346	1478.98170278573	88.629997253418	0.197200185259965
0.118584927596797	1484.10444876062	89.0299987792969	0.197198553612148
0.119117202281248	1488.9107278493	89.4300003051758	0.197203411889358
0.119651823605257	1494.11700878791	89.8300018310547	0.197197710288557
0.120184098289707	1498.82603166391	90.2300033569336	0.197207793505408
0.120718719613717	1503.98708736592	90.629997253418	0.197198553612148
0.121250994298167	1508.88656117759	91.0299987792969	0.197203503554966
0.121783268982618	1513.63993113025	91.4300003051758	0.197197380292369
0.122317890306627	1518.49154522553	91.8300018310547	0.197195711978308
0.122852511630635	1523.30419097373	92.2300033569336	0.197201486911595
0.123382439675528	1528.22133775408	92.629997253418	0.197195656978943
0.123917060999537	1533.14693682379	93.0299987792969	0.197191880355904
0.124451682323546	1537.86496083911	93.4300003051758	0.197194300327949
0.124981610368439	1542.37321440019	93.8300018310547	0.197198626944634
0.125516231692447	1547.12812113274	94.2300033569336	0.197192265351457
0.126050853016456	1551.9865409675	94.629997253418	0.197193438671236
0.126583127700907	1556.7220184115	95.0299987792969	0.197198278615324
0.127115402385358	1561.55804516795	95.4300003051758	0.197203100226291
0.127650023709367	1566.13238026407	95.8300018310547	0.197196793632479
0.128182298393817	1570.42043522171	96.2300033569336	0.197195400315242
0.128714582244829	1575.20102813232	96.629997253418	0.197194831988474
0.129249194402277	1579.65318922762	97.0299987792969	0.197185683760821
0.129781478253289	1584.28032368977	97.4300003051758	0.197180623819274
0.130316090410737	1588.71064055672	97.8300018310547	0.197194245328584
0.130848374261748	1592.78727851025	98.2300033569336	0.197185408763998
0.131380648946199	1596.67269713816	98.629997253418	0.197179322167645
0.13191292363065	1601.31739479899	99.0299987792969	0.197191733690932
0.132447544954659	1605.91401320343	99.4300003051758	0.197203540221209
0.132979819639109	1610.69317910415	99.8300018310547	0.197188818724606
0.133514440963118	1615.23293665287	100.230003356934	0.197179945493777
0.134049062287127	1619.91638312079	100.629997253418	0.197203888550518
0.134576643692461	1624.42672231172	101.029998779297	0.197186362086319
0.13511126501647	1629.14738080684	101.430000305176	0.197188653726512
0.135645886340479	1633.69010214533	101.830001831055	0.197195473647728
0.13617816102493	1637.96531401394	102.230003356934	0.197193090341926
0.136712782348939	1641.66708744565	102.629997253418	0.19717536221339
0.13724505703339	1645.66732548493	103.029998779297	0.197178240513473
0.13777733171784	1639.89254575906	103.430000305176	0.197193292006264
0.138311953041849	1641.96653998314	103.830001831055	0.197186270420711
0.1388442277263	1646.1133209614	104.230003356934	0.197190945366706
0.139376502410751	1650.63836933123	104.629997253418	0.197193017009441
0.139911123734759	1655.47527424761	105.029998779297	0.197185537095849
0.14044339841921	1660.0099823767	105.430000305176	0.197184693772258
0.140975673103661	1664.52504167728	105.830001831055	0.197192045353998
0.14151029442767	1669.09257103391	106.230003356934	0.197180917149219
0.14204256911212	1673.69039690826	106.629997253418	0.197182438798307
0.142574852963132	1678.07911094833	107.029998779297	0.197188378729689
0.143109474287141	1682.53291859351	107.430000305176	0.197188947056457
0.143644086444589	1687.04742904413	107.830001831055	0.197169330616401
0.144174023656043	1691.22516516006	108.230003356934	0.197171273927285
0.144708644980052	1695.71036702288	108.629997253418	0.197169642279467
0.14524326630406	1699.88722497888	109.029998779297	0.197176352201954
0.145775540988511	1703.68823048314	109.430000305176	0.197164050677395
0.146314846425075	1585.72171345141	109.830001831055	0.197193677001816
0.146847121109526	1589.37782256656	110.230003356934	0.197166323984467
0.147379395793977	1596.10957708049	110.629997253418	0.197160769048638
0.147914017117985	1603.38513213355	111.029998779297	0.197164875667865
0.148448638441994	1611.03083159877	111.430000305176	0.197174078894882
0.148980913126445	1618.3226326106	111.830001831055	0.197166525648804
0.149515534450454	1625.85098795465	112.230003356934	0.197165003999716
0.150047809134905	1633.2236894504	112.629997253418	0.197167277306788
0.150577746346358	1640.15171270957	113.029998779297	0.197169862276926
0.151112367670367	1647.20399559941	113.430000305176	0.19715178581908
0.151646979827815	1653.96297307129	113.830001831055	0.197163940678666
0.152179263678827	1660.48067610132	114.230003356934	0.19717109059607
0.152711538363278	1666.72867426162	114.629997253418	0.1971681389635
0.153246159687286	1672.75087554889	115.029998779297	0.197179688830075
0.153776087732179	1678.64036491614	115.430000305176	0.19716126404292
0.154310709056188	1684.46563883822	115.830001831055	0.197174903885352
0.154845321213636	1690.1950835575	116.230003356934	0.197174867219108
0.155375258425089	1695.76272730895	116.629997253418	0.197145809221455
0.155909870582537	1701.37394974712	117.029998779297	0.197162767358887
0.156442154433549	1707.02128651257	117.430000305176	0.197178552176539
0.156974438284561	1712.35468110163	117.830001831055	0.197149512512008
0.157509050442009	1717.93747311193	118.230003356934	0.197146982541235
0.15804133429302	1723.39073653198	118.629997253418	0.19717132892665
0.158575946450468	1728.77308853735	119.029998779297	0.197151712486594
0.15910823030148	1733.94984134818	119.430000305176	0.197164802335379
0.15964049581937	1739.219898652	119.830001831055	0.197145130895958
0.160172779670381	1744.54549957164	120.230003356934	0.197155452443389
0.160707391827829	1749.80798274603	120.629997253418	0.197144195906759
0.161242022318399	1754.86212247608	121.029998779297	0.197169348949522
0.161774287836289	1759.96489031247	121.430000305176	0.197171548924108
0.162308918326858	1765.04910702026	121.830001831055	0.197148742520903
0.162841183844748	1769.96570495065	122.230003356934	0.197158074079771
0.163371121056202	1774.8655080723	122.629997253418	0.197161190710434
0.163908079853208	1779.77541003319	123.029998779297	0.197161649038472
0.16444036370422	1784.62109654891	123.430000305176	0.197154939115986
0.164972629222109	1789.42638770766	123.830001831055	0.197163317352533
0.165507259712679	1794.22750760673	124.230003356934	0.197150850829881
0.166037178591011	1798.32094036901	124.629997253418	0.197153454133141
0.166571809081581	1802.93117025243	125.029998779297	0.197152354145848
0.167104074599471	1807.58936962224	125.430000305176	0.197156974092478
0.167636358450482	1812.21112535479	125.830001831055	0.197157267422423
0.16817097060793	1816.86065289526	126.230003356934	0.197156589096925
0.168703254458942	1821.37856621562	126.629997253418	0.197136752659411
0.169233191670395	1825.66288899354	127.029998779297	0.197138329307864
0.169767803827843	1830.11537939882	127.430000305176	0.197167955632285
0.170302434318413	1834.6183640003	127.830001831055	0.197159027402091
0.170837046475861	1838.89456379883	128.229995727539	0.197139557627008
0.171366983687315	1843.49831725274	128.630004882813	0.197133617695626
0.171901595844763	1847.73104813454	129.029998779297	0.197145680889605
0.172433879695774	1851.87925612269	129.429992675781	0.197142582592063
0.172963798574106	1856.14535708198	129.830001831055	0.19715581910582
0.173500775704234	1859.58576816335	130.229995727539	0.197135029345985
0.174035387861682	1863.24615830817	130.630004882813	0.197141335939798
0.174565325073135	1867.45627657167	131.029998779297	0.197140015955046
0.175099937230583	1871.31161822184	131.429992675781	0.197132059380295
0.175632221081595	1874.19066556541	131.830001831055	0.1971449108985
0.176164486599485	1875.90417513659	132.229995727539	0.197143334250046
0.176699117090054	1878.00605093858	132.630004882813	0.19712501946162
0.177231382607945	1873.47057441954	133.029998779297	0.197143664246234
0.177773053017188	1752.95816196921	133.429992675781	0.19711209461093
0.178307665174636	1759.57751201159	133.830001831055	0.197118584535957
0.178839949025648	1766.65570061948	134.229995727539	0.197146322548859
0.179372214543538	1773.92444993304	134.630004882813	0.197124451134852
0.179906845034107	1781.28430833976	135.029998779297	0.197128392755985
0.180439110551997	1788.55470420319	135.429992675781	0.197122471157726
0.180971394403009	1795.79919434858	135.830001831055	0.197147569201124
0.181506006560457	1802.95367310073	136.229995727539	0.197119996186317
0.182038290411468	1809.90299173831	136.630004882813	0.197133342698803
0.182570555929359	1816.86899541463	137.029998779297	0.197142655924549
0.183105186419928	1823.65519584447	137.429992675781	0.197143040920102
0.183637451937818	1830.14842016634	137.830001831055	0.197101864729106
0.18416973578883	1836.34647298039	138.229995727539	0.19711517457535
0.184704347946278	1842.39908055538	138.630004882813	0.197138842635267
0.185236631797289	1848.27023833401	139.029998779297	0.197139172631455
0.185768897315179	1854.0979271959	139.429992675781	0.19712868608593
0.186303527805749	1859.84745982367	139.830001831055	0.19711695288814
0.186835793323639	1865.28744107472	140.229995727539	0.197119574524521
0.18736807717465	1870.82072681875	140.630004882813	0.197131857715958
0.187902689332098	1876.26751380928	141.029998779297	0.197124341136123
0.18843497318311	1881.69520082124	141.429992675781	0.197116512893222
0.188967238701	1886.98018684394	141.830001831055	0.197121169506096
0.18950186919157	1892.38745663744	142.229995727539	0.197126449445101
0.190034153042581	1897.72403455626	142.630004882813	0.197128777751538
0.190566418560471	1902.88278508844	143.029998779297	0.197123607811261
0.191101049051041	1908.07754017792	143.429992675781	0.19711482624604
0.191633314568931	1913.17152641497	143.830001831055	0.197108959647145
0.192163251780384	1918.46924575671	144.229995727539	0.197139887623196
0.19270021057739	1923.52920329632	144.630004882813	0.197132957703251
0.193232494428402	1928.64448491177	145.029998779297	0.197104504698609
0.193764759946292	1933.63923907629	145.429992675781	0.197132462708969
0.194299390436861	1938.57625422514	145.830001831055	0.197135744337726
0.194829309315193	1943.53127165264	146.229995727539	0.197110426296869
0.195363939805763	1948.46301784189	146.630004882813	0.19710356970941
0.195898551963211	1953.3607353337	147.029998779297	0.197117209551841
0.196428489174665	1958.2318884875	147.429992675781	0.1971273844343
0.19696544797167	1963.02510494717	147.830001831055	0.197140070954411
0.197497731822682	1967.91074773988	148.229995727539	0.197075923362116
0.198027650701014	1972.51340349387	148.630004882813	0.197129437743913
0.198562281191584	1977.08400641027	149.029998779297	0.197110737959935
0.199096893349032	1981.68029550474	149.429992675781	0.197112149610294
0.199631523839602	1986.31215007653	149.830001831055	0.197106099680183
0.200163789357491	1991.081436678	150.229995727539	0.197099096427752
0.200696073208503	1995.5629063611	150.630004882813	0.197122361158996
0.201228338726393	2000.14558397659	151.029998779297	0.197090094865072
0.201760622577404	2004.67820647584	151.429992675781	0.197115082909742
0.202295234734852	2009.29974266841	151.830001831055	0.197110572961841
0.202827518585864	2013.9171076013	152.229995727539	0.197111471284797
0.203359802436876	2018.37750144598	152.630004882813	0.197107896326095
0.203894414594324	2022.96369170121	153.029998779297	0.197097391447448
0.204426698445335	2027.3149741741	153.429992675781	0.197107529663664
0.204958963963225	2031.78371053815	153.830001831055	0.197110591294963
0.205493594453795	2036.32862727648	154.229995727539	0.197107987991703
0.206025859971685	2040.6289764732	154.630004882813	0.19709563146778
0.206560490462254	2045.17586907138	155.029998779297	0.197101663064769
0.207092755980144	2049.37018045607	155.429992675781	0.197111599616648
0.207625039831156	2053.74166060744	155.830001831055	0.197106503008857
0.208157305349046	2058.19678549252	156.229995727539	0.197089984866343
0.208691935839615	2062.6692540363	156.630004882813	0.197091854844741
0.209226547997063	2066.79902066584	157.029998779297	0.19708378827126
0.209758831848075	2071.17818471663	157.429992675781	0.197114459583609
0.210291097365965	2075.6254061623	157.830001831055	0.197093706490017
0.210823381216977	2080.04781958984	158.229995727539	0.197091323184216
0.211355646734867	2084.36551244525	158.630004882813	0.197095998130211
0.211892623864994	2088.7466523559	159.029998779297	0.197098381436012
0.212422542743326	2093.02285215443	159.429992675781	0.197082688283967
0.212954826594338	2097.25931521594	159.830001831055	0.197074878374188
0.213489438751786	2101.51948859568	160.229995727539	0.197089929866978
0.214019375963239	2105.62905754674	160.630004882813	0.197104908027283
0.214556334760245	2110.02095491657	161.029998779297	0.197092221507172
0.215088618611257	2114.19967896243	161.429992675781	0.197087399896205
0.215620902462269	2118.50156493903	161.830001831055	0.197095484802807
0.216155514619717	2122.6229890492	162.229995727539	0.197091414849824
0.216687798470728	2126.922240546	162.630004882813	0.197081808294133
0.217220063988618	2131.14531166852	163.029998779297	0.197085658249658
0.21775234783963	2135.41119308783	163.429992675781	0.197093816488746
0.218289306636636	2139.58969759371	163.830001831055	0.197096603123222
0.218821590487647	2143.63603902952	164.229995727539	0.197082468286509
0.219353856005537	2146.22134187516	164.630004882813	0.197091414849824
0.219888486496107	2150.26373159127	165.029998779297	0.197078160002945
0.220418405374439	2154.11116980204	165.429992675781	0.197086299908912
0.22095068922545	2157.46266719008	165.830001831055	0.197080928304299
0.221487648022456	2160.65016821046	166.229995727539	0.197089324873967
0.222019931873468	2164.2172538623	166.630004882813	0.197090406528139
0.222645989641195	38.5434342930748	166.979995727539	0.197221635012176