File: CouponData/1-0T-1.txt
File Path: C:\Users\MTS\Desktop\SE171\Test Run 8 2-3-2017 3 05 56 PM\DAQ- Crosshead, … - (Timed).txt
Test: MTS EM Tension (Extensometer-Crosshead) 171-2017-W
Test Run: Test Run 8
Date: 2/3/2017 1:11:59 PM


Crosshead 	Load 	Time 	Extensometer
in	lbf	sec	in
0.00012896547144289	-1.35802481277209	0.239999994635582	-7.16927102111524E-05
0.00052758602442185	7.95858767818772	0.839999973773956	-2.40699009280462E-06
0.00092620655949737	17.2884855540668	1.44000005722046	6.33631173077161E-05
0.0013271719079802	26.4056534738286	2.03999996185303	0.000126311295561187
0.00172344777287593	35.272710467393	2.64000010490417	0.00018617915132589
0.00212206827214457	44.2726731936221	3.24000000953674	0.000246951497781162
0.00252303369224115	53.1908092516278	3.83999991416931	0.000303510699547666
0.00292399911233774	62.2021125901294	4.44000005722046	0.000366760291148611
0.00332261961160638	70.9080666843986	5.03999996185303	0.000429090755997595
0.00372124011087503	79.5694198588957	5.6399998664856	0.000490549108525465
0.00412220553097161	88.1788175241738	6.23999977111816	0.000547896509194437
0.00452082603024024	96.9017928277884	6.84000015258789	0.000606831407800543
0.00491944681596394	105.377634716231	7.44000005722046	0.00066362455380461
0.00531806731523256	113.831419696958	8.03999996185303	0.000726615369098087
0.00571903273532913	122.204901068096	8.64000034332275	0.000781736548739764
0.00611999815542575	130.439640030289	9.23999977111816	0.000842466589368654
0.00651861865469437	138.704661788956	9.84000015258789	0.000896667818700177
0.00691723915396303	146.715634622971	10.4399995803833	0.000955089533130461
0.00731820457405961	154.703322497487	11.039999961853	0.0010114855092435
0.00771916999415618	162.665447685174	11.6400003433228	0.00106669663576277
0.00811544557259689	170.403930235924	12.2399997711182	0.00112388236837748
0.00851641099269346	177.993468629122	12.8400001525879	0.00117551431098337
0.00891503149196213	185.669972298281	13.4399995803833	0.00123447692411306
0.0093159969120587	193.247271337398	14.039999961853	0.00128605644544953
0.0097146179842374	200.787029039338	14.6400003433228	0.00134122224046123
0.010113238483506	208.239533319086	15.2399997711182	0.00139528804818007
0.0105142033306926	215.531183397178	15.8400001525879	0.00144770401818715
0.0109151693236992	222.86685124196	16.4400005340576	0.0014987786625435
0.0113137898229679	230.11768060437	17.0400009155273	0.00155240261338754
0.0117124103222365	237.169702790475	17.6399993896484	0.00160724328194679
0.012113375169423	244.20831931634	18.2399997711182	0.00165250704291013
0.0125119956686917	251.220151964215	18.8400001525879	0.00170184448077233
0.0129106161679603	258.02369605275	19.4400005340576	0.00175383062501563
0.013309236667229	264.780560452295	20.0400009155273	0.00180603719640002
0.0137102026602356	271.479713278678	20.6399993896484	0.00185314887872435
0.0141111675074221	278.079826130007	21.2399997711182	0.00190306739060311
0.0145097880066908	284.498159874999	21.8400001525879	0.00195018394266285
0.0149084085059594	290.70425334095	22.4400005340576	0.00199450297495644
0.0153093744989661	297.034057587599	23.0400009155273	0.00204182348299339
0.0157103393461526	303.168800558912	23.6399993896484	0.00208215763944561
0.0161089598454212	308.783837504295	24.2399997711182	0.00213165749730652
0.0165075803446899	314.352084990694	24.8400001525879	0.00216905133616304
0.0169085463376965	319.766599603651	25.4400005340576	0.00221187693518806
0.017309511184883	324.899005337816	26.0400009155273	0.00225256042354227
0.0177081316841517	329.669773834169	26.6399993896484	0.00228492568767681
0.0181067521834203	334.243532637831	27.2399997711182	0.00231927035602844
0.018507718176427	338.090806193607	27.8400001525879	0.00235193997862617
0.0189086830236135	341.080611458844	28.4400005340576	0.00237308078909322
0.0193073046687022	342.909599061348	29.0400009155273	0.00238912756986528
0.0197059240221508	344.282272808156	29.6399993896484	0.00239478749146054
0.0201068900151574	345.651872995194	30.2399997711182	0.00240406920715404
0.0205078560081641	347.233878116265	30.8400001525879	0.00242308237292899
0.0209064753616126	349.180511707425	31.4400005340576	0.00243467377548245
0.0213050970067013	351.451186314225	32.0400009155273	0.00245349215184096
0.0217060607080678	353.933634677604	32.6399993896484	0.00247371415781796
0.0221070267010744	356.908209356486	33.2400016784668	0.00249345377353423
0.0225056483461632	359.992444257124	33.8400001525879	0.0025148387869094
0.0229066120475296	363.40181787332	34.439998626709	0.00254070166522256
0.0233052336926183	367.027740240736	35.0400009155273	0.0025647885223858
0.023706199685625	370.962884674907	35.6399993896484	0.00258917443859428
0.0241048190390735	374.659032394545	36.2400016784668	0.00261996377041329
0.0245034406841622	378.798760650837	36.8400001525879	0.00264738811506325
0.0249044066771689	383.081738746359	37.439998626709	0.00267924449184733
0.0253053703785353	387.442077243564	38.0400009155273	0.00271257983592126
0.0257039920236241	391.880215222421	38.6399993896484	0.00274674790475048
0.0261026113770726	396.317200616366	39.2400016784668	0.00277418055659615
0.0265035773700793	400.875536736187	39.8400001525879	0.00280769779961043
0.0269045433630859	405.536151045819	40.439998626709	0.00284248718938709
0.0273031627165344	410.14638092924	41.0400009155273	0.00287886926909821
0.0277017843616231	414.607872473841	41.6399993896484	0.00290981500536042
0.0281004037150717	419.363026188869	42.2400016784668	0.00294408734381844
0.0285037140559963	423.811455104452	42.8400001525879	0.00297820786111365
0.0288999913531671	428.641801263825	43.439998626709	0.00301492537965807
0.0293009550545335	433.165010986286	44.0400009155273	0.00304819684426161
0.0296995766996223	437.734324105282	44.6399993896484	0.00307988994168191
0.0301028870405468	442.456409610293	45.2400016784668	0.00311700219524966
0.0305015063939954	447.005332953323	45.8400001525879	0.00315018571816077
0.0309001280390841	451.688312898775	46.439998626709	0.00318153764764727
0.0313010940320907	456.183256848361	47.0400009155273	0.00321706150810594
0.0316997133855393	460.863327889032	47.6399993896484	0.00325513166727454
0.032098335030628	465.579430929492	48.2400016784668	0.00328631401538673
0.0324992987319945	470.161614580022	48.8400001525879	0.00332376371297296
0.0329002647250011	474.798244146457	49.439998626709	0.00335665533821443
0.0333012307180077	479.52444602616	50.0400009155273	0.0033935687919954
0.0336998500714563	484.240439296628	50.6399993896484	0.00342808576304407
0.034098471716545	488.970922206009	51.2400016784668	0.00346407454000698
0.0344994377095516	493.79449006839	51.8400001525879	0.00350057292045791
0.0349004014109181	498.489407500445	52.439998626709	0.00353326288136235
0.0352966787080889	503.325379371894	53.0400009155273	0.0035747524541546
0.0356976424094554	508.156082283741	53.6399993896484	0.00360815883907453
0.0360962640545441	513.141999963917	54.2400016784668	0.00364428797899929
0.0364995743954686	518.011232142868	54.8400001525879	0.003676447998109
0.0368981937489172	522.840947124787	55.439998626709	0.00371380774881764
0.0372968153940059	527.830706754677	56.0400009155273	0.00375325919411285
0.0376954347474545	532.833693668571	56.6399993896484	0.00379190713306522
0.038098745088379	537.778228061859	57.2400016784668	0.00382923250917096
0.0384973644418275	542.740490308814	57.8400001525879	0.0038648626444436
0.0388959860869163	547.636561250746	58.439998626709	0.00390092389452763
0.039294607732005	552.728406972962	59.0400009155273	0.00394184485409689
0.0396979180729295	557.956312599947	59.6399993896484	0.00397632630472256
0.0400965397180181	563.019508354314	60.2400016784668	0.00401195357544496
0.0404951567798268	567.918268661045	60.8400001525879	0.00405229045321988
0.0408961250644736	573.050125545251	61.439998626709	0.0040922606685639
0.0412970887658398	578.128634213468	62.0400009155273	0.00413073959905201
0.0416957104109287	583.35752777038	62.6399993896484	0.00417027869958461
0.0420943320560173	588.422589614606	63.2400016784668	0.00420653559845016
0.0424929537011063	593.466904930395	63.8400001525879	0.00424591457062421
0.0428939174024724	598.896842227191	64.4400024414063	0.00428534854216295
0.0432925390475614	603.881168242489	65.0400009155273	0.0043222771780602
0.0436911561093697	609.016318226447	65.6399993896484	0.00436000588284
0.0440921243940165	614.250590512954	66.2399978637695	0.00440119152685158
0.0444930880953831	619.40626748537	66.8399963378906	0.00443996951638492
0.0448917097404717	624.591472585566	67.4400024414063	0.00447916773543878
0.0452926734418382	629.751320817668	68.0400009155273	0.00452183549774547
0.0456912950869268	634.965066115718	68.6399993896484	0.00455739430571709
0.0460922587882933	640.105320404294	69.2399978637695	0.00459494569483689
0.0464908804333819	645.320712252221	69.8399963378906	0.00463515280848591
0.0468895020784709	650.476114799656	70.4400024414063	0.00467392564182882
0.0472881237235595	655.714942540822	71.0400009155273	0.00471324875527319
0.0476914340644839	660.983243524771	71.6399993896484	0.00475113157285598
0.0480900511262925	666.114332019035	72.2399978637695	0.00479378128849614
0.0484886727713811	671.298713844291	72.8399963378906	0.00482940712694342
0.0488849477769118	676.39956070583	73.4400024414063	0.00487290073908484
0.0492882581178362	681.663196465129	74.0400009155273	0.00491133326385905
0.0496868797629252	686.999335303978	74.6399993896484	0.00494653400305043
0.0500855014080138	692.182180349352	75.2399978637695	0.00498993079339366
0.0504841230531024	697.470569241791	75.8399963378906	0.00503075120724945
0.0508850867544689	702.802207510979	76.4400024414063	0.00507224994660244
0.0512837083995579	707.924185095928	77.0400009155273	0.00511022013296764
0.051684672100924	713.357799687449	77.6399993896484	0.00515013248439673
0.052083293746013	718.585321119462	78.2399978637695	0.00518912646101831
0.0524842574473791	723.87387466689	78.8399963378906	0.00522676894283583
0.052885225732026	729.183010087769	79.4400024414063	0.00526959339604075
0.0532815007375567	734.467282605516	80.0400009155273	0.00530857362282118
0.0536824644389232	739.636900366884	80.6399993896484	0.00535222764977614
0.0540857747798476	745.097079296408	81.2399978637695	0.00539000877582536
0.0544843964249366	750.3102757445	81.8399963378906	0.00542726282463004
0.0548830180700252	755.634230114265	82.4400024414063	0.00546879364694579
0.0552839817713917	760.996274671167	83.0400009155273	0.0055113574260787
0.0556872921123161	766.236913617195	83.6399993896484	0.00555284356141067
0.0560835671178469	771.457574424726	84.2399978637695	0.00559491864827232
0.0564845308192134	776.670002482875	84.8399963378906	0.0056320604067076
0.056883152464302	782.052244718258	85.4400024414063	0.00567579234942909
0.0572841207489488	787.342225275578	86.0400009155273	0.00571768353216528
0.0576827378107571	792.466123835382	86.6399993896484	0.00575634121058847
0.0580837060954039	797.585192515551	87.2399978637695	0.00579815275882787
0.0584823277404929	802.740210868016	87.8399963378906	0.00583722465121606
0.0588457727086122	807.434908760085	88.4400024414063	0.00587458755292996
0.0588481193481701	804.401195498148	89.0400009155273	0.00585735269994512
0.058850461404448	802.282085807455	89.6399993896484	0.00584280422217705
0.058850461404448	800.434986156313	90.2399978637695	0.00583520227874536
0.058850461404448	798.875868078523	90.8399963378906	0.0058244900066611
0.058850461404448	797.517135120667	91.4400024414063	0.00581663655571815
0.058850461404448	796.255109525541	92.0400009155273	0.00493330722876394
0.058850461404448	795.04582841145	92.6399993896484	0.0347875404230312
0.058850461404448	794.025187028177	93.2399978637695	0.0845584981730134
0.058850461404448	792.98495170138	93.8399963378906	0.252676889388345
0.058850461404448	792.044771722059	94.4400024414063	0.241431517629173
0.058850461404448	791.175942237374	95.0400009155273	0.20163381237566
0.058850461404448	790.41364452968	95.6399993896484	0.215630490684838
0.058850461404448	789.565561573435	96.2399978637695	0.212310362372577
0.058850461404448	788.908533287829	96.8399963378906	0.213125434623459
0.058850461404448	788.208090970486	97.4400024414063	0.214638118815469
0.058850461404448	787.535146036074	98.0400009155273	0.215083485337224
0.058850461404448	786.953310194816	98.6399993896484	0.214523133477123
0.058850461404448	786.277895435591	99.2399978637695	0.213733635930799
0.0591928095329465	793.094721693127	99.8399963378906	0.213440580982861
0.059593773234313	800.79404379932	100.440002441406	0.213730830963202
0.0599923948794016	808.009115586918	101.040000915527	0.214155536056973
0.0603910165244906	814.772593628466	101.639999389648	0.214431027874468
0.0607919802258567	821.076245174581	102.23999786377	0.214454310938833
0.0611929439272232	827.332915164228	102.839996337891	0.214214642040842
0.0615915655723122	833.190022383913	103.440002441406	0.214047993965975
0.0619901872174008	839.177810778774	104.040000915527	0.213868531039146
0.0623911509187673	845.131735131181	104.639999389648	0.213889357465224
0.0627897725638559	851.007503249463	105.23999786377	0.214011914382769
0.0631883942089449	856.58508118516	105.839996337891	0.214079600267523
0.063589357910311	862.222648421349	106.440002441406	0.214198747224461
0.0639903216116776	867.81098381624	107.040000915527	0.214238145102666
0.0643889432567662	873.221436939503	107.639999389648	0.214176674146117
0.0647852182622969	878.664381980323	108.23999786377	0.214140282899845
0.0651861865469437	883.836853761476	108.839996337891	0.214063980447965
0.0655871502483102	889.11239956488	109.440002441406	0.21401204271462
0.0659881139496768	894.367143954847	110.040000915527	0.214024417571665
0.0663843935384878	899.483468385222	110.639999389648	0.214033107471278
0.0667853572398543	904.678662554667	111.23999786377	0.214070378707385
0.0671863209412205	909.657554955372	111.839996337891	0.214121693114596
0.0675849425863095	914.575085930691	112.440002441406	0.214131116339072
0.0679812175918402	919.492397366025	113.040000915527	0.21414721281979
0.0683821858764866	924.289016695433	113.639999389648	0.21413986123805
0.0687808029382953	929.048204457656	114.23999786377	0.214105486635148
0.0691817712229421	933.983133976666	114.839996337891	0.214091736793987
0.0695803928680307	938.618281648213	115.440002441406	0.214075566980782
0.069979009929839	943.21193626288	116.040000915527	0.21405492388592
0.0703823202707638	947.999554452965	116.639999389648	0.214064823771556
0.0707832885554106	952.525261442739	117.23999786377	0.214077473625423
0.0711819056172189	957.035490863677	117.839996337891	0.21408086525291
0.0715805272623075	961.58688403152	118.440002441406	0.214108786597027
0.0719814955469543	965.994478510174	119.040000915527	0.214112544886944
0.0723801126087626	970.57177739607	119.639999389648	0.214105816631336
0.0727810808934095	974.987275314129	120.23999786377	0.214116908169872
0.073182044594776	979.434826069779	120.839996337891	0.214102296671999
0.0735806662398646	983.681168430555	121.440002441406	0.214092763448794
0.0739816299412311	988.003800935596	122.040000915527	0.214091608462137
0.0743802515863201	992.38065981656	122.639999389648	0.214072010355202
0.0747812152876862	996.624257927543	123.23999786377	0.214077015297385
0.0751821835723331	1000.81648368239	123.839996337891	0.214091333465313
0.0755808006341413	1005.0583254735	124.440002441406	0.214082863563158
0.0759794222792303	1009.2138880511	125.040000915527	0.214090691806059
0.0763803905638772	1013.40852874576	125.639999389648	0.214105614966999
0.0767813542652437	1017.4705672904	126.23999786377	0.214099198374457
0.0771823225498902	1021.56740292241	126.839996337891	0.214105779965093
0.0775785929721406	1025.78191198558	127.440002441406	0.214103469991778
0.0779795566735071	1029.93088836368	128.039993286133	0.21409023347802
0.0783805295414342	1033.89226782587	128.639999389648	0.214090948469761
0.0787814932428008	1038.24047673899	129.240005493164	0.214095403418297
0.0791801103046091	1042.19164759196	129.839996337891	0.214083578554899
0.0795787365329783	1046.15829601376	130.440002441406	0.214074521992854
0.0799797002343445	1050.06226577027	131.039993286133	0.214089536819402
0.080380663935711	1054.01244869331	131.639999389648	0.214109739919347
0.0807792809975193	1057.74539680269	132.240005493164	0.21412541473827
0.0811779072258886	1061.88789675127	132.839996337891	0.214091791793352
0.0815788709272551	1065.90921062896	133.440002441406	0.214074411994125
0.0819798346286213	1069.97520089329	134.039993286133	0.214081396913435
0.0823784516904299	1074.11385889217	134.639999389648	0.214065447097688
0.0827770779187988	1078.08961822328	135.240005493164	0.214064732105948
0.0831780416201654	1082.26647617928	135.839996337891	0.214073825334235
0.0835790053215319	1086.1783493752	136.440002441406	0.214068288731528
0.0839752849103429	1090.05608410369	137.039993286133	0.214061982137716
0.0843762486117094	1094.13623469696	137.639999389648	0.214058040516583
0.0847772123130756	1098.22977722922	138.240005493164	0.214063063791887
0.0851781760144421	1102.31761172191	138.839996337891	0.214063962114843
0.0855744556032531	1106.33135147018	139.440002441406	0.214067922069097
0.0859754193046197	1110.36517912693	140.039993286133	0.214073367006197
0.0863763830059862	1114.40910562292	140.639999389648	0.214077986952827
0.0867773467073524	1118.40308677267	141.240005493164	0.21406806873407
0.0871736262961634	1122.39684838243	141.839996337891	0.214071442028434
0.0875745899975299	1126.36206979434	142.440002441406	0.214075621980147
0.0879755536988965	1129.58689261191	143.039993286133	0.21406806873407
0.0883765265668236	1133.57022607246	143.639999389648	0.214064567107854
0.0887751436286319	1137.51316417605	144.240005493164	0.214070048711196
0.0891737606904402	1141.57564180064	144.839996337891	0.214069938712467
0.0895747243918067	1145.69256534115	145.440002441406	0.214051348927218
0.089973350620176	1149.56766558983	146.039993286133	0.214068142066556
0.0903743143215425	1153.55615823999	146.639999389648	0.214070342041141
0.0907729313833508	1157.57922843755	147.240005493164	0.214080296926142
0.091173904251278	1161.54313260956	147.839996337891	0.21407210202081
0.0915748679526445	1165.35313925314	148.440002441406	0.2140572888586
0.0919734850144528	1168.92670133449	149.039993286133	0.214061450477191
0.0923721112428216	1173.01464559718	149.639999389648	0.214055602211417
0.0927730749441882	1176.89073377579	150.240005493164	0.214053365570588
0.0931740386455547	1180.82049948036	150.839996337891	0.214071002033517
0.0935703182343658	1184.72084682715	151.440002441406	0.214075053653379
0.0939712819357323	1188.52997531079	152.039993286133	0.214069957045589
0.0943722456370988	1192.55655814809	152.639999389648	0.214054538890367
0.0947708626989071	1196.34439125334	153.240005493164	0.214054465557881
0.095169488927276	1200.32651724397	153.839996337891	0.214043960679235
0.0955704526286425	1204.19898301286	154.440002441406	0.214053310571224
0.0959714163300091	1208.10163552947	155.039993286133	0.21405362223429
0.0963723800313756	1212.08485922003	155.639999389648	0.214052412248268
0.0967686596201866	1215.85787337639	156.240005493164	0.214052613912605
0.0971696233215528	1219.62957029284	156.839996337891	0.214051183929124
0.0975705870229193	1223.46998322414	157.440002441406	0.214047480638572
0.0979715507242858	1227.30754213564	158.039993286133	0.214047645636665
0.0983701769526551	1230.97067653026	158.639999389648	0.214043062356279
0.0987664473749051	1234.66926663222	159.240005493164	0.214050395604898
0.0991697577158295	1238.55940536977	159.839996337891	0.214052962241914
0.0995683839441988	1242.30958736784	160.440002441406	0.214055748876389
0.0999693476455654	1246.13858422	161.039993286133	0.214051312260975
0.100367964707374	1249.89052253794	161.639999389648	0.214010942727327
0.100766590935743	1253.76781818646	162.240005493164	0.21401926596451
0.101167554637109	1256.46706228354	162.839996337891	0.214033235803129
0.101568518338476	1259.77816431462	163.440002441406	0.214050248939925
0.101967135400284	1263.67521856166	164.039993286133	0.214060698819208
0.102368108268211	1267.40234886147	164.639999389648	0.214062403799511
0.102769071969578	1271.10609815303	165.240005493164	0.214075988642578
0.103165342391828	1273.80193938037	165.839996337891	0.214056518867494
0.103568652732752	1277.33258139495	166.440002441406	0.214045353996472
0.103967278961122	1280.94708768322	167.039993286133	0.214045298997108
0.104368242662488	1284.6027577184	167.639999389648	0.214041430708461
0.104766859724296	1288.34218225729	168.240005493164	0.214016369331306
0.105165485952665	1292.09554758512	168.839996337891	0.214009861073156
0.105566449654032	1295.75429118007	169.440002441406	0.21401464601788
0.105969759994956	1299.52993981623	170.039993286133	0.214038057414096
0.106366030417207	1303.13346910533	170.639999389648	0.214051000597909
0.106767003285134	1306.74709723368	171.240005493164	0.214047315640478
0.107165620346942	1309.62724227716	171.839996337891	0.21405338390371
0.107568930687867	1309.95841834226	172.440002441406	0.214052100585202
0.107967547749675	1311.10145326633	173.039993286133	0.214046948978047
0.108363827338486	1314.08050107238	173.639999389648	0.214046197320063
0.108767137679411	1317.15329245138	174.240005493164	0.214044895668433
0.109165754741219	1319.24452056417	174.839996337891	0.214036334100671
0.109566718442585	1322.34760846089	175.440002441406	0.214038864071444
0.109965344670955	1325.6862627599	176.039993286133	0.214043630683046
0.110363961732763	1329.32733338618	176.639999389648	0.21404366734929
0.11076492543413	1333.01099476925	177.240005493164	0.214037067425533
0.111165898302057	1336.73856414903	177.839996337891	0.214048837289566
0.111564515363865	1340.34878940763	178.440002441406	0.214039010736417
0.111965479065232	1343.90259289047	179.039993286133	0.214042732360091
0.112366442766598	1347.29843735518	179.639999389648	0.214042329031417
0.112762722355409	1350.89384366489	180.240005493164	0.214036132436334
0.113163686056775	1354.22898532417	180.839996337891	0.214038680740229
0.113564649758142	1357.83042898342	181.440002441406	0.214053567234926
0.113965613459508	1361.47029213979	182.039993286133	0.214043979012356
0.114364239687878	1365.05680708017	182.639999389648	0.214022309262687
0.114762856749686	1368.63574789112	183.240005493164	0.214016699327493
0.115163820451052	1372.29844320577	183.839996337891	0.214023134253156
0.11556479331898	1375.8044967422	184.440002441406	0.214020494283654
0.115963410380788	1379.52767532231	185.039993286133	0.21402696587556
0.116362027442596	1383.08268627505	185.639999389648	0.214035050782162
0.116763000310523	1386.56085823358	186.240005493164	0.214038039080975
0.11716396401189	1390.22629779802	186.839996337891	0.214031384157853
0.117564927713256	1393.81742307806	187.440002441406	0.214034042460477
0.117961198135506	1397.44411383542	188.039993286133	0.214029165850146
0.118364508476431	1401.0239328063	188.639999389648	0.214051917253986
0.1187631347048	1404.25973262304	189.240005493164	0.21402494923219
0.119164098406167	1407.09926276958	189.839996337891	0.214030009173737
0.119562715467975	1409.64087715851	190.440002441406	0.214021539271582
0.119961341696344	1411.97436764309	191.039993286133	0.214019449295726
0.120362305397711	1414.40489480037	191.639999389648	0.21402755253545
0.120763269099077	1416.84815527669	192.240005493164	0.214028212527825
0.121161895327446	1419.17868197149	192.839996337891	0.214023757579289
0.121560512389254	1421.26518997464	193.440002441406	0.214024417571665
0.121963822730179	1423.25180728529	194.039993286133	0.214024069242356
0.122362439791987	1416.25188468152	194.639999389648	0.214024857566582
0.122763403493354	1403.36181409055	195.240005493164	0.214031200826637
0.123164376361281	1358.71023546728	195.839996337891	0.214032997472549
0.123567686702206	1357.29101924397	196.440002441406	0.21404568399266
0.123963957124456	1361.2334084976	197.039993286133	0.21404130237661
0.124364920825822	1365.91257393584	197.639999389648	0.214029844175643
0.124765893693749	1371.02072050183	198.240005493164	0.214027039208046
0.125166857395116	1376.20702330194	198.839996337891	0.214027937531002
0.125565474456924	1381.20177746645	199.440002441406	0.214020585949261
0.125964100685293	1386.36184523854	200.039993286133	0.21401286770509
0.126362717747102	1391.2123616339	200.639999389648	0.214020164287466
0.126766028088026	1396.01479877287	201.240005493164	0.214014334354814
0.127164645149835	1400.66542401325	201.839996337891	0.214022034265864
0.127563271378204	1405.3099021341	202.440002441406	0.214025829222024
0.12796423507957	1409.82419304473	203.039993286133	0.214023959243626
0.128365198780937	1414.19852721588	203.639999389648	0.214027717533543
0.128763815842745	1418.48241091384	204.240005493164	0.214027460869842
0.129162442071114	1422.73852280388	204.839996337891	0.214028579190256
0.12956340577248	1426.83118717621	205.440002441406	0.214022272596444
0.129964369473847	1431.06249104811	206.039993286133	0.213998696202133
0.130362995702216	1435.12409051278	206.639999389648	0.214008467755919
0.130761612764024	1439.23761118354	207.240005493164	0.214016827659344
0.131160229825833	1443.40458984028	207.839996337891	0.214017780981665
0.131563540166757	1447.45949333545	208.440002441406	0.214033822463019
0.131959819755568	1451.5213123401	209.039993286133	0.21403301580567
0.132360783456935	1455.39586373882	209.639999389648	0.214027002541803
0.132759400518743	1459.58062513423	210.240005493164	0.214007954428515
0.133162710859668	1463.4931569501	210.839996337891	0.214016076001361
0.133561337088037	1467.44213240323	211.440002441406	0.214015251010891
0.133959954149845	1471.37980154721	212.039993286133	0.214010832728598
0.134360917851211	1475.3080304719	212.639999389648	0.214014847682217
0.134761890719139	1479.22001343781	213.240005493164	0.214015177678405
0.135160507780947	1483.09708954635	213.839996337891	0.21401002607125
0.135559124842756	1486.84990602422	214.440002441406	0.214013876026775
0.135957751071124	1490.60799146171	215.039993286133	0.214022180930836
0.136361061412049	1494.54697784559	215.639999389648	0.214026672545615
0.136762025113415	1498.33667704069	216.240005493164	0.214025572558322
0.137158295535666	1501.97675973705	216.839996337891	0.21401796431288
0.137559268403593	1505.63956482169	217.440002441406	0.21400978774067
0.137960232104959	1509.3227871248	218.039993286133	0.214011712718432
0.138358849166768	1512.99360541884	218.639999389648	0.214006836108101
0.138757475395137	1516.70218459004	219.240005493164	0.214005204460283
0.139158439096504	1520.17442896901	219.839996337891	0.214020420951167
0.13955940279787	1523.79080134715	220.440002441406	0.214010722729869
0.139958019859678	1527.43395760327	221.039993286133	0.214020915945449
0.140356646088047	1530.72727689569	221.639999389648	0.214018770970228
0.140757609789414	1534.37888544118	222.240005493164	0.214019082633295
0.14115857349078	1535.32576138999	222.839996337891	0.214008834418349
0.141557190552589	1538.93840158841	223.440002441406	0.214006396113183
0.141958163420516	1542.51701308938	224.039993286133	0.214000657846139
0.142356780482324	1546.18881931335	224.639999389648	0.214007496100476
0.142757744183691	1549.75799059503	225.240005493164	0.214006726109371
0.14315637041206	1553.20729304573	225.839996337891	0.214002051163377
0.143554987473868	1556.76625571818	226.440002441406	0.214016552662521
0.143955951175235	1560.48910498831	227.039993286133	0.214016387664427
0.144359261516159	1563.94345685862	227.639999389648	0.214014939347825
0.144757878577967	1567.47881898285	228.240005493164	0.214013692695559
0.145156504806337	1570.8634669084	228.839996337891	0.214014187689841
0.145555121868145	1574.37094745472	229.440002441406	0.21401002607125
0.145956085569511	1577.86591422198	230.039993286133	0.214003462813736
0.146357058437439	1581.28557877491	230.639999389648	0.21400458113415
0.146753328859689	1583.57801528257	231.240005493164	0.213998439538432
0.147154292561055	1584.37736036248	231.839996337891	0.214004672799758
0.147555265428982	1586.89109317351	232.440002441406	0.214006157782604
0.147956229130349	1589.2895674932	233.039993286133	0.214008137759731
0.148354846192157	1592.51109721101	233.639999389648	0.214010557731775
0.148753472420526	1595.76522861638	234.240005493164	0.214009769407548
0.149154436121893	1598.23417527078	234.839996337891	0.214008559421526
0.149555399823259	1599.90739925499	235.440002441406	0.214009347745753
0.149954016885068	1602.46701592257	236.039993286133	0.21401998095625
0.150352643113437	1604.0468256438	236.639999389648	0.214022455927659
0.150753606814803	1606.73816630148	237.240005493164	0.214012226045836
0.151152223876611	1609.86474497643	237.839996337891	0.214007312769261
0.151553187577978	1613.03852474784	238.440002441406	0.214008834418349
0.151954160445905	1616.38936351594	239.039993286133	0.21400492946346
0.152355124147272	1619.39003601036	239.639999389648	0.213997669547327
0.15275374120908	1622.60739446849	240.240005493164	0.214004012807382
0.153152367437449	1625.09324570161	240.839996337891	0.214001226172907
0.153553331138815	1626.56800554074	241.440002441406	0.214006396113183
0.153954294840182	1629.23936805992	242.039993286133	0.214008449422797
0.154355258541548	1631.45255063354	242.639999389648	0.214010246068709
0.154753875603357	1631.95628512567	243.240005493164	0.214002289493957
0.155157185944281	1533.14649774382	243.839996337891	0.213986944671222
0.155560496285206	1536.68712882765	244.440002441406	0.213990647961774
0.155961459986572	1541.73127948845	245.039993286133	0.213990207966857
0.156357748741944	1546.90484896952	245.639999389648	0.21399983285567
0.156758712443311	1552.30992336319	246.240005493164	0.214005186127161
0.157159676144677	1557.7582471336	246.839996337891	0.214004159472355
0.157558293206485	1563.1655169271	247.440002441406	0.214005607788957
0.157959256907852	1568.52086551451	248.039993286133	0.214004251137963
0.158355527330102	1573.68433615634	248.639999389648	0.214002289493957
0.158758837671026	1578.87382228621	249.240005493164	0.21399664289252
0.159157473065956	1583.84036556285	249.839996337891	0.213998861200228
0.159556090127765	1588.68989402828	250.440002441406	0.214002784488239
0.159954707189573	1593.21988204773	251.039993286133	0.214006322780697
0.160358017530498	1597.94218709273	251.639999389648	0.214008834418349
0.160756634592306	1602.36130742051	252.240005493164	0.21400575445393
0.161155251654114	1606.9267511473	252.839996337891	0.214006506111913
0.161553868715923	1611.34027320551	253.440002441406	0.214004489468543
0.161954850750411	1615.47014960504	254.039993286133	0.213999062864565
0.162353467812219	1619.53998181908	254.639999389648	0.213998494537796
0.162752084874027	1623.78906842965	255.240005493164	0.213992444607686
0.163153048575394	1627.90840690998	255.839996337891	0.213984689697271
0.16355401227676	1632.10162059475	256.440002441406	0.213991491285365
0.163954975978127	1636.12776435208	257.040008544922	0.214003536146222
0.164353593039935	1640.08442370463	257.640014648438	0.214011162724786
0.164752228434865	1644.1127628618	258.239990234375	0.214001666167824
0.165153192136232	1648.05460326546	258.839996337891	0.213998934532714
0.165554155837598	1652.00994537812	259.440002441406	0.213997852878543
0.165950426259848	1655.90864617503	260.040008544922	0.213998916199592
0.166351389961215	1659.75564530582	260.640014648438	0.214018385974676
0.166752353662581	1663.74633335582	261.239990234375	0.214006029450753
0.167153317363947	1667.59926006617	261.839996337891	0.214007991094758
0.167551952758877	1671.37853111206	262.440002441406	0.214001867832161
0.167950569820686	1675.15681422802	263.040008544922	0.213995029577824
0.168351533522052	1679.04025699608	263.640014648438	0.213997376217382
0.168752497223419	1682.77002177569	264.239990234375	0.213997064554316
0.169151114285227	1686.52832675315	264.839996337891	0.213990262966222
0.169549731347035	1690.20628009666	265.440002441406	0.214001207839785
0.169950695048402	1693.90728513843	266.040008544922	0.21399722955241
0.170351658749768	1697.64144071771	266.640014648438	0.21399805454288
0.170750294144698	1701.19765914037	267.239990234375	0.214000896176719
0.171148911206506	1704.93620551932	267.839996337891	0.213994094588625
0.171552221547431	1708.60230370372	268.440002441406	0.213997871211664
0.171950838609239	1712.18234221458	269.040008544922	0.214002436158929
0.172349455671048	1715.71726525884	269.640014648438	0.214004122806112
0.172750419372414	1719.26129921241	270.239990234375	0.214001886165283
0.17315138307378	1722.72992118165	270.839996337891	0.214005057795311
0.17355001846871	1726.42379117396	271.440002441406	0.214003792809924
0.173948635530519	1729.91063496183	272.040008544922	0.214001152840421
0.174349599231885	1733.40944367881	272.640014648438	0.213999997853763
0.174750562933252	1737.00177642875	273.239990234375	0.213997797879178
0.175151526634618	1740.38104562471	273.839996337891	0.213989456308874
0.175547797056868	1743.92453072832	274.440002441406	0.213981939729039
0.175948760758235	1747.30379992428	275.040008544922	0.21399380125868
0.176349742792723	1750.67549499081	275.640014648438	0.213996697891885
0.176750706494089	1754.11876009196	276.239990234375	0.213991876280918
0.177149323555898	1757.62217914859	276.839996337891	0.213997211219288
0.177547940617706	1760.95161276829	277.440002441406	0.213998127875366
0.177948904319072	1764.36205664191	278.040008544922	0.213999411193874
0.178349868020439	1767.80016255344	278.640014648438	0.21400054784741
0.178748485082247	1771.1169726241	279.239990234375	0.213997981210393
0.179147120477177	1774.5807647137	279.839996337891	0.21399876953462
0.179548084178543	1778.00383213637	280.440002441406	0.213994259586719
0.17994904787991	1781.37640536283	281.040008544922	0.213995157909675
0.180347664941718	1784.74107514989	281.640014648438	0.213992169610863
0.180746282003527	1788.11924664593	282.239990234375	0.214000749511747
0.181149592344451	1791.48567275286	282.839996337891	0.213996312896332
0.181548209406259	1794.86022183917	283.440002441406	0.213996477894426
0.181946844801189	1798.1534313616	284.040008544922	0.213996459561305
0.182347808502556	1801.41458804644	284.640014648438	0.213996001233266
0.182748772203922	1804.89550425476	285.239990234375	0.213996221230725
0.183147389265731	1808.20463042599	285.839996337891	0.21399213294462
0.183546006327539	1811.43066071347	286.440002441406	0.213994662915393
0.183944623389347	1814.64834848157	287.040008544922	0.21399048296368
0.184347933730272	1818.15132845823	287.640014648438	0.213993031267575
0.184748897431638	1821.51797410514	288.239990234375	0.213989162978929
0.18514518618701	1824.78791238932	288.839996337891	0.213989676306332
0.185546149888376	1828.06015584332	289.440002441406	0.21398562468647
0.185944766950185	1831.39079693294	290.040008544922	0.21398644967694
0.186345730651551	1834.76710233912	290.640014648438	0.21398538635589
0.18674434771336	1838.06020209156	291.239990234375	0.213984928027851
0.187142964775168	1841.35483862388	291.839996337891	0.213988722984012
0.187543946809656	1844.69678602264	292.440002441406	0.213988649651526
0.187944910511022	1847.92029160031	293.040008544922	0.213988264655973
0.188343527572831	1851.16070175671	293.640014648438	0.214002656156388
0.188744491274197	1854.56203472101	294.239990234375	0.214003187816913
0.189145454975564	1857.85271953363	294.839996337891	0.213992902935724
0.189544072037372	1861.12188942787	295.440002441406	0.213991234621664
0.189945035738739	1864.41718458014	296.040008544922	0.2139890529802
0.190343652800547	1867.84003246282	296.640014648438	0.213983754708072
0.190744634835035	1871.08132077915	297.239990234375	0.21398384637368
0.191143251896843	1874.40910784898	297.839996337891	0.213987824661056
0.191541868958652	1877.66598350414	298.440002441406	0.213988539652796
0.191942832660018	1880.9202246795	299.040008544922	0.21398870465089
0.192343796361384	1884.32814384331	299.640014648438	0.213988099657879
0.192744760062751	1887.65702861306	300.239990234375	0.213987824661056
0.193143377124559	1890.97691224348	300.839996337891	0.213987861327299
0.193542012519489	1894.11545584754	301.440002441406	0.213986376344454
0.193942976220856	1897.40833605999	302.040008544922	0.214002857820725
0.194343939922222	1900.67377377451	302.640014648438	0.2140077710973
0.19474255698403	1903.94579768853	303.239990234375	0.213993892924288
0.195141174045839	1907.19564806422	303.839996337891	0.213991362953515
0.195542137747205	1910.34802268723	304.440002441406	0.214004471135421
0.195943101448572	1913.83058544543	305.040008544922	0.213995286241526
0.196341736843502	1917.0593599827	305.640014648438	0.21399106962357
0.19674035390531	1920.24751962303	306.239990234375	0.213999191196415
0.197141317606676	1923.65148706713	306.839996337891	0.213996257896968
0.197542281308043	1926.84206164727	307.440002441406	0.213991527951609
0.197940898369851	1930.21792797349	308.040008544922	0.213985441355255
0.198341862071217	1933.37842557589	308.640014648438	0.213990574629288
0.198740479133026	1936.71543332503	309.239990234375	0.213991087956691
0.199141442834392	1939.90403204532	309.839996337891	0.21399226127647
0.19954242486888	1943.2684822924	310.440002441406	0.213992462940807
0.199941041930689	1946.4781568511	311.040008544922	0.213995652903957
0.200342005632055	1949.83119101904	311.640014648438	0.213989566307603
0.200740622693863	1953.01803341946	312.239990234375	0.213987567997354
0.20114158639523	1956.1967528405	312.839996337891	0.213993287931277
0.201540203457038	1959.5620812475	313.440002441406	0.213989841304426
0.201941167158405	1962.74299606838	314.040008544922	0.213988612985282
0.202339802553335	1966.02775330144	314.640014648438	0.213991637950338
0.202738419615143	1969.212839382	315.239990234375	0.213993837924924
0.203137036676951	1972.47300813691	315.839996337891	0.213989841304426
0.203540347017876	1975.81133312595	316.440002441406	0.213988961314592
0.203941310719242	1978.88621013479	317.040008544922	0.213986908004978
0.204337581141493	1982.18282252696	317.640014648438	0.214004086139868
0.204738544842859	1985.36922584742	318.239990234375	0.21399640456194
0.205137180237789	1988.58394982575	318.839996337891	0.213988686317769
0.205540490578713	1991.83928870103	319.440002441406	0.213995891234537
0.205936761000964	1994.93699786815	320.040008544922	0.213991289621028
0.206335378062772	1998.14272070716	320.640014648438	0.213989676306332
0.206736341764139	2001.38949752308	321.239990234375	0.213995891234537
0.207137305465505	2004.60861230108	321.839996337891	0.213994827913487
0.207535922527313	2007.881953455	322.440002441406	0.213990647961774
0.207936904561801	2011.19876352565	323.040008544922	0.21398787966042
0.208337868263168	2014.37309214702	323.640014648438	0.213994241253598
0.208736485324976	2017.73271251446	324.239990234375	0.213987861327299
0.209137449026343	2020.91011469559	324.839996337891	0.213986064681387
0.209533719448593	2024.030656021	325.440002441406	0.213996954555587
0.209937029789517	2027.19400764319	326.040008544922	0.213988997980835
0.210335646851326	2030.36921442449	326.640014648438	0.213995121243432
0.210736628885814	2033.4645086518	327.239990234375	0.214000401182437
0.211135245947622	2036.70996822782	327.839996337891	0.213995249575283
0.211536209648988	2039.81536129436	328.440002441406	0.213991234621664
0.211937173350355	2041.83337282266	329.040008544922	0.213993507928735
0.212335790412163	2042.1574138383	329.640014648438	0.21398597301578
0.212734407473972	2044.86214643497	330.239990234375	0.213983351379398
0.213135371175338	2047.57939281069	330.839996337891	0.213991692949702
0.213536334876704	2050.79258000914	331.440002441406	0.213996972888708
0.213934970271634	2054.00005916801	332.040008544922	0.213995487905863
0.214333587333443	2057.05627527826	332.640014648438	0.213996441228183
0.214734551034809	2059.46967831683	333.239990234375	0.213999209529537
0.215137861375733	2059.78713313296	333.839996337891	0.213997522882355
0.215536478437542	2062.15113967525	334.440002441406	0.213995322907769
0.21593509549935	2026.02188367131	335.040008544922	0.213998879533349
0.216089863711455	53.8995289124115	335.109985351563	0.214270961390236