File: CouponData/2-0T-2.txt
File Path: C:\Users\MTS\Desktop\SE171\Test Run 11 2-3-2017 3 06 11 PM\DAQ- Crosshead, … - (Timed).txt
Test: MTS EM Tension (Extensometer-Crosshead) 171-2017-W
Test Run: Test Run 11
Date: 2/3/2017 1:30:11 PM


Crosshead 	Load 	Time 	Extensometer
in	lbf	sec	in
0.00027668955756487	4.35924851549125	0.239999994635582	-0.000103407873620034
0.000804275617793598	16.6291263712912	0.639999985694885	-2.91945337546246E-05
0.00133655130483694	28.8068600372214	1.03999996185303	5.08076369427957E-05
0.00186882699188028	40.8498767656226	1.44000005722046	0.000124276140035019
0.00240110267892363	52.8346879558998	1.8400000333786	0.000205358819083648
0.0029357231435674	64.6920870585675	2.24000000953674	0.000284613780802213
0.00346799897383825	76.4570358159981	2.64000010490417	0.00035988067986726
0.00399792959682614	87.8521831924787	3.03999996185303	0.000433594473501516
0.00453255034792492	99.4869584609452	3.44000005722046	0.000511499641242705
0.00506482617819579	111.108266323549	3.83999991416931	0.000589519713255469
0.00559475651472866	122.531988201007	4.23999977111816	0.000666011368679835
0.00613172218665539	133.930737405342	4.6399998664856	0.000740523906342142
0.00666399801692626	145.491232692517	5.03999996185303	0.000817915889907512
0.00719392892636917	156.645318306495	5.44000005722046	0.000895542336910169
0.00772854910455791	167.869080422735	5.84000015258789	0.000970105505498
0.00826316985565669	179.125183522794	6.23999977111816	0.0010455135015659
0.00879310076509961	190.148862386575	6.6399998664856	0.00112417147311063
0.00932772094328835	201.115282478411	7.03999996185303	0.00119604010251351
0.00985999620064917	211.957470382086	7.44000005722046	0.00126465309895282
0.01039227203092	222.794581423643	7.84000015258789	0.00134472759059212
0.0109245478611909	233.735685811131	8.23999977111816	0.00141948862798791
0.0114591691851997	244.403133609193	8.64000034332275	0.00149317574549804
0.0119890995217326	255.203183557285	9.03999996185303	0.00156227557225094
0.0125237196999213	265.858995736222	9.4399995803833	0.001636169080606
0.0130583410239302	276.440356418255	9.84000015258789	0.0017082269851661
0.0135859270125452	286.994082504866	10.2399997711182	0.00178602372968063
0.0141228915386518	297.600113992546	10.6400003433228	0.00185971313883096
0.0146551673689226	308.117808079363	11.039999961853	0.00193074410212937
0.0151850988512756	318.413053277907	11.4399995803833	0.0020078156857502
0.0157197190294644	328.738293126693	11.8400001525879	0.00207908755772395
0.0162519948597352	338.982742261555	12.2399997711182	0.00215328184385439
0.0167819251962681	349.274145510386	12.6400003433228	0.00222307761308854
0.0173188908681948	359.481602158027	13.039999961853	0.00230318418769056
0.0178511666984657	369.604535912024	13.4399995803833	0.00237436897733696
0.0183810970349985	379.601481157992	13.8400001525879	0.00244344330959271
0.0189157183590074	389.517580805036	14.2399997711182	0.00251863832635013
0.0194479930434582	399.431677149732	14.6400003433228	0.00258934774388391
0.019977923379991	409.083148789169	15.039999961853	0.00265902535042058
0.0205125447039998	418.843649472912	15.4399995803833	0.00272830335219853
0.0210471660280087	428.687300925403	15.8400001525879	0.00280078936379227
0.0215794407124594	438.087701151218	16.2399997711182	0.002871225789688
0.0221117176885504	447.603222655877	16.6399993896484	0.00294065360744359
0.0226463367209191	456.919593953006	17.0400009155273	0.00300883821039424
0.0231762670574519	466.14639293687	17.4400005340576	0.00307862094592479
0.0237108883814607	475.182274462588	17.8400001525879	0.00314504413693175
0.0242431653575517	484.203501694406	18.2399997711182	0.00321457507849605
0.0247754400420025	492.899974405637	18.6399993896484	0.00328002031205046
0.0253124057139292	501.270979091337	19.0400009155273	0.00334104325294157
0.02584468039838	509.507241112166	19.4400005340576	0.00340597859655294
0.026374613026553	517.607498113219	19.8400001525879	0.00346555006983653
0.0269092320589217	525.604296897049	20.2399997711182	0.00352865697102856
0.0274415090350126	533.782325937257	20.6399993896484	0.00358851862325165
0.0279737837194634	541.600748484496	21.0400009155273	0.00365031757080326
0.0285084050434722	549.4994677807	21.4400005340576	0.0037074776656933
0.029040679727923	557.307352408734	21.8400001525879	0.00376815227727501
0.0295706100644558	564.894599353352	22.2399997711182	0.00382626827258074
0.0301052313884647	572.563515171833	22.6399993896484	0.00388671773051344
0.0306375060729154	579.971617489919	23.0400009155273	0.00394617233014717
0.0311697830490064	587.468907926301	23.4400005340576	0.00400094510886567
0.0317044043730152	595.006977914618	23.8400001525879	0.00405576658493831
0.0322390234053839	602.293400196852	24.2399997711182	0.00411065938831197
0.0327666093939989	609.488329190963	24.6399993896484	0.00417187883734968
0.0333035750659256	616.801151156214	25.0400009155273	0.00422651383120157
0.0338358497503763	624.036146197313	25.4400005340576	0.00428793666330642
0.0343657823785494	631.122896864558	25.8400001525879	0.00433865438470264
0.0349027480504761	638.197188637741	26.2399997711182	0.00439475574182331
0.0354350227349269	645.320273172254	26.6399993896484	0.00445217851597051
0.0359649530714598	652.213005379083	27.0400009155273	0.00450674848453193
0.0365019187433865	658.987844614777	27.4400005340576	0.00456246685128528
0.0370341957194775	666.069216552427	27.8400001525879	0.00461445013097831
0.0375641260560103	672.100034784051	28.2399997711182	0.00466216064753071
0.038098745088379	678.692710718439	28.6399993896484	0.00471161882618559
0.0386310220644699	685.43950372124	29.0400009155273	0.00476301773762933
0.0391632967489207	692.126801388514	29.4400005340576	0.00481497323118504
0.0396979180729295	698.829960819597	29.8400001525879	0.00487362604320606
0.0402325393969382	705.55463516906	30.2399997711182	0.00492713985209331
0.040764814081389	712.278815553562	30.6399993896484	0.00498038210161764
0.041299435405398	718.929889123559	31.0400009155273	0.0050294369515985
0.0418317100898488	725.501434334536	31.4400005340576	0.00508731576214421
0.0423592960784638	730.274014035752	31.8400001525879	0.00513096749745898
0.0428986060983083	735.9467076693	32.2400016784668	0.00516996204699059
0.0434308807827591	732.071991615585	32.6399993896484	0.00515407181388925
0.0439608134109323	737.068996064931	33.0400009155273	0.00519197210522854
0.0444977767912185	743.505304646072	33.439998626709	0.0052362649268874
0.04503005605895	748.786778029031	33.8400001525879	0.00528014983659185
0.0455599841038425	754.759692590009	34.2400016784668	0.00532702132637839
0.0460969520674095	760.960599423849	34.6399993896484	0.00537972618627736
0.0466292267518602	767.190265995526	35.0400009155273	0.00542472941639622
0.047161501436311	773.339471163252	35.439998626709	0.00546972691741457
0.0476961227603197	779.453989013585	35.8400001525879	0.00551589716530193
0.0482283974447705	785.410767385777	36.2400016784668	0.00556624507326193
0.0487606721292213	790.991967731205	36.6399993896484	0.0056108398185163
0.0492929513969524	796.786231630613	37.0400009155273	0.00565664684143299
0.0498252260814032	802.319846684616	37.439998626709	0.00570294083789079
0.0503575007658539	806.566847665343	37.8400001525879	0.00574343641174913
0.0508944641461406	800.204139863667	38.2400016784668	0.00570265151831638
0.0514243967743134	805.640718244966	38.6399993896484	0.00574712881701083
0.0519543294024866	811.464674927142	39.0400009155273	0.00578860292123177
0.052488946143215	817.028860923849	39.439998626709	0.00583574482456114
0.0530212254109461	822.50237690737	39.8400001525879	0.00573174331766209
0.0535535000953969	827.97007508133	40.2400016784668	0.0107222006153902
0.0540904634756835	833.457422083811	40.6399993896484	0.076716441265124
0.0546227427434146	838.9273705426	41.0400009155273	0.140274880365945
0.0551526707883075	844.26669271121	41.439998626709	0.0660313572001268
0.0556896387518744	849.730988015426	41.8400001525879	0.267220023051491
0.0562219134363252	855.158400602413	42.2400016784668	0.155584842670621
0.056754188120776	860.490587721559	42.6399993896484	0.173423171600723
0.0572888094447847	865.994235567816	43.0400009155273	0.181633330089605
0.0578210841292354	871.349529270226	43.439998626709	0.188295623126227
0.0583557054532441	876.602901535297	43.8400001525879	0.191428698599339
0.0588879801376949	882.272302069093	44.2400016784668	0.19251361606628
0.0594202548221457	887.731163758716	44.6399993896484	0.193085499459833
0.0599525340898768	893.006709562121	45.0400009155273	0.192764211504713
0.0604894974701634	898.169027619036	45.439998626709	0.193462391772608
0.0610217721546142	903.164550173491	45.8400001525879	0.193594078584684
0.0615517047827874	908.214683298842	46.2400016784668	0.193384054344235
0.0620886681630736	913.098350231707	46.6399993896484	0.193486518160565
0.0626209428475244	918.052105304301	47.0400009155273	0.193135988876576
0.0631508754756976	922.877484371547	47.439998626709	0.194390689382168
0.0636878388559843	928.0047309161	47.8400001525879	0.193677274290267
0.0642201181237154	932.825170333718	48.2400016784668	0.193679950926013
0.0647523928081662	937.643743661475	48.6399993896484	0.194196449959372
0.0652893561884528	942.70765292079	49.0400009155273	0.193540619202252
0.0658192888166256	947.784295499147	49.439998626709	0.194032075191577
0.0663515635010764	952.863023707347	49.8400001525879	0.193746115161678
0.0668885314646433	957.920346767157	50.2400016784668	0.193910984923755
0.0674184595095362	963.100063367765	50.6399993896484	0.193828614208642
0.0679507341939866	968.142787018672	51.0400009155273	0.193953976093784
0.0684830134617181	973.136333713276	51.439998626709	0.193798272892481
0.0690152881461685	978.392669768125	51.8400001525879	0.193844252361322
0.0695475628306193	983.4943399046	52.2400016784668	0.193963307652652
0.0700821841546284	988.762970198525	52.6399993896484	0.193718615479357
0.0706121167828012	993.857395515545	53.0400009155273	0.193976452500802
0.0711420448276941	998.997375379141	53.439998626709	0.193768114907535
0.071679012791261	1004.18016553952	53.8400001525879	0.193920664811932
0.0722112874757118	1009.30027703461	54.2400016784668	0.193789197997315
0.0727435621601626	1014.46802870612	54.6399993896484	0.193920078152043
0.0732805255404492	1019.79538594562	55.0400009155273	0.193823297603393
0.0738128048081803	1024.89420206231	55.439998626709	0.193849403968477
0.0743427328530728	1030.046256625	55.8400001525879	0.193898041739943
0.0748797008166398	1035.340463327	56.2400016784668	0.193809841092177
0.0754119755010906	1040.49076156982	56.6399993896484	0.193904549998092
0.0759442501855413	1045.60516502534	57.0400009155273	0.193815029365575
0.07647887150955	1050.88543093839	57.439998626709	0.193910123267043
0.0770111461940008	1055.8802948729	57.8400001525879	0.193792479626072
0.0775434208784516	1061.12181197886	58.2400016784668	0.193911424918672
0.0780780422024606	1066.31492051846	58.6399993896484	0.193814406039443
0.0786103168869114	1071.37740276788	59.0400009155273	0.193883430242069
0.0791425915713618	1076.45108155646	59.439998626709	0.193843207373394
0.0796772128953709	1081.76801064676	59.8400001525879	0.193869368737842
0.0802094875798217	1086.98087778487	60.2400016784668	0.193862750480963
0.0807394247912752	1092.07365655202	60.6399993896484	0.193857837204389
0.0812763835882811	1097.33065122682	61.0400009155273	0.193887500195053
0.0818086582727319	1102.30213415308	61.439998626709	0.193817284339526
0.0823409421237433	1107.42334334808	61.8400001525879	0.193894246783782
0.0828755542811917	1112.67221504349	62.2400016784668	0.193823444268365
0.0834078381322031	1117.6457835996	62.6399993896484	0.193903596675771
0.0839401128166539	1122.78488530326	63.0400009155273	0.193822527612288
0.0844747341406626	1128.00368002093	63.439998626709	0.193885666882898
0.0850070088251134	1133.03059679303	63.8400001525879	0.193837780769416
0.0855416301491224	1138.17826055605	64.2399978637695	0.193862970478422
0.0860739048335732	1143.20748249797	64.6399993896484	0.193848413979913
0.0866061795180236	1148.17457462456	65.0400009155273	0.193863667137041
0.0871384542024744	1153.34825387562	65.4400024414063	0.193861907157372
0.0876730755264835	1158.46507227096	65.8399963378906	0.193852905594693
0.0882053502109343	1163.49484306284	66.2399978637695	0.193873640355163
0.088737624895385	1168.65271543509	66.6399993896484	0.193843940698256
0.089274592858952	1173.73078502334	67.0400009155273	0.193871532046185
0.0898045209038445	1178.72663688777	67.4400024414063	0.193830520853283
0.0903367955882953	1183.8595914719	67.8399963378906	0.193872870364058
0.0908714169123043	1188.89507030335	68.2399978637695	0.193843262372758
0.0914036915967547	1193.93966004411	68.6399993896484	0.193876738652704
0.0919359662812055	1198.90741079066	69.0400009155273	0.193837909101267
0.0924729342447724	1204.0945917507	69.4400024414063	0.193878645297345
0.0930028622896654	1209.0908826951	69.8399963378906	0.193835947457261
0.0935351369741162	1214.1976022512	70.2399978637695	0.193864400461903
0.0940721049376831	1219.37501368198	70.6399993896484	0.193842327383559
0.0946020421491362	1224.33387305919	71.0400009155273	0.19385607722472
0.095134316833587	1229.39284266888	71.4400024414063	0.193858258866184
0.0956689381575961	1234.38979223323	71.8399963378906	0.193847790653781
0.0961988662024886	1239.31780624276	72.2399978637695	0.193868543747372
0.0967334875264976	1244.316182817	72.6399993896484	0.19384078740135
0.0972681088505063	1249.26757783477	73.0400009155273	0.193863667137041
0.0978003835349571	1254.24685443045	73.4400024414063	0.19384221738483
0.0983326582194079	1259.23205860568	73.8399963378906	0.193860550506378
0.0988696261829748	1264.14174102659	74.2399978637695	0.193855435565466
0.0993995542278673	1268.99456259177	74.6399993896484	0.193846159005963
0.0999318289123181	1273.91873465159	75.0400009155273	0.193851053949416
0.100466450236327	1278.80426767431	75.4400024414063	0.193863190475881
0.100998724920778	1283.39484872921	75.8399963378906	0.193837157443283
0.101530999605229	1288.15963476101	76.2399978637695	0.193850760619471
0.102065620929237	1292.90411334434	76.6399993896484	0.193851622276184
0.10259554897413	1297.56341041407	77.0400009155273	0.193846049007234
0.103127823658581	1302.17122535767	77.4400024414063	0.193855527231074
0.103664791622148	1306.80856842905	77.8399963378906	0.193852538932261
0.104194719667041	1310.5431630883	78.2399978637695	0.193865298784859
0.104729340991049	1313.79191576407	78.6399993896484	0.193840017410245
0.105263962315058	1316.32793188342	79.0400009155273	0.193849293969748
0.105791552886954	1315.61947635668	79.4400024414063	0.193848652310493
0.10632852085052	1314.07325625292	79.8399963378906	0.193850045627731
0.106863133007969	1313.78950082425	80.2399978637695	0.193843189040272
0.10739541685898	1312.43691498594	80.6399993896484	0.193850467289527
0.107930029016428	1310.06555385421	81.0400009155273	0.193845462347344
0.108464650340437	1309.65501408507	81.4400024414063	0.193851402278726
0.108996925024888	1310.17784855576	81.8399963378906	0.193850870618201
0.109529208875899	1311.29914902147	82.2399978637695	0.193839669080935
0.110066167672906	1312.83592890594	82.6399993896484	0.193852850595328
0.110596104884359	1314.63923033037	83.0400009155273	0.19383250083041
0.111130726208368	1316.74933888174	83.4400024414063	0.193854353911295
0.111665338365816	1318.91850368868	83.8399963378906	0.19385145727809
0.112195275577269	1321.39985435214	84.2399978637695	0.193842767378477
0.112729896901278	1323.95551930001	84.6399993896484	0.193851603943063
0.113266855698284	1326.97869464274	85.0400009155273	0.193849477300963
0.113796792909738	1329.86882875547	85.4400024414063	0.193844545691267
0.114331414233746	1333.12548487065	85.8399963378906	0.193861503828698
0.114863688918197	1336.42363404271	86.2399978637695	0.193829365866626
0.11539361696309	1339.69302347692	86.6399993896484	0.193846727332731
0.115930584926657	1343.1864534643	87.0400009155273	0.193841777389913
0.116462859611107	1346.71709547888	87.4400024414063	0.193839595748449
0.116995134295558	1350.24378577376	87.8399963378906	0.193844949019941
0.117529755619567	1353.97914882295	88.2399978637695	0.193841484059969
0.118064376943576	1357.68125156464	88.6399993896484	0.19384126406251
0.118594304988469	1361.3677669675	89.0400009155273	0.193852722263477
0.119126579672919	1365.23232929698	89.4400024414063	0.193845425681101
0.119663547636486	1369.19645300897	89.8399963378906	0.193843262372758
0.120195822320937	1373.07056532773	90.2399978637695	0.193845279016129
0.120728097005388	1376.91405181879	90.6399993896484	0.193840622403256
0.121262718329397	1381.00386217133	91.0400009155273	0.193845444014222
0.121792646374289	1384.90947847772	91.4400024414063	0.193837414106985
0.122327267698298	1388.93968372475	91.8399963378906	0.193845389014858
0.122864235661865	1393.00084410944	92.2399978637695	0.19383629578657
0.123394163706758	1396.92336499456	92.6399993896484	0.193838385762427
0.123928785030767	1400.89407490606	93.0400009155273	0.193838239097454
0.124461059715217	1404.97565250922	93.4400024414063	0.19383770743693
0.124990996926671	1409.05207092277	93.8399963378906	0.1938442340282
0.125527955723677	1413.11718302717	94.2399978637695	0.193838165764968
0.126062577047686	1417.28471053387	94.6399993896484	0.193838495761156
0.126592514259139	1421.28253363333	95.0400009155273	0.193831950836764
0.127127126416587	1425.15488963222	95.4400024414063	0.193837047444554
0.127661747740596	1429.38816936398	95.8399963378906	0.193830392521432
0.12819168495205	1433.34164538677	96.2399978637695	0.19383119917878
0.128726306276059	1437.3598857047	96.6399993896484	0.19383523246552
0.129260918433507	1441.22818021389	97.0400009155273	0.19383913742041
0.129793202284518	1445.16200740816	97.4400024414063	0.193837010778311
0.130325476968969	1449.09265127267	97.8399963378906	0.193836350785935
0.130860098292978	1453.01989226744	98.2399978637695	0.193832922492206
0.13139002633787	1456.87095288793	98.6399993896484	0.19383523246552
0.131924647661879	1460.82398983076	99.0400009155273	0.193833967480134
0.132461615625446	1464.77768539353	99.4400024414063	0.193830997514443
0.132989197030781	1468.69537639901	99.8399963378906	0.193823865930161
0.13352381835479	1472.76959941273	100.23999786377	0.193832354165438
0.134058439678798	1476.66961744954	100.639999389648	0.193833655817068
0.134588367723691	1480.64142506096	101.040000915527	0.193829952526515
0.1351229890477	1484.49435177131	101.440002441406	0.193844215695079
0.135657610371709	1488.38020947918	101.839996337891	0.193834719138117
0.136187538416602	1491.20986032646	102.23999786377	0.193836424118421
0.13672215974061	1492.28626486554	102.639999389648	0.193831767505548
0.137256781064619	1493.88824812511	103.040000915527	0.193832445831045
0.137786709109512	1495.9755245182	103.440002441406	0.193828192546846
0.138321330433521	1498.1743272229	103.839996337891	0.193840879066957
0.13885595175753	1499.39321321127	104.23999786377	0.193829879194029
0.13938822644198	1499.23327833329	104.639999389648	0.19383119917878
0.139922847765989	1499.88750748411	105.040000915527	0.193834077478863
0.140457469089998	1501.4346057478	105.440002441406	0.193829310867261
0.140987397134891	1495.97607336815	105.839996337891	0.193824489256294
0.1415220184589	1492.01963355558	106.23999786377	0.193825240914277
0.142058986422467	1492.64982307821	106.639999389648	0.193836570783394
0.142588914467359	1494.48912905994	107.040000915527	0.19382610257099
0.143123535791368	1497.16169904902	107.440002441406	0.193833545818338
0.143658157115377	1499.97170106778	107.839996337891	0.193825772574802
0.14418809432683	1502.84207658199	108.23999786377	0.193825167581791
0.144722706484278	1506.04055460154	108.639999389648	0.193828229213089
0.145257327808287	1509.30522392612	109.040000915527	0.193826377567813
0.145787265019741	1512.43257099102	109.440002441406	0.193822270948587
0.14632188634375	1515.984398614	109.839996337891	0.193829365866626
0.146856507667758	1519.49681880995	110.23999786377	0.193825735908559
0.147386435712651	1522.75490193502	110.639999389648	0.193825369246128
0.14792105703666	1526.36161455388	111.040000915527	0.193830924181957
0.148458015833666	1530.10696667232	111.440002441406	0.193829145869167
0.148987953045119	1533.64781729613	111.839996337891	0.19382480091936
0.14952022772957	1537.39251079462	112.23999786377	0.193827367556377
0.150057195693137	1541.15048646211	112.639999389648	0.193826909228338
0.15058712373803	1544.95489483611	113.040000915527	0.193820364303946
0.151121745062039	1548.79333190755	113.440002441406	0.193822490946045
0.151656366386048	1552.72770795178	113.839996337891	0.193822527612288
0.15218629443094	1556.50599106774	114.23999786377	0.193824012595133
0.152720915754949	1560.37110224718	114.639999389648	0.193813801046432
0.1532531904394	1564.1991111694	115.040000915527	0.193819245983531
0.153783118484293	1568.1113136753	115.440002441406	0.193820107640244
0.15432009561442	1572.0646799281	115.839996337891	0.193825442578614
0.15485236113231	1575.96513704488	116.23999786377	0.193824489256294
0.155384644983322	1579.92838259694	116.639999389648	0.193828064214996
0.15591925714077	1583.92938902616	117.040000915527	0.193819245983531
0.156453887631339	1587.96552185273	117.440002441406	0.193827184225161
0.156983806509671	1591.77519918634	117.839996337891	0.193836515784029
0.157516090360683	1595.73076083897	118.23999786377	0.193811234409415
0.158053049157689	1599.7582218362	118.639999389648	0.193829879194029
0.158582986369143	1603.618503136	119.040000915527	0.193826854228973
0.159117598526591	1607.62181473505	119.440002441406	0.193815011032454
0.15965222901716	1611.70503888809	119.839996337891	0.193829145869167
0.160182147895492	1615.45950191584	120.23999786377	0.193803442832757
0.160716778386061	1619.39003601036	120.639999389648	0.193826432567178
0.16125139054351	1623.45075731509	121.040000915527	0.193816752679001
0.161783674394521	1627.31817366435	121.440002441406	0.193830117524609
0.162318286551969	1631.27735772671	121.839996337891	0.19381946598099
0.162852917042539	1635.14016373632	122.23999786377	0.193820437636432
0.163380489281313	1638.95082899985	122.639999389648	0.193822417613559
0.163917466411441	1643.01363593442	123.040000915527	0.193818750989249
0.16444973192933	1646.86985574453	123.440002441406	0.193832794160355
0.164982015780342	1650.74671231308	123.839996337891	0.193814717702509
0.16551662793779	1654.6638544686	124.23999786377	0.193827844217537
0.166048911788802	1658.72753956311	124.639999389648	0.193813819379553
0.166581177306691	1662.65170699811	125.040000915527	0.193812682726017
0.167113461157703	1666.51001243805	125.440002441406	0.193819667645327
0.167648073315151	1670.41936092416	125.839996337891	0.193820125973365
0.168180357166163	1674.23781985711	126.23999786377	0.193819319316017
0.168712641017174	1678.05814487991	126.639999389648	0.193820804298863
0.169247253174622	1681.94630775761	127.040000915527	0.193823444268365
0.169777190386076	1685.73600695272	127.440002441406	0.193816587680907
0.170311802543524	1689.54370842647	127.839996337891	0.193826927561459
0.170848779673652	1693.63033544925	128.240005493164	0.19381070274889
0.171376351912425	1697.26229516621	128.639999389648	0.193817651001957
0.171913329042553	1701.19041432091	129.039993286133	0.193816917677094
0.172445594560443	1705.03774276169	129.440002441406	0.193814626036901
0.172975531771896	1708.81163507798	129.839996337891	0.193823224270907
0.173512490568902	1712.62647160119	130.240005493164	0.1938176876682
0.174044774419914	1716.49762013017	130.639999389648	0.193814589370658
0.174577039937804	1720.15614418514	131.039993286133	0.193819300982896
0.175111670428374	1724.05923578172	131.440002441406	0.193814424372564
0.175643935946264	1727.94465440963	131.839996337891	0.193815194363669
0.176176219797275	1731.65663645058	132.240005493164	0.193816771012122
0.176710831954723	1735.49474421204	132.639999389648	0.193809767759691
0.177245462445293	1739.27006353823	133.039993286133	0.19381614768599
0.177775381323625	1743.11574542912	133.440002441406	0.193816917677094
0.178310011814195	1746.94737676108	133.839996337891	0.193821574289968
0.178844623971643	1750.65046743269	134.240005493164	0.193834975801819
0.179374561183096	1754.31755354701	134.639999389648	0.193828394211183
0.179909173340544	1758.11087515185	135.039993286133	0.193815341028641
0.180443803831114	1761.97620587127	135.440002441406	0.193821372625631
0.180976069349004	1765.70608042087	135.839996337891	0.193819795977178
0.181510699839573	1769.62662544614	136.240005493164	0.193811014411956
0.182042965357463	1773.41094591165	136.639999389648	0.193821922619277
0.182572902568917	1776.99669246208	137.039993286133	0.19382076763262
0.183109861365923	1780.85357089214	137.440002441406	0.193811472739995
0.183642145216934	1784.65688156622	137.839996337891	0.193817156007675
0.184174429067946	1788.23681030709	138.240005493164	0.193813049388448
0.184711387864952	1792.09017609741	138.639999389648	0.193815689357951
0.185243671715963	1795.73552775337	139.039993286133	0.193821262626902
0.185773590594295	1799.43817934502	139.440002441406	0.193814571037537
0.186308221084865	1803.05938160279	139.839996337891	0.193807879448172
0.186842833242313	1806.75281251513	140.240005493164	0.193810317753337
0.187372770453767	1810.40134750085	140.639999389648	0.193806596129663
0.187907382611215	1814.09697381302	141.039993286133	0.193803534498365
0.188442013101784	1817.88151381852	141.440002441406	0.193811527739359
0.188971931980116	1821.41797364266	141.839996337891	0.193813471050244
0.189506562470686	1825.17155851048	142.240005493164	0.193810666082647
0.190041174628134	1828.89868881029	142.639999389648	0.193817522670106
0.190571111839587	1832.54371115627	143.039993286133	0.193818329327454
0.191108070636593	1836.28401385509	143.440002441406	0.193801554521238
0.191640354487605	1839.7822737221	143.839996337891	0.193804579486293
0.192170273365937	1843.40413459982	144.240005493164	0.193813177720299
0.192707250496065	1847.08823506286	144.639999389648	0.193797887896928
0.193239516013955	1850.69374021182	145.039993286133	0.193810592750161
0.193769453225408	1854.22065004668	145.440002441406	0.193805276144912
0.194304065382856	1857.92428956825	145.839996337891	0.193811069411321
0.194838695873426	1861.45141894309	146.240005493164	0.193812829390989
0.195368633084879	1865.08612290985	146.639999389648	0.193798767886763
0.195905591881885	1868.81325320966	147.039993286133	0.193807201122674
0.196440204039333	1872.48088817394	147.440002441406	0.193800124537757
0.196970141250787	1876.01701868811	147.839996337891	0.193797374569525
0.197504753408235	1879.63481807613	148.240005493164	0.193809859425299
0.198037037259246	1883.32704151857	148.639999389648	0.193810482751432
0.198569321110258	1886.94198688681	149.039993286133	0.193805771139194
0.199103933267706	1890.58525291292	149.440002441406	0.193814277707592
0.199638563758276	1894.20458908083	149.839996337891	0.193808869436735
0.200168482636607	1897.7128380171	150.240005493164	0.193800931195105
0.200705459766735	1901.34490750405	150.639999389648	0.193812829390989
0.201237725284625	1904.87247595886	151.039993286133	0.193797154572067
0.201767662496079	1908.33615827848	151.440002441406	0.193816349350327
0.202304621293085	1912.01169668216	151.839996337891	0.193803167835934
0.202836905144096	1915.73355802237	152.240005493164	0.193801719519332
0.203369170661986	1919.29427701469	152.639999389648	0.193814112709498
0.203903801152556	1922.86092358656	153.039993286133	0.193799757875326
0.204436066670446	1926.43986439751	153.440002441406	0.193793066285961
0.204966003881899	1929.99443627029	153.839996337891	0.193798914551735
0.205500616039348	1933.70466199137	154.240005493164	0.193804707818144
0.206035246529917	1937.35012341732	154.639999389648	0.193801847851183
0.206567512047807	1940.8473953544	155.039993286133	0.193798749553641
0.207102142538377	1944.48451426098	155.440002441406	0.193790499648945
0.207636754695825	1947.99803215685	155.839996337891	0.193806632795906
0.208166691907278	1951.44766391752	156.240005493164	0.193805459476128
0.208701304064726	1955.07578168477	156.639999389648	0.193797227904552
0.209233587915738	1958.62135241822	157.039993286133	0.193810006090271
0.209765853433628	1962.13135767436	157.440002441406	0.193800674531404
0.210302830563756	1965.74871798242	157.839996337891	0.193804121158254
0.210832749442087	1969.13139004812	158.240005493164	0.193802067848641
0.211362686653541	1972.63700450458	158.639999389648	0.193807714450078
0.211899645450547	1976.16369479946	159.039993286133	0.193791232973807
0.212431929301559	1979.74263561041	159.440002441406	0.193813727713945
0.212961866513012	1983.25220178657	159.839996337891	0.193804139491376
0.213498825310018	1986.95167004846	160.240005493164	0.193802892839111
0.21403110916103	1990.38264091053	160.639999389648	0.193808392775575
0.21456337467892	1993.67881422274	161.039993286133	0.193804396155078
0.215098005169489	1997.32295840878	161.440002441406	0.191175041529607
0.215632617326937	2000.70936265421	161.839996337891	0.196585365695747
0.216162554538391	2004.27074026648	162.240005493164	0.196587987332128
0.216697166695839	2007.76647542368	162.639999389648	0.194745306952263
0.217231797186408	2011.18822560645	163.039993286133	0.196440937364195
0.217761716064741	2014.60141372985	163.440002441406	0.195620915170495
0.218298693194868	2018.18233040065	163.839996337891	0.195546666028228
0.218830958712758	2021.55797718689	164.240005493164	0.196113031152196
0.21936324256377	2025.08796058152	164.639999389648	0.195536821141956
0.219897854721218	2028.56020496049	165.039993286133	0.195829967755502
0.220427791932671	2031.85001161317	165.440002441406	0.195849639194922
0.220960057450561	2035.35321112981	165.839996337891	0.19567061626301
0.221497034580689	2038.93281056071	166.240005493164	0.195812807953733
0.222029300098579	2042.27025738982	166.639999389648	0.195805034710197
0.22256158394959	2045.52383994522	167.039993286133	0.195720794016686
0.223096196107038	2048.95195678751	167.440002441406	0.195799314776274
0.22362847995805	2052.30389325552	167.839996337891	0.195784153284754
0.22416074547594	2055.72322849847	168.240005493164	0.195754270296632
0.224695375966509	2059.33575892689	168.639999389648	0.195759733566853
0.2252276414844	2062.69647699425	169.039993286133	0.195824797815225
0.225759925335411	2066.28815112424	169.440002441406	0.195714982417156
0.226294537492859	2069.68223926909	169.839996337891	0.195797939792158
0.22682682134387	2072.99707347989	170.240005493164	0.19578611492876
0.227359105194882	2076.49610173685	170.639999389648	0.195739237136963
0.22789371735233	2079.9472702774	171.039993286133	0.195782979964975
0.228428329509778	2083.35804346099	171.440002441406	0.195774950057737
0.22896061336079	2086.84346023897	171.839996337891	0.195752070322046
0.229495225518238	2090.31372875809	172.240005493164	0.195764206848511
0.230025162729691	2093.68783876444	172.639999389648	0.195790826540998
0.230557446580703	2096.99630631572	173.039993286133	0.195735112184615
0.231094405377709	2100.44066911678	173.440002441406	0.195783933287296
0.23162668922872	2103.76977342651	173.839996337891	0.195762153538897
0.232158954746611	2107.2005247486	174.240005493164	0.195767891805942
0.23269358523718	2110.72721504348	174.639999389648	0.195764866840886
0.23322585075507	2114.05083085362	175.039993286133	0.195773116745583
0.233758134606081	2117.41484202073	175.440002441406	0.195756818600527
0.23429274676353	2120.78741524719	175.839996337891	0.195762061873289
0.234825030614541	2124.1606470936	176.240005493164	0.195773648406108
0.235357296132431	2127.45155144621	176.639999389648	0.195757643590996
0.235891926623001	2130.64168694638	177.039993286133	0.195768130136522
0.236424192140891	2134.04126359082	177.440002441406	0.195767286812931
0.236956475991902	2137.38441845949	177.839996337891	0.195765050172102
0.237493434788909	2140.53174366289	178.240005493164	0.195751190332212
0.238023372000362	2143.78027679867	178.639999389648	0.195775481718262
0.238555637518252	2147.06700989159	179.039993286133	0.195757075264229
0.23909261464838	2150.44704747749	179.440002441406	0.1957548386234
0.23962488016627	2153.592835901	179.839996337891	0.195765068505223
0.240157164017281	2156.83851501701	180.240005493164	0.195766901817378
0.240691776174729	2159.98693792032	180.639999389648	0.19574950368503
0.241221713386183	2163.24205725561	181.039993286133	0.195773721738594
0.241756325543631	2166.38477211935	181.440002441406	0.195747065379864
0.2422909560342	2169.70377758984	181.839996337891	0.195757221929201
0.242823221552091	2172.85527405293	182.240005493164	0.195760045229919
0.243355505403102	2176.13081060668	182.639999389648	0.195751043667239
0.24389011756055	2179.28033120991	183.039993286133	0.195753665303621
0.244422401411561	2182.29944506295	183.440002441406	0.195742262102018
0.244954685262573	2185.70846192667	183.839996337891	0.195762190205141
0.245486950780463	2188.85666529	184.240005493164	0.195742738763178
0.246019234631474	2192.08500074731	184.639999389648	0.195760100229284
0.246551500149365	2195.30477414526	185.039993286133	0.195756305273124
0.247088477279492	2198.44156142944	185.440002441406	0.195755865278206
0.247620742797382	2201.74476002112	185.839996337891	0.195758560247074
0.248153026648394	2204.95180010003	186.240005493164	0.195753426973041
0.2486899854454	2208.14391146006	186.639999389648	0.195752143654532
0.249217576017295	2211.26730680525	187.039993286133	0.19575839524898
0.249752188174743	2214.48817790312	187.440002441406	0.195748275365886
0.250289165304871	2217.74044321863	187.839996337891	0.195752986978124
0.250819084183203	2220.90335576085	188.240005493164	0.195748367031494
0.251353714673772	2224.11829927916	188.639999389648	0.195746808716162
0.25188832683122	2227.29745778017	189.039993286133	0.195757551925389
0.252418264042674	2230.34291643122	189.440002441406	0.195743215424339
0.252950529560564	2233.64699318283	189.839996337891	0.19575945857003
0.253487506690692	2236.91594353709	190.240005493164	0.195746570385582
0.254019772208582	2240.04153428212	190.639999389648	0.195753720302985
0.254552056059593	2243.02705851768	191.039993286133	0.195747835370969
0.255086668217041	2246.29205715223	191.440002441406	0.195755810278842
0.255618952068053	2249.52632018909	191.839996337891	0.195749852014339
0.256151217585943	2252.5590455211	192.240005493164	0.195753005311245
0.256685848076513	2255.57464673439	192.639999389648	0.195742500432598
0.257218113594402	2258.70221333928	193.039993286133	0.195750548672958
0.257750397445414	2261.74284211069	193.440002441406	0.195750493673593
0.25828735624242	2264.8633834361	193.839996337891	0.195746332055002
0.258817293453874	2268.08776717371	194.240005493164	0.195755663613869
0.259349577304885	2271.16879130209	194.639999389648	0.1957548386234
0.259886536101891	2274.29416250713	195.039993286133	0.195758651912682
0.260416473313345	2277.21075118787	195.440002441406	0.195744113747295
0.260951085470793	2280.1980317433	195.839996337891	0.195754691958428
0.261485697628241	2283.32296386838	196.240005493164	0.195743967082322
0.262017981479252	2286.53000394729	196.639999389648	0.195750860336024
0.262550265330264	2289.41827197016	197.039993286133	0.195750787003538
0.263084877487712	2292.59677185121	197.440002441406	0.195751245331576
0.263617161338724	2295.46132955586	197.839996337891	0.195747560374145
0.264149426856613	2298.4764916892	198.240005493164	0.195754416961604
0.264681710707625	2301.70175358673	198.639999389648	0.195745983725693
0.265216322865073	2304.69232724191	199.039993286133	0.195742298768261
0.265748606716085	2307.65304345934	199.440002441406	0.195740245458648
0.266283218873533	2310.68532971138	199.839996337891	0.195747743705361
0.266815502724544	2313.62101837069	200.240005493164	0.195742720430057
0.267347768242434	2316.54397371095	200.639999389648	0.19574371041862
0.267882398733004	2319.76594250874	201.039993286133	0.19574097878351
0.268412317611336	2322.60152093557	201.440002441406	0.195741290446576
0.268946948101906	2325.4197557037	201.839996337891	0.195749668683123
0.269483906898911	2328.4074753391	202.240005493164	0.19573742215793
0.270013844110365	2331.28827900253	202.639999389648	0.195750585339201
0.270548456267813	2334.40508814822	203.039993286133	0.195742023771438
0.271080740118824	2337.23934933515	203.440002441406	0.195731720557128
0.271610677330278	2340.1159817389	203.839996337891	0.195744572075333
0.272145289487726	2342.98668656309	204.240005493164	0.195734177195416
0.272679901645174	2345.84817070797	204.639999389648	0.195739017139504
0.273212185496186	2348.74280539036	205.039993286133	0.195731353894697
0.273746797653634	2351.86663981553	205.440002441406	0.195739658798758
0.274279081504645	2354.68597228358	205.839996337891	0.195736230505029
0.274811365355657	2357.46732433449	206.240005493164	0.195734507191604
0.275343630873547	2360.33868777863	206.639999389648	0.195736138839421
0.275880589670553	2363.4012705484	207.039993286133	0.195734268861024
0.276412873521565	2366.32071324892	207.440002441406	0.195739053805747
0.276945157372576	2369.14663191648	207.839996337891	0.195732618880084
0.277479769530024	2371.9876988429	208.240005493164	0.195725468962681
0.278009706741478	2374.93063232166	208.639999389648	0.195736413836244
0.278544318898926	2377.80924058526	209.039993286133	0.19573115223036
0.279078949389495	2380.48038356445	209.440002441406	0.19573269221257
0.279608868267827	2383.49027673818	209.839996337891	0.195737880485968
0.280143498758397	2386.35724938265	210.240005493164	0.195735918841963
0.280678110915845	2389.40929423321	210.639999389648	0.195729502249421
0.281210394766856	2392.17396124537	211.039993286133	0.195732655546327
0.281742660284746	2394.99219601351	211.440002441406	0.19573269221257
0.282277290775316	2397.84358131915	211.839996337891	0.195731812222736
0.282809556293206	2400.42778646488	212.240005493164	0.195717934049724
0.283344186783776	2403.21682241521	212.639999389648	0.195743783751107
0.283878798941224	2406.04691234246	213.039993286133	0.195729300585084
0.284408736152677	2408.81070119469	213.440002441406	0.195730217241161
0.284943348310125	2411.72970481525	213.839996337891	0.195737990484698
0.285477978800695	2414.50095802691	214.240005493164	0.195727705603509
0.286007897679027	2417.22896186183	214.639999389648	0.195738118816548
0.286540181530038	2419.83885318563	215.039993286133	0.195728457261493
0.28714983115398	-18.1983124155132	215.380004882813	0.196194998538635