File: CouponData/2-0T-1.txt
File Path: C:\Users\MTS\Desktop\SE171\Test Run 10 2-3-2017 3 06 06 PM\DAQ- Crosshead, … - (Timed).txt
Test: MTS EM Tension (Extensometer-Crosshead) 171-2017-W
Test Run: Test Run 10
Date: 2/3/2017 1:25:13 PM


Crosshead 	Load 	Time 	Extensometer
in	lbf	sec	in
0.000279034388875616	6.46289864648738	0.230000004172325	-0.000531120449737701
0.000806620395394028	18.8566390743039	0.629999995231628	-0.000465770462478831
0.00133889608243737	31.1990260126998	1.02999997138977	-0.000397635308826732
0.00187117176948071	43.2198486208946	1.42999994754791	-0.000324186665124231
0.00240110267892363	55.2217633480109	1.83000004291534	-0.000253085788896474
0.0029357231435674	67.2004891643703	2.23000001907349	-0.000175611932904507
0.00346799897383825	78.986959700808	2.63000011444092	-0.000106509384828873
0.00400027451765409	90.6048303905451	3.02999997138977	-3.14445126454889E-05
0.00453255034792492	102.263549238462	3.4300000667572	4.0022054751652E-05
0.00506482617819579	113.799771636212	3.82999992370605	0.000112156156348188
0.00559710143555661	125.367141269121	4.23000001907349	0.000187366489497679
0.00613172218665539	136.953336455614	4.63000011444092	0.000260443242965037
0.00666634236484413	148.406682509595	5.03000020980835	0.00033421506164513
0.00719627327428705	159.640255318847	5.42999982833862	0.000408625299056925
0.00772854910455791	170.901641099759	5.82999992370605	0.000477081604598008
0.00826316985565669	181.840275662433	6.23000001907349	0.000550709533338768
0.00879310076509961	192.89619946129	6.63000011444092	0.000619743224787965
0.00932537602246043	203.817819675244	7.03000020980835	0.000685999340902075
0.00985999620064917	214.816251440923	7.42999982833862	0.000759257492013496
0.01039227203092	225.705064148593	7.82999992370605	0.000836261615476122
0.0109268933549289	236.635342470646	8.22999954223633	0.000903588357243106
0.0114591691851997	247.456221274674	8.63000011444092	0.000976084466376453
0.0119890995217326	258.214092103438	9.02999973297119	0.00104413128446047
0.0125237196999213	269.00964148187	9.43000030517578	0.00111551988685657
0.0130559955301922	279.710980764882	9.82999992370605	0.00118475176937563
0.013588271360463	290.30770924576	10.2299995422363	0.001255580781882
0.0141228915386518	300.966704754457	10.6300001144409	0.00132722662088982
0.0146551673689226	311.555996318394	11.0299997329712	0.00140078597945917
0.0151874431991935	321.978053299904	11.4300003051758	0.00146808156924227
0.0157197190294644	332.468716526254	11.8299999237061	0.00153961769597583
0.0162543392076531	342.829302312386	12.2299995422363	0.00160774672665179
0.016786615037924	353.154706816161	12.6300001144409	0.00168050472729099
0.0173188908681948	363.377970342613	13.0299997329712	0.00174967358970472
0.0178535110463835	373.647995885552	13.4300003051758	0.00182167706781023
0.0183834425287365	383.737943757028	13.8299999237061	0.00189086326075293
0.0189157183590074	393.80879164994	14.2299995422363	0.00196356454329734
0.019450337391376	403.811966342938	14.6300001144409	0.00203068009609774
0.0199802700195491	413.764290087259	15.0299997329712	0.00210180086304624
0.0205148890519177	423.588896446182	15.4300003051758	0.00216834064124805
0.0210471660280087	433.504090490795	15.8299999237061	0.00223823180000525
0.0215794407124594	443.19979943691	16.2299995422363	0.0023017181108768
0.0221140620364683	452.755140006074	16.6299991607666	0.00237181838180166
0.0226463367209191	462.353894606977	17.0300006866455	0.00243977353427794
0.02317861369701	471.801084291772	17.4300003051758	0.00251128674460956
0.0237132327293787	481.012707574278	17.8299999237061	0.00257524384431336
0.0242455097054696	490.20852397797	18.2299995422363	0.00264028689501382
0.0247777843899204	499.151814515647	18.6299991607666	0.00270341785842787
0.0253100613660113	507.854983196377	19.0300006866455	0.00276375359371598
0.02584468039838	516.363255256757	19.4300003051758	0.00282656859723837
0.0263769573744709	524.813184566522	19.8299999237061	0.00288582239190014
0.0269092320589217	533.01514346493	20.2299995422363	0.00294974139308572
0.0274415090350126	541.122151320475	20.6299991607666	0.00300199565923164
0.0279737837194634	549.144197202409	21.0300006866455	0.00306244053388396
0.0285084050434722	557.061412742221	21.4300003051758	0.00312096730569436
0.029040679727923	564.936970570167	21.8299999237061	0.00317545678039397
0.0295729567040139	572.666479424092	22.2299995422363	0.00323448255685649
0.0301052313884647	580.227875535655	22.6299991607666	0.00328919919039028
0.0306375060729154	587.657383002132	23.0300006866455	0.00334077541749397
0.0311674387010885	594.983432251387	23.4300003051758	0.00339650409662817
0.0317044043730152	602.380008720341	23.8299999237061	0.00344983600657507
0.032236679057466	609.613576751548	24.2299995422363	0.00350229795261352
0.0327689537419168	616.665091251441	24.6299991607666	0.00355723601588099
0.0333035750659256	623.731150275243	25.0300006866455	0.00360930551853632
0.0338358497503763	630.699514006386	25.4300003051758	0.00366128564722411
0.0343681267264673	637.500588270108	25.8299999237061	0.00371104431719937
0.0349004014109181	644.432453478997	26.2299995422363	0.00375947068485717
0.0354350227349269	651.12759970068	26.6299991607666	0.00380848285303943
0.0359672974193777	657.734820158975	27.0300006866455	0.00385778577307122
0.0364995743954686	664.145277907061	27.4300003051758	0.00390628146284487
0.0370341957194775	670.319510632905	27.8299999237061	0.00395136031709012
0.0375664704039282	676.390340026523	28.2299995422363	0.00400020032580284
0.038098745088379	682.346734203743	28.6299991607666	0.00404066324378839
0.0386310220644699	688.424588876833	29.0300006866455	0.0040893537229785
0.0391632967489207	694.284056151341	29.4300003051758	0.00413057517386811
0.0397002647124878	700.033094814149	29.8299999237061	0.00417275510326862
0.0402301927573803	705.675766354955	30.2299995422363	0.00421304758051484
0.0407624674418311	711.083859423394	30.6299991607666	0.00425673082588224
0.0412970887658398	716.370656650954	31.0300006866455	0.0042986432062902
0.0418293634502905	721.75031929153	31.4300003051758	0.00433922901348114
0.0423592960784638	727.131683366979	31.8299999237061	0.00438121816383559
0.0428962594587504	732.625945878942	32.2299995422363	0.00441677324789189
0.0434285387264815	737.761095862901	32.6300010681152	0.00445363370749339
0.0439608134109323	743.162383191852	33.0299987792969	0.00449343691955827
0.0444954347349409	748.597973643224	33.4300003051758	0.00452983761884595
0.04503005605895	753.946351836154	33.8300018310547	0.00456916273747547
0.0455623307434008	759.425027009287	34.2299995422363	0.00461356527140862
0.0460946054278512	764.983065886456	34.6300010681152	0.00465271966284374
0.0466292267518602	753.327413737683	35.0299987792969	0.00385000765979965
0.0471638480758689	759.330899241364	35.4300003051758	0.00384427855931604
0.0476961227603197	765.255405235982	35.8300018310547	0.00385674651424349
0.0482307440843287	770.867011869122	36.2299995422363	0.00387978007628282
0.0487606721292213	776.711385769764	36.6300010681152	0.00390245270499168
0.0492952934532303	782.446264103638	37.0299987792969	0.00392423675021553
0.0498275681376811	788.108419817979	37.4300003051758	0.00395097188407732
0.0503575007658539	793.696974752851	37.8300018310547	0.00397281723067634
0.0508944641461406	799.355178747489	38.2299995422363	0.00399688145789268
0.0514267434138716	805.07918985218	38.6300010681152	0.00402272657599433
0.0519590180983224	810.512914213693	39.0299987792969	0.00404767537632532
0.0524936394223311	816.082149630018	39.4300003051758	0.00400101586325665
0.053023567467224	821.620649448656	39.8300018310547	0.00320895884129197
0.0535581887912327	826.973418441254	40.2299995422363	0.0186286571959957
0.0540904634756835	832.349239132121	40.6300010681152	0.0889900353128516
0.0546250847996925	837.480162971396	41.0299987792969	0.0610921255085528
0.0551573594841433	842.891988219557	41.4300003051758	0.111896326530754
0.055691980808152	848.1603440885	41.8300018310547	0.196904967003685
0.0562242554926028	853.415692213423	42.2299995422363	0.169363228501532
0.056754188120776	858.871809653253	42.6300010681152	0.186705426496314
0.0572888094447847	864.317608713858	43.0299987792969	0.192018310121429
0.0578234307687933	869.745295725825	43.4300003051758	0.216777887430013
0.0583510167574087	875.139448005314	43.8300018310547	0.206706073780463
0.058885633498137	880.551547678453	44.2299995422363	0.205530755691172
0.0594179127658681	885.820891477322	44.6300010681152	0.20468251882341
0.0599501874503189	891.175855869757	45.0299987792969	0.204808742365265
0.0604848087743276	896.638888819067	45.4300003051758	0.204618701227303
0.0610170834587783	902.167015373483	45.8300018310547	0.204344107732763
0.0615517047827874	907.607655244477	46.2299995422363	0.204962832251872
0.0620886681630736	913.122554514886	46.6300010681152	0.204737683186146
0.0626186007912468	918.46023013362	47.0299987792969	0.204473392905917
0.0631532221152559	923.858718327782	47.4300003051758	0.204980615379773
0.0636878388559843	929.278062820376	47.8300018310547	0.204494915990613
0.0642201181237154	934.035384492738	48.2299995422363	0.205198504529365
0.0647523928081662	939.277999298618	48.6300010681152	0.204514789094371
0.0652870141321748	944.601295048433	49.0299987792969	0.204728938287168
0.0658192888166256	949.906259209626	49.4300003051758	0.205166604897873
0.0663539101406346	955.268742846494	49.8300018310547	0.204660684075646
0.0668861848250854	960.621127644122	50.2299995422363	0.204681913830398
0.0674208061490941	965.868243019664	50.6300010681152	0.204796660838165
0.0679507341939866	971.270902473512	51.0299987792969	0.2047612962467
0.0684853555179957	976.641179779795	51.4300003051758	0.204743733116257
0.0690176302024465	981.927373272399	51.8300018310547	0.2047117784854
0.0695499094701776	987.164280038708	52.2299995422363	0.204809897351922
0.0700845307941862	992.514140126526	52.6300010681152	0.204808999028966
0.070616805478637	997.832496226712	53.0299987792969	0.20481614894637
0.0711490801630878	1003.0856489518	53.4300003051758	0.204761131248606
0.0716837014870969	1008.34857120615	53.8300018310547	0.204817432264878
0.0722136295319894	1013.37922015797	54.2299995422363	0.204815342289022
0.0727459087997205	1018.50460061266	54.6300010681152	0.204764137880539
0.0732805255404492	1023.53964036415	55.0299987792969	0.204805020741591
0.0738128048081803	1028.49290147178	55.4300003051758	0.204796972501231
0.0743474215489087	1033.39413160332	55.8300018310547	0.204763111225733
0.0748797008166398	1038.66528660706	56.2299995422363	0.204780399359352
0.0754119755010906	1043.54697768007	56.6300010681152	0.204785184304076
0.0759442501855413	1048.46028251071	57.0299987792969	0.204772516117087
0.07647887150955	1053.6614042597	57.4300003051758	0.204786724286286
0.0770111461940008	1058.55319417196	57.8300018310547	0.204788740929656
0.0775434208784516	1063.66606084759	58.2299995422363	0.204755117984738
0.0780780422024606	1068.70406438885	58.6300010681152	0.204784927640374
0.0786103168869114	1073.75282538931	59.0299987792969	0.204798072488524
0.0791425915713618	1078.87699837409	59.4300003051758	0.204764339544876
0.0796772128953709	1084.0859137925	59.8300018310547	0.204781994340927
0.0802094875798217	1089.18615691909	60.2299995422363	0.204792242555872
0.0807417622642724	1094.52932103741	60.6300010681152	0.204757959618578
0.0812763835882811	1099.75107954486	61.0299987792969	0.204780087696286
0.0818086582727319	1104.99995124027	61.4300003051758	0.204764871205401
0.0823409421237433	1110.29097461251	61.8300018310547	0.204768446164103
0.0828755542811917	1115.49231590149	62.2299995422363	0.204763166225097
0.0834078381322031	1120.48663098604	62.6300010681152	0.204770646138689
0.0839424594562118	1125.7468089906	63.0299987792969	0.204796349175098
0.0844747341406626	1131.01093871486	63.4300003051758	0.204751213029848
0.0850070088251134	1136.13522146963	63.8300018310547	0.204780087696286
0.0855392835095642	1141.47037237856	64.2300033569336	0.20476840949786
0.0860739048335732	1146.7826911292	64.629997253418	0.204768244499766
0.0866061795180236	1152.03364845445	65.0299987792969	0.204784872641009
0.0871384542024744	1157.36539649363	65.4300003051758	0.2047591696046
0.0876730755264835	1162.667945715	65.8300018310547	0.204763496221285
0.0882053502109343	1167.94294266845	66.2300033569336	0.204753706334379
0.088737624895385	1173.30257228553	66.629997253418	0.204779629368247
0.089274592858952	1178.65232260336	67.0299987792969	0.204752698012694
0.0898045209038445	1183.87561789069	67.4300003051758	0.204743953113715
0.0903367955882953	1189.11021948717	67.8300018310547	0.20476817116728
0.0908690702727461	1194.41573249832	68.2300033569336	0.204687303768133
0.0913990074841996	1199.62563584666	68.629997253418	0.204742761460815
0.0919336288082083	1204.95233446622	69.0299987792969	0.20475608964018
0.0924659034926591	1210.19560789205	69.4300003051758	0.20474116647924
0.0929981781771098	1215.5650070384	69.8300018310547	0.204773781102473
0.0935327995011185	1220.93429641476	70.2300033569336	0.204751671357887
0.0940650741855693	1226.18338765015	70.629997253418	0.204730038274461
0.0945973488700201	1231.39263237854	71.0299987792969	0.204757006296257
0.0951319701940291	1236.64512648368	71.4300003051758	0.204738984837776
0.0956642448784799	1241.78433795733	71.8300018310547	0.204754219661782
0.0961988662024886	1246.16185545825	72.2300033569336	0.204754237994904
0.0967334875264976	1251.48471212809	72.629997253418	0.204737738185511
0.0972681088505063	1256.74302404279	73.0299987792969	0.204696103666476
0.0977980368953992	1261.94689004159	73.4300003051758	0.204761314579821
0.0983326582194079	1267.06623314673	73.8300018310547	0.204759701265125
0.0988672795434165	1272.22454459895	74.2300033569336	0.204724593337361
0.0993995542278673	1277.30546820699	74.629997253418	0.204738508176616
0.0999318289123181	1282.29550226185	75.0299987792969	0.204719221732748
0.100466450236327	1287.53175040821	75.4300003051758	0.204716948425676
0.10099637828122	1292.5002695447	75.8300018310547	0.204743623117528
0.101530999605229	1297.56395926403	76.2300033569336	0.204720560050621
0.10206327428968	1302.74126092482	76.629997253418	0.2047229250233
0.10259554897413	1307.92514878511	77.0299987792969	0.204731321592969
0.103130170298139	1313.14196764293	77.4300003051758	0.204714436788024
0.10366244498259	1318.36405546036	77.8300018310547	0.204733209904489
0.104194719667041	1323.56879961908	78.2300033569336	0.204740964814903
0.104729340991049	1328.70307144311	78.629997253418	0.204703271917002
0.105261624842061	1333.76116289286	79.0299987792969	0.204724721669212
0.105796236999509	1322.94420836604	79.4300003051758	0.204713281801367
0.10632852085052	1326.63533410855	79.8300018310547	0.204718928402803
0.106863133007969	1331.77487489218	80.2300033569336	0.204716966758798
0.107393070219422	1336.82176980278	80.629997253418	0.204728039964212
0.107927691543431	1341.89039917173	81.0299987792969	0.204709450178963
0.10846231286744	1346.84772176906	81.4300003051758	0.204680813843106
0.108994587551891	1351.74006053127	81.8300018310547	0.204755337982196
0.109526862236341	1356.64304698269	82.2300033569336	0.204667247333161
0.11006148356035	1361.64328964679	82.629997253418	0.20474756473866
0.110591411605243	1366.67778054831	83.0299987792969	0.204721293375483
0.111128379568809	1371.73850647787	83.4300003051758	0.204683288814515
0.11166065425326	1376.68232736621	83.8300018310547	0.204748591393467
0.112192928937711	1381.700023459	84.2300033569336	0.204691612051697
0.11272755026172	1386.64263687743	84.629997253418	0.20468737710062
0.113259824946171	1391.36318560256	85.0299987792969	0.204737554854295
0.113792099630622	1395.77078008121	85.4300003051758	0.204694802014846
0.11432672095463	1400.19341304873	85.8300018310547	0.204703785244405
0.114858995639081	1404.59639718773	86.2300033569336	0.204718323409792
0.115391270323532	1408.55975250978	86.629997253418	0.204696176998963
0.115925891647541	1412.70236222836	87.0299987792969	0.204715426776587
0.116458166331991	1416.83926390736	87.4300003051758	0.204711411822969
0.116990441016442	1420.76881007195	87.8300018310547	0.204704536902388
0.117522715700893	1423.66454245426	88.2300033569336	0.204683912140647
0.11805968366446	1426.14512472778	88.629997253418	0.204700613614377
0.118589611709352	1427.52603122397	89.0299987792969	0.204744503107362
0.119124233033361	1428.66401672842	89.4300003051758	0.204658374102331
0.11965885435737	1428.02526514644	89.8300018310547	0.204666184012111
0.120188791568824	1428.0830041621	90.2300033569336	0.204741148146119
0.120723403726272	1429.52724794353	90.629997253418	0.204632267737248
0.121258025050281	1431.89882861524	91.0299987792969	0.204711540154819
0.121790308901292	1434.77414377908	91.4300003051758	0.204720541717499
0.12232492105874	1437.67283995117	91.8300018310547	0.204645265920425
0.122857204909752	1440.76110889901	92.2300033569336	0.204728718289709
0.123389479594202	1443.41853062923	92.629997253418	0.204704261905565
0.123924100918211	1444.69515563326	93.0299987792969	0.204668017324265
0.124456375602662	1445.13313790033	93.4300003051758	0.204708570189129
0.124990996926671	1445.58791497615	93.8300018310547	0.204669868969542
0.125523271611122	1446.45970825061	94.2300033569336	0.20470407857435
0.126060230408128	1438.57064871368	94.629997253418	0.204703565246946
0.126590167619582	1432.31749136377	95.0299987792969	0.204649739202083
0.12712478894359	1432.39872115766	95.4300003051758	0.204705691889046
0.127659410267599	1434.0942284502	95.8300018310547	0.204681015507443
0.128189338312492	1436.50510677896	96.2300033569336	0.204689522075841
0.128726306276059	1439.13190268148	96.629997253418	0.204707140205648
0.129260918433507	1441.84881974724	97.0299987792969	0.20465633912584
0.12979085564496	1444.69537517324	97.4300003051758	0.20469780864678
0.130325476968969	1447.66871493972	97.8300018310547	0.20468074051062
0.13085775165342	1450.62273518765	98.2300033569336	0.204696396996421
0.13139002633787	1453.64481283046	98.629997253418	0.204709046850289
0.131926994301437	1456.77929494482	99.0299987792969	0.204584509955617
0.132459268985888	1459.95955114574	99.4300003051758	0.204712988471422
0.132991543670339	1463.21609749093	99.8300018310547	0.204696653660123
0.133526164994348	1466.43641973883	100.230003356934	0.204631992740424
0.134058439678798	1469.73292236102	100.629997253418	0.204683637143824
0.134590714363249	1472.94051128988	101.029998779297	0.204622917845259
0.135125335687258	1476.45282171584	101.430000305176	0.204667558996227
0.135657610371709	1479.76941224651	101.830001831055	0.204676230562719
0.136189885056159	1483.31937377964	102.230003356934	0.204626327805867
0.13672215974061	1486.73530615284	102.629997253418	0.20467269227026
0.137259127704177	1490.38647561836	103.029998779297	0.204665047358575
0.13778905574907	1493.87079469642	103.430000305176	0.204655165806061
0.138323677073079	1497.43502632848	103.830001831055	0.204670107300122
0.13885595175753	1500.97949936202	104.230003356934	0.204640407643215
0.13938822644198	1504.58741945079	104.629997253418	0.204671482284238
0.139922847765989	1508.26427509437	105.029998779297	0.20465195750979
0.14045512245044	1512.05408405947	105.430000305176	0.204648969210978
0.140987397134891	1515.66628517792	105.830001831055	0.204673773924432
0.1415220184589	1519.51240614878	106.230003356934	0.204636612687055
0.142054302309911	1523.06291653187	106.629997253418	0.204656797453878
0.142586576994362	1526.71595208725	107.029998779297	0.204659345757774
0.143121198318371	1530.52387310098	107.430000305176	0.20464651257269
0.143655810475819	1534.14353857887	107.830001831055	0.20466700900258
0.14418809432683	1537.86035049945	108.230003356934	0.204642882614624
0.144722706484278	1541.63786522547	108.629997253418	0.204659235759044
0.14525499033529	1545.20692673716	109.029998779297	0.204656302459596
0.145784918380183	1548.91023694876	109.430000305176	0.204636851017635
0.146319539704191	1552.76481020899	109.830001831055	0.204641874292939
0.1468541610282	1556.39270843626	110.230003356934	0.204650692524403
0.147386435712651	1560.17417488198	110.629997253418	0.204633606055121
0.14792105703666	1564.00262288417	111.029998779297	0.204652709167773
0.148453331721111	1567.74896293254	111.430000305176	0.204640425976337
0.148983259766003	1571.47883748214	111.830001831055	0.204617784571225
0.14952022772957	1575.22550684048	112.230003356934	0.204655000807967
0.150052502414021	1578.96899286906	112.629997253418	0.204627152796336
0.150584777098472	1582.87438963547	113.029998779297	0.204641067635591
0.151119398422481	1586.69197040847	113.430000305176	0.204648089221143
0.151651673106932	1590.42755299765	113.830001831055	0.204611789640479
0.152183947791382	1594.21110507321	114.230003356934	0.20465753077874
0.152718569115391	1597.91265896495	114.629997253418	0.204624494493712
0.153250843799842	1601.66426797291	115.029998779297	0.204636136025894
0.153783118484293	1605.33080523728	115.430000305176	0.204654267483105
0.154317748974862	1609.19064745711	115.830001831055	0.204598149798048
0.15485236113231	1612.93270647579	116.230003356934	0.204657494112497
0.155382298343763	1616.60110983002	116.629997253418	0.204645027589845
0.155916910501212	1620.42253255274	117.029998779297	0.204599213119098
0.156451540991781	1624.28907074207	117.430000305176	0.204651774178574
0.156981459870113	1628.03420332052	117.830001831055	0.204624347828739
0.157516090360683	1631.73323250244	118.230003356934	0.204600606436335
0.158048355878573	1635.41535710563	118.629997253418	0.204650124197635
0.158580639729584	1639.15950175416	119.029998779297	0.204605684711004
0.159117598526591	1643.11517317679	119.430000305176	0.204607353025065
0.159649882377602	1646.93736428945	119.830001831055	0.20464675090327
0.160182147895492	1650.74319967334	120.230003356934	0.204603961397578
0.160716778386061	1654.52795921882	120.629997253418	0.204603044741501
0.161246697264393	1658.26551766784	121.029998779297	0.204635549366005
0.161781327754963	1662.09923462964	121.430000305176	0.204604383059374
0.162315939912411	1666.02669516439	121.830001831055	0.204622477850341
0.162848223763423	1669.76798579313	122.230003356934	0.204623431172662
0.163382835920871	1673.55966084809	122.629997253418	0.204627464459402
0.163915119771882	1677.31906352547	123.029998779297	0.204616391253988
0.16444973192933	1681.0712213834	123.430000305176	0.20460634470338
0.164979669140784	1684.82337924133	123.830001831055	0.204635604365369
0.165514281298232	1688.52910439274	124.230003356934	0.204608324680507
0.166048911788802	1692.31375416823	124.629997253418	0.204611899639209
0.166578849000255	1696.05669134685	125.029998779297	0.204616446253352
0.167113461157703	1699.90303185769	125.430000305176	0.204620461206971
0.167645745008715	1703.73609019954	125.830001831055	0.204610542988214
0.168178010526605	1707.41140906324	126.230003356934	0.204607023028877
0.168712641017174	1711.14732096239	126.629997253418	0.204598388128628
0.169244906535064	1715.03021488049	127.029998779297	0.204580201672053
0.169777190386076	1718.78862962795	127.430000305176	0.204608544677965
0.170314149183082	1722.55319149494	127.830001831055	0.204638830994762
0.170844086394535	1726.29239649384	128.229995727539	0.2045985347936
0.171376351912425	1729.98648602613	128.630004882813	0.204612596297827
0.171910982402995	1733.77464844135	129.029998779297	0.204606436368987
0.172443247920885	1737.49892472138	129.429992675781	0.204592649861583
0.172975531771896	1741.1247373188	129.830001831055	0.204608453012357
0.173510143929344	1745.05878405305	130.229995727539	0.204621579527385
0.174044774419914	1748.75462990521	130.630004882813	0.204587498254429
0.174574693298246	1752.38055227263	131.029998779297	0.204597746469374
0.175109323788816	1756.18046007697	131.429992675781	0.20461879289291
0.175643935946264	1759.83086115255	131.830001831055	0.204593181522108
0.176173873157717	1763.51232713579	132.229995727539	0.204594098178186
0.176708485315165	1767.37063257573	132.630004882813	0.204602898076529
0.177243115805735	1771.00204344274	133.029998779297	0.204560640231361
0.177775381323625	1774.82983282498	133.429992675781	0.204605391381059
0.178310011814195	1778.65476818743	133.830001831055	0.204590449886998
0.178842277332084	1782.47410528031	134.229995727539	0.204607664688131
0.179374561183096	1786.00299097502	134.630004882813	0.204595546494788
0.179909173340544	1789.73912241415	135.029998779297	0.204563830194511
0.180441457191556	1793.50533083103	135.429992675781	0.204609296335949
0.180973741042567	1797.1850404944	135.830001831055	0.204590669884456
0.181510699839573	1801.00964654688	136.229995727539	0.20458810324744
0.182040637051027	1804.67332979146	136.630004882813	0.204610634653822
0.182575249208475	1808.33624464609	137.029998779297	0.204584326624401
0.183107533059486	1811.90047627815	137.429992675781	0.204590908215037
0.183639798577376	1815.63386346749	137.830001831055	0.204585903272854
0.184172082428388	1819.38953396515	138.229995727539	0.204566708494594
0.184709041225394	1823.01589541253	138.630004882813	0.204565828504759
0.185241325076406	1826.82688998604	139.029998779297	0.204622734514043
0.185773590594295	1830.48892668074	139.429992675781	0.204579596679042
0.186308221084865	1834.19355413224	139.830001831055	0.204581246659981
0.186838139963197	1837.91881834219	140.229995727539	0.204581338325589
0.187370423814209	1841.5221280913	140.630004882813	0.204584143293185
0.187907382611215	1845.32884163513	141.029998779297	0.204592796526556
0.188439666462226	1849.03292023667	141.429992675781	0.20458940489907
0.188971931980116	1852.70033566097	141.830001831055	0.20457838669302
0.189506562470686	1856.60770828723	142.229995727539	0.204577708367522
0.190036481349018	1860.14142386157	142.630004882813	0.204585536610423
0.190571111839587	1863.84879556287	143.029998779297	0.204584399956887
0.191105723997035	1867.62971315863	143.429992675781	0.204593474852053
0.191638007848047	1871.2349987676	143.830001831055	0.20457294175592
0.192170273365937	1874.92129463048	144.229995727539	0.20457365674766
0.192704903856507	1878.62844679179	144.630004882813	0.204582584977854
0.193237169374396	1882.46490800338	145.029998779297	0.204587956582467
0.193769453225408	1886.12661538811	145.429992675781	0.20456962346092
0.194304065382856	1889.74529293607	145.830001831055	0.20457116344313
0.194836349233868	1893.5053542334	146.229995727539	0.204586178269677
0.195368633084879	1897.16750069809	146.630004882813	0.204576370049649
0.195903245242327	1900.76685872751	147.029998779297	0.204576168385312
0.196435529093339	1904.47357180885	147.429992675781	0.204581649988655
0.196967794611229	1908.20267796851	147.830001831055	0.204568505140506
0.197504753408235	1911.93924848761	148.229995727539	0.204573051754649
0.198034690619688	1915.62752021034	148.630004882813	0.204564105191334
0.198569321110258	1919.31688963299	149.029998779297	0.204552940320311
0.199103933267706	1922.8910005643	149.429992675781	0.204587314923213
0.199633870479159	1926.66423426064	149.830001831055	0.2045577802644
0.200168482636607	1930.36040942278	150.229995727539	0.204553013652798
0.200703113127177	1934.12310519991	150.630004882813	0.204583831630119
0.201233032005509	1937.77932408505	151.029998779297	0.204556698610229
0.201767662496079	1941.42500505098	151.429992675781	0.204557138605146
0.202302274653527	1945.23424330462	151.830001831055	0.204567625150671
0.202834558504538	1948.99298736205	152.229995727539	0.204554315304428
0.203366824022428	1952.54975463466	152.630004882813	0.204560016905229
0.203901454512998	1956.44505256183	153.029998779297	0.204554296971306
0.204433720030888	1959.99259915514	153.429992675781	0.204518309053708
0.204966003881899	1963.60029970393	153.830001831055	0.204550227018322
0.205500616039348	1967.41941725682	154.229995727539	0.204550447015781
0.206030553250801	1971.07146488227	154.630004882813	0.204528777266112
0.206565165408249	1974.89321691497	155.029998779297	0.204570283453296
0.207102142538377	1978.49345310431	155.429992675781	0.204537540498212
0.207632061416709	1982.25329486166	155.830001831055	0.204527420615117
0.208166691907278	1985.96374012273	156.229995727539	0.20455754193382
0.208701304064726	1989.62456934752	156.630004882813	0.204534973861195
0.20923124127618	1993.18726419969	157.029998779297	0.204547678714428
0.209763525127191	1996.95654617633	157.429992675781	0.204554058640726
0.210300483924197	2000.62725470038	157.830001831055	0.204530555578902
0.210830421135651	2004.2970850645	158.229995727539	0.204552793655339
0.211362686653541	2007.98843034699	158.630004882813	0.204543590428322
0.211897317144111	2011.73839280509	159.029998779297	0.204526338960946
0.212429582662	2015.3138209763	159.429992675781	0.204549768690284
0.212961866513012	2019.07344319366	159.830001831055	0.204534075538239
0.21349647867046	2022.58300936983	160.229995727539	0.204544525417521
0.214028762521472	2026.27567189223	160.630004882813	0.204552775322218
0.21456337467892	2029.9927033528	161.029998779297	0.20453290221846
0.215095658529931	2033.66297279688	161.429992675781	0.204541793782411
0.215627924047821	2037.39142033659	161.830001831055	0.2045423804423
0.216160207898833	2041.12403913598	162.229995727539	0.204534295535698
0.216694820056281	2044.70627304668	162.630004882813	0.204537265501389
0.217227103907292	2048.39937464905	163.029998779297	0.204464318010751
0.217761716064741	2052.1153084097	163.429992675781	0.204493724337713
0.21829634655531	2055.90478806482	163.830001831055	0.204585096615506
0.218826265433642	2059.50085299448	164.229995727539	0.20451394577078
0.219360895924211	2063.13182478152	164.630004882813	0.204532957217825
0.219895508081659	2066.83195166336	165.029998779297	0.204549347028488
0.220427791932671	2070.40342811487	165.429992675781	0.204493614338984
0.220962404090119	2074.16963653174	165.830001831055	0.20456133688998
0.221494687941131	2077.85724963452	166.229995727539	0.204557046939538
0.222026953459021	2081.50029612065	166.630004882813	0.204495044322465
0.222559237310032	2085.0127163166	167.029998779297	0.204525715634813
0.22309384946748	2088.72118571781	167.429992675781	0.204537943826886
0.223626133318492	2092.37191610336	167.830001831055	0.204509839151553
0.224158417169503	2096.16227391842	168.229995727539	0.204516934069592
0.224693029326952	2099.87469503933	168.630004882813	0.204547275385754
0.225225313177963	2103.51357026577	169.029998779297	0.204517575728846
0.225757578695853	2107.04948123996	169.429992675781	0.20453064724451
0.226294537492859	2110.96387914569	169.830001831055	0.204536330512189
0.226824474704313	2114.52811077774	170.229995727539	0.204512625786028
0.227356758555324	2118.13822626635	170.630004882813	0.204507034183957
0.22789371735233	2121.89916572361	171.029998779297	0.204537632163819
0.228423654563784	2125.41422039937	171.429992675781	0.204506594189039
0.228958266721232	2129.11829900091	171.830001831055	0.204437038325888
0.229492897211801	2132.77627420591	172.229995727539	0.204514514097548
0.230025162729691	2136.31723459972	172.630004882813	0.204521059021941
0.230557446580703	2140.00682356235	173.029998779297	0.204488389399343
0.231089712098593	2143.81474457608	173.429992675781	0.204566341832163
0.231621995949604	2147.46613358159	173.830001831055	0.204496859301498
0.232154261467495	2151.21653511964	174.229995727539	0.204473796234591
0.232691238597622	2154.89426892317	174.630004882813	0.204558788586085
0.233223504115512	2158.67606467887	175.029998779297	0.204499774267824
0.233758134606081	2162.49364545187	175.429992675781	0.204503917553293
0.234290400123972	2165.99245416885	175.830001831055	0.204553361982107
0.234820337335425	2169.55580764097	176.229995727539	0.204504155883874
0.235354949492873	2173.28271840079	176.630004882813	0.204485822762326
0.235891926623001	2177.05287853737	177.029998779297	0.204535340523626
0.236421845501333	2180.65004116694	177.429992675781	0.204506997517713
0.236956475991902	2184.29155087319	177.830001831055	0.20450316589531
0.23749108814935	2188.00638693392	178.229995727539	0.204524578981278
0.238021025360804	2191.47467959319	178.630004882813	0.204513652440835
0.238555637518252	2195.2749167075	179.029998779297	0.20451312078031
0.239090268008822	2199.01719526617	179.429992675781	0.204520985689454
0.239620205220275	2202.50963732362	179.830001831055	0.204515907414785
0.240157164017281	2206.2172285649	180.229995727539	0.204489214389812
0.240689429535171	2209.58365467182	180.630004882813	0.204544012090118
0.241221713386183	2213.37818374657	181.029998779297	0.204512974115338
0.241751650597636	2216.95536823765	181.429992675781	0.204495319319288
0.242286262755084	2220.58787680457	181.830001831055	0.204550373683295
0.242818546606096	2224.17362335501	182.229995727539	0.204498380950586
0.243353158763544	2227.73675728714	182.630004882813	0.204504009218901
0.243887789254113	2231.56070471967	183.029998779297	0.204532718887245
0.244417708132445	2235.07224675569	183.429992675781	0.204520655693266
0.244952338623015	2238.68455764413	183.830001831055	0.204484851106884
0.245486950780463	2242.224639878	184.229995727539	0.204545203743019
0.246014541352358	2246.06307694944	184.630004882813	0.204505824197934
0.246551500149365	2249.49580413138	185.029998779297	0.204475226218072
0.247086130639934	2253.09560124076	185.429992675781	0.204507529178238
0.247616049518266	2256.67059033201	185.830001831055	0.204496914300862
0.248150680008836	2260.26028860215	186.229995727539	0.204508940828598
0.248685292166284	2264.01398323996	186.630004882813	0.204508995827962
0.249215229377737	2267.54572295445	187.029998779297	0.204500782589509
0.249749841535185	2271.02828571265	187.429992675781	0.20451346910962
0.250284472025755	2274.32555672477	187.830001831055	0.204497207630807
0.250816737543645	2277.75103908726	188.229995727539	0.204505035873708
0.251349021394656	2281.48826822631	188.630004882813	0.204512845783487
0.251883633552104	2285.15019515102	189.029998779297	0.204471834590585
0.252415917403116	2288.68654520517	189.429992675781	0.204492257687989
0.252950529560564	2292.36427900869	189.830001831055	0.204430823397683
0.253482813411576	2295.99305539589	190.229995727539	0.204509490822244
0.254012750623029	2299.62358810296	190.630004882813	0.20452188401241
0.254549709420035	2303.21218867318	191.029998779297	0.20448646442158
0.255084321577484	2306.82230416179	191.429992675781	0.204503697555835
0.255614258788937	2310.36282547563	191.830001831055	0.204485309434923
0.256148889279506	2313.87678245146	192.229995727539	0.204463254689701
0.256683501436954	2317.74134478094	192.630004882813	0.204505457535504
0.25721109200885	2321.10842950781	193.029998779297	0.204519977367769
0.257748050805856	2324.77101505247	193.429992675781	0.204480359492105
0.258282681296426	2328.35346850316	193.830001831055	0.20451086580636
0.258814946814315	2331.84305654082	194.229995727539	0.204492349353597
0.259347230665327	2335.31815493958	194.630004882813	0.204465821326718
0.259881842822775	2339.05428637871	195.029998779297	0.20450730918078
0.260414126673787	2342.47954920121	195.429992675781	0.204506539189675
0.260946392191677	2345.96408781926	195.830001831055	0.204460798051414
0.261481022682246	2349.53600335073	196.229995727539	0.204504210883238
0.262013288200136	2352.96741329277	196.630004882813	0.204492184355503
0.262547918690706	2356.22911882757	197.029998779297	0.204467892969452
0.263082530848154	2359.53846453879	197.429992675781	0.204482981128486
0.263612468059607	2362.85878724918	197.830001831055	0.204501167585061
0.264147080217056	2366.38745340391	198.229995727539	0.204468112966911
0.264679364068067	2369.77473580926	198.630004882813	0.204511617464343
0.265209282946399	2372.93962421134	199.029998779297	0.204490461042078
0.265708732176719	3.76175544279132	199.270004272461	0.204303756532237