File: CouponData/4-0T-2.txt
File Path: C:\Users\MTS\Desktop\SE171\Test Run 15 2-3-2017 3 06 28 PM\DAQ- Crosshead, … - (Timed).txt
Test: MTS EM Tension (Extensometer-Crosshead) 171-2017-W
Test Run: Test Run 15
Date: 2/3/2017 1:48:36 PM


Crosshead 	Load 	Time 	Extensometer
in	lbf	sec	in
0.000351724016281234	7.95188484806662	0.230000004172325	-0.000155680839908007
0.000682344604476071	16.5131715265707	0.430000007152557	-0.000114273067928601
0.00101531004188509	25.0659175851699	0.629999995231628	-7.5816445125498E-05
0.00134827547929411	33.5766749067695	0.829999983310699	-3.01536590272667E-05
0.00168124077347562	42.0812731027384	1.02999997138977	1.01191490532475E-05
0.00201420621088464	50.5077356464563	1.23000001907349	4.69177836039736E-05
0.00234482687069323	58.7074133872228	1.42999994754791	8.45222877514756E-05
0.00268013708570268	66.8060718627712	1.62999999523163	0.000127667105094072
0.00301075774551127	75.0256351236054	1.83000004291534	0.000163453653761631
0.00334606796052072	83.0318192417307	2.02999997138977	0.000207081863957532
0.00367668833387429	91.0688007031656	2.23000001907349	0.000243603769527321
0.00400965391451083	99.1448191179159	2.4300000667572	0.000281321266754283
0.00434261920869232	107.203089097126	2.63000011444092	0.000322249011726918
0.00467323986850091	115.134231704642	2.82999992370605	0.000361012678509065
0.00500854979705536	123.157869251455	3.02999997138977	0.00040637100543726
0.00534151537769189	131.115384099489	3.23000001907349	0.000443259895699902
0.00567448095832843	138.872527548837	3.4300000667572	0.000489981318860662
0.00600744653896496	146.998127696735	3.63000011444092	0.000526463299761453
0.0063380666258635	154.425288829639	3.82999992370605	0.000570079478846339
0.00667337712732795	162.348294736517	4.03000020980835	0.00060646839767115
0.00700634270796449	169.896861480294	4.23000001907349	0.000649882446929598
0.00733930771569098	177.524270520644	4.42999982833862	0.000687371030785362
0.00767227329632752	185.143391926617	4.63000011444092	0.000729658738888732
0.00800523887696405	192.613774993772	4.82999992370605	0.000773705424068087
0.00833820388469051	200.158883982809	5.03000020980835	0.000814462961046039
0.008673514386155	207.760003110136	5.23000001907349	0.000854078043773807
0.00900413504596358	215.167542857015	5.42999982833862	0.000897789003664819
0.00933944497451803	222.680379468478	5.63000011444092	0.000942516735664158
0.00967241055515457	230.096700814696	5.82999992370605	0.000982322883893055
0.010005375562881	237.632191208206	6.03000020980835	0.00102234100883984
0.0103383417164276	245.00522201393	6.23000001907349	0.00106537994524413
0.0106689623762362	252.274328079967	6.42999982833862	0.00110984306441488
0.0110019273839627	259.585146742867	6.63000011444092	0.00114923900904915
0.0113348923916892	266.929198270769	6.82999992370605	0.00119124856932404
0.0116678585452357	274.178600623287	7.03000020980835	0.00123418158898313
0.0120008235529622	281.37111467758	7.23000001907349	0.00127624879833164
0.0123337885606887	288.547739525568	7.42999982833862	0.00131952799888746
0.0126644092204973	295.797306533073	7.63000011444092	0.001363704376579
0.0130020652156998	302.952882985143	7.82999992370605	0.00140664613311633
0.0133326847296883	310.011066012036	8.02999973297119	0.00144787703702175
0.0136656508832348	317.15887623719	8.22999954223633	0.00149413064332114
0.0139986158909613	324.149029311697	8.43000030517578	0.00153538303135337
0.0143292365507699	331.151558952774	8.63000011444092	0.0015802321486692
0.0146645470522344	338.221871563754	8.82999992370605	0.00162436197741932
0.0149975120599609	345.158621537276	9.02999973297119	0.00166778025188938
0.0153304782135075	352.158489256051	9.22999954223633	0.00170887437352075
0.015663443221234	359.064640844373	9.43000030517578	0.00175338991396093
0.0159964082289604	365.897493520705	9.63000011444092	0.00179702832911706
0.0163317187304249	372.826120514836	9.82999992370605	0.00184239449775154
0.0166646837381514	379.528099918507	10.0299997329712	0.00188514547524277
0.016997649891698	386.365809916973	10.2299995422363	0.0019213714369657
0.0173306148994245	393.106153932761	10.4300003051758	0.00196724434453796
0.0176612355592331	399.626491442587	10.6300001144409	0.00200645316242769
0.0179942005669595	406.437746873042	10.8299999237061	0.0020494101010813
0.0183271667205061	413.001388644611	11.0299997329712	0.00208889305642916
0.0186601317282326	419.610420307769	11.2299995422363	0.00213247117280271
0.0189930967359591	426.069204294723	11.4300003051758	0.00217154492714853
0.0193260617436856	432.576671273015	11.6300001144409	0.00221375579369167
0.0196566835493143	438.965037810262	11.8299999237061	0.0022525619990449
0.0199919940507787	445.348794007856	12.0299997329712	0.00229132294450432
0.0203249579126851	451.649783631672	12.2299995422363	0.00233264164687464
0.0206555797183138	457.861667464686	12.4300003051758	0.00237185003508183
0.0209908902197783	464.139358407751	12.6300001144409	0.00241059493905989
0.0213215097337668	470.319573598147	12.8299999237061	0.00245171870878626
0.0216544758873134	476.322565136865	13.0299997329712	0.00249110083196561
0.02198744204086	482.282636608809	13.2299995422363	0.00252445164461085
0.0223204059027663	488.222071322305	13.4300003051758	0.00256152665902545
0.0226557164042308	494.111011839597	13.6300001144409	0.00259926710846122
0.0229863382098595	500.009776771148	13.8299999237061	0.00263522981801694
0.0233216464196838	505.764413703538	14.0299997329712	0.00267663030329667
0.0236546125732304	511.443473996607	14.2299995422363	0.0027136950053304
0.0239875787267769	517.275882968149	14.4300003051758	0.00275028104101872
0.0243228892282414	522.958949865916	14.6300001144409	0.00278775222273177
0.0246558530901478	528.500852554298	14.8299999237061	0.00282162524288608
0.0249888192436944	534.158233273996	15.0299997329712	0.00285807950926329
0.025321785397241	539.555953078216	15.2299995422363	0.00289343006443232
0.0256547492591474	545.065912698999	15.4300003051758	0.00293280015650066
0.0259877154126939	550.465663248065	15.6300001144409	0.00296694129855761
0.0263206815662405	555.810144606287	15.8299999237061	0.00300374647233943
0.0266536454281469	561.215987389896	16.0300006866455	0.00303867823026312
0.0269889559296114	566.469853619931	16.2299995422363	0.00306931344927912
0.0273195777352401	571.676463868518	16.4300003051758	0.00310909173975691
0.0276525415971465	576.934995323201	16.6299991607666	0.00314537356020956
0.027985507750693	582.082329776244	16.8299999237061	0.00317619325626113
0.0283184739042396	587.268577691361	17.0300006866455	0.00321362719882104
0.028651437766146	592.223101153899	17.2299995422363	0.00324207132335708
0.0289844039196926	597.024934557914	17.4300003051758	0.00327426313897448
0.0293150257253213	601.934397438839	17.6299991607666	0.00331061886482337
0.0296479895872277	606.596109448389	17.8299999237061	0.00333875820121369
0.0299809557407743	611.385483958342	18.0300006866455	0.00337310358570287
0.0303139218943208	615.908721123304	18.2299995422363	0.00340453171222581
0.0306492301041451	620.637008632848	18.4300003051758	0.00343628525165621
0.0309798519097738	625.247677596235	18.6299991607666	0.00346726822707157
0.0313151624112383	629.75796190217	18.8299999237061	0.00349644882747478
0.0316481285647848	634.205677312806	19.0300006866455	0.00353130209672184
0.0319810924266912	638.714095528881	19.2299995422363	0.00355837324232699
0.0323164029281557	643.213183295656	19.4300003051758	0.00358900015414729
0.0326470247337844	647.770394273062	19.6299991607666	0.00362000375432439
0.0329823329436087	652.178812026655	19.8299999237061	0.00365301225321573
0.0333152990971553	656.502926426583	20.0300006866455	0.00368365835752265
0.0336459209027839	661.005965913063	20.2299995422363	0.00371353103326428
0.0339812291126082	665.457797698391	20.4300003051758	0.00374363287302526
0.0343141952661548	669.730375087194	20.6299991607666	0.00377456686463148
0.0346471614197014	674.225566019263	20.8299999237061	0.00380509953274883
0.0349801252816078	678.538813190008	21.0300006866455	0.00383621112647004
0.0353130914351544	682.838833076749	21.2299995422363	0.00386642668887562
0.035646057588701	687.172717005945	21.4300003051758	0.00389849246428238
0.0359790214506073	691.424602751303	21.6299991607666	0.00392651435411278
0.0363119876041539	695.788892968213	21.8299999237061	0.00395644403440421
0.0366449537577005	700.020965230062	22.0300006866455	0.00398619955004098
0.036975573271689	704.203915420602	22.2299995422363	0.00401096301397134
0.0373085394252356	708.399159850221	22.4300003051758	0.00404539691306299
0.0376415055787821	712.52865205478	22.6299991607666	0.00407596853906362
0.0379768160802466	716.680317797675	22.8299999237061	0.00410060768151346
0.038309779942153	720.565132690628	23.0300006866455	0.00413118818761984
0.0386427460956996	724.590782482996	23.2299995422363	0.00415879614994032
0.0389757122492462	728.109679108458	23.4300003051758	0.00418041863453055
0.0393086784027928	731.797621521213	23.6299991607666	0.00421040417355169
0.0396416399730591	735.269152395235	23.8299999237061	0.00423150674227303
0.0399769527661638	738.895019877657	24.0300006866455	0.00425795370238047
0.0403099189197102	742.5112824858	24.2299995422363	0.00428291854419284
0.0406428850732567	746.171453090642	24.4300003051758	0.00431030650905472
0.0409758466435228	749.986728693824	24.6299991607666	0.00433569100747752
0.0413088127970697	753.725823922733	24.8299999237061	0.00436035965479484
0.0416417789506161	757.398124111662	25.0300006866455	0.00438627037109705
0.0419770917437209	761.20373995557	25.2299995422363	0.0044141272628335
0.042310053313987	764.906501317211	25.4300003051758	0.00444130554261772
0.0426453661070917	768.567824506967	25.6299991607666	0.00446736492907744
0.0429759856210803	772.027774646861	25.8299999237061	0.00449487377795957
0.0433089517746268	775.641128350222	26.0300006866455	0.00451909183152386
0.0436442599844512	779.303494354899	26.2299995422363	0.00454397675238449
0.0439748840817201	783.024203110191	26.4300003051758	0.00456550642554685
0.0443101922915441	786.466754706392	26.6299991607666	0.00459211580565303
0.0446408118055327	789.985322021879	26.8299999237061	0.0046139213350037
0.0449737779590791	793.538247344784	27.0300006866455	0.00463826772041882
0.045306744112626	796.954783452943	27.2299995422363	0.00466691007183161
0.0456397102661724	800.603263553662	27.4300003051758	0.00469058386084996
0.0459750184759969	804.329570578534	27.6299991607666	0.00471287493146661
0.0463079846295433	807.669267692467	27.8299999237061	0.00474011680426618
0.0466386041435319	811.354026775461	28.0300006866455	0.0050514871135398
0.0469739169366366	814.743998545616	28.2299995422363	0.0038322941404694
0.0473045364506248	818.441381177661	28.4300003051758	0.00390855190536653
0.0476398446604492	822.044745811773	28.6299991607666	0.00390421784085068
0.0479728108139957	825.535815744328	28.8299999237061	-7.72197703855189E-05
0.0483057769675425	828.998510134016	29.0300006866455	-0.000237056481880897
0.0486363964815307	832.569657275551	29.2299995422363	0.000439870130171264
0.0489717092746354	835.9583666908	29.4300003051758	0.00271517683717048
0.0493046754281823	839.528306362426	29.6299991607666	0.000338694573699508
0.0496399836380063	843.063888026634	29.8299999237061	0.134335159815437
0.0499729497915532	846.652488596856	30.0300006866455	0.159349090852371
0.0503035693055413	850.106017192232	30.2299995422363	0.0984125539631122
0.0506388775153657	853.585890585629	30.4300003051758	0.0778374749815134
0.0509695016126347	857.045401645556	30.6299991607666	0.0733075531448906
0.0513024677661811	860.651455644467	30.8299999237061	0.297219554827673
0.0516354293364472	864.169748534974	31.0300006866455	0.237588052029215
0.0519683954899941	867.684967865714	31.2299995422363	0.230908232528394
0.0523013616435406	871.166597578977	31.4300003051758	0.194847917433564
0.0526319811575291	874.646800282349	31.6299991607666	0.196480096911821
0.0529649473110756	878.327442990651	31.8299999237061	0.182805531548233
0.0533002601041803	882.022849762845	32.0299987792969	0.179820111036066
0.0536308796181689	885.422591062266	32.2299995422363	0.196122802705981
0.0539661878279929	889.082267702144	32.4300003051758	0.21601291960032
0.0542968073419815	892.620374076163	32.6300010681152	0.203716179986638
0.0546321201350862	896.201235861968	32.8300018310547	0.207926436349398
0.0549650862886327	899.714534217852	33.0299987792969	0.212308712391637
0.0552980524421795	903.298689103407	33.2299995422363	0.208311303570045
0.0556333606520035	906.876861524414	33.4300003051758	0.206757626518255
0.0559663268055504	910.38093920099	33.6300010681152	0.209338618369084
0.0562992929590969	914.110100245647	33.8300018310547	0.20974372535592
0.0566322591126433	917.619391996831	34.0299987792969	0.209277697406181
0.0569652206829095	921.005466932278	34.2299995422363	0.209008952177416
0.0573005334760142	924.705374274133	34.4300003051758	0.20857779382486
0.057633499629561	928.372789698431	34.6300010681152	0.208739528623153
0.0579664657831075	931.978953467333	34.8300018310547	0.208775919869425
0.0582994273533736	935.563382777869	35.0299987792969	0.209445262137126
0.0586323935069201	939.075363893852	35.2299995422363	0.209354971513504
0.0589653596604669	942.708750620707	35.4300003051758	0.208630281551851
0.0593006678702909	946.213706457218	35.6300010681152	0.208663629499946
0.0596336340238378	949.924041948289	35.8300018310547	0.209258245964219
0.0599642581211067	953.380259908463	36.0299987792969	0.209099609463469
0.0602995663309307	956.919354212408	36.2299995422363	0.208717950539091
0.0606301858449193	960.494892153612	36.4300003051758	0.208932521393684
0.060965498638024	964.084261113777	36.6300010681152	0.209240536168804
0.0612984602082902	967.753762167918	36.8300018310547	0.20899100405142
0.0616314263618366	971.321396669716	37.0299987792969	0.208864340514648
0.0619643925153835	974.843037544973	37.2299995422363	0.209005743881145
0.0622950120293721	978.350408321302	37.4300003051758	0.208964989351944
0.0626303248224764	981.887746305378	37.6300010681152	0.208933786379071
0.0629632909760232	985.482164685163	37.8300018310547	0.209093962862031
0.0632962571295697	988.907647047648	38.0299987792969	0.209142362302917
0.0636315653393941	992.563426852821	38.2299995422363	0.208857208930367
0.0639621848533823	996.10789988636	38.4300003051758	0.208733533692407
0.064297497646487	999.674217148258	38.6300010681152	0.209044848429406
0.0646304592167532	1003.23219189078	38.8300018310547	0.209175948581592
0.0649634253703	1006.84307576933	39.0299987792969	0.208938332993215
0.0652987381634047	1010.52026072289	39.2299995422363	0.208910686645921
0.0656293576773929	1013.93048505653	39.4300003051758	0.209036268528522
0.0659646658872173	1017.48637416921	39.6300010681152	0.208977107545287
0.0662976320407638	1021.15367982351	39.8300018310547	0.208992104038713
0.0666305981943106	1024.71176433603	40.0299987792969	0.209022757017941
0.0669635643478571	1028.23373452126	40.2299995422363	0.208903243398572
0.0672965305014035	1031.7409955276	40.4300003051758	0.208906946689125
0.0676294966549504	1035.18898073839	40.6300010681152	0.209027450297057
0.0679624582252165	1038.78954623772	40.8300018310547	0.209111837655541
0.0682930823224854	1042.26321762658	41.0299987792969	0.208967390990867
0.0686260484760319	1045.76718553316	41.2299995422363	0.208854110632825
0.068959010046298	1049.21692706382	41.4300003051758	0.208988235750067
0.0692919761998449	1052.93428783437	41.6300010681152	0.209050091702169
0.0696225957138331	1056.37865063543	41.8300018310547	0.208995917327995
0.0699555618673799	1060.06538557828	42.0299987792969	0.208991095717028
0.0702885280209264	1063.76156074041	42.2299995422363	0.208928506440065
0.0706214941744728	1067.20877756126	42.4300003051758	0.208947939548906
0.0709544603280197	1070.68475411995	42.6300010681152	0.2090229770154
0.0712874264815661	1074.43274071819	42.8300018310547	0.209029448607306
0.0716203880518323	1078.00191199988	43.0299987792969	0.208959287751143
0.0719533542053787	1081.74045837883	43.2299995422363	0.208896973471003
0.0722863203589256	1085.25891592432	43.4300003051758	0.208971112614542
0.072619286512472	1088.95640832636	43.6300010681152	0.209085731290457
0.0729522526660185	1092.5500583162	43.8300018310547	0.208997053981532
0.0732899075154008	1096.32449948245	44.0299987792969	0.20893046808407
0.0736205270293894	1099.97138791829	44.2299995422363	0.208944731252635
0.0739558398224941	1103.76306297325	44.4300003051758	0.20896729932526
0.0742888013927602	1107.32444058552	44.6300010681152	0.209035406871809
0.0746217675463071	1110.98219625054	44.8300018310547	0.209016542089736
0.0749570803394114	1114.71152195019	45.0299987792969	0.208936609679789
0.0752876998534	1118.22723524589	45.2299995422363	0.20893981797606
0.0756230080632244	1121.98586953333	45.4300003051758	0.20898779575515
0.0759559742167709	1125.52035349762	45.6300010681152	0.209043491778411
0.0762889403703173	1129.3143337224	45.8300018310547	0.208996613986614
0.0766219065238642	1132.94761067927	46.0299987792969	0.208924161490258
0.0769548726774106	1136.60778128411	46.2299995422363	0.20895794943327
0.0772878388309571	1140.21317666307	46.4300003051758	0.209008805512443
0.0776208049845039	1143.80441171309	46.6300010681152	0.209028165288798
0.0779514244984925	1147.39345136328	46.8300018310547	0.208988290749432
0.078284390652039	1151.17063677933	47.0299987792969	0.208949827860425
0.0786196942785827	1154.83366140396	47.2299995422363	0.208947957882027
0.0789526604321295	1158.59460086122	47.4300003051758	0.208985027453796
0.0792832799461177	1162.17365144216	47.6300010681152	0.209025396987444
0.0796185927392224	1165.8698266043	47.8300018310547	0.208981745825039
0.079949212253211	1169.52439893956	48.0299987792969	0.208936298016723
0.0802868716858736	1173.18511839436	48.2299995422363	0.208983817467774
0.0806174911998622	1176.8958929654	48.4300003051758	0.209006000544846
0.0809504573534091	1180.55189231056	48.6300010681152	0.20900829218504
0.0812834235069555	1184.14455437047	48.8300018310547	0.208976227555453
0.081616389660502	1187.83359448314	49.0299987792969	0.208933438049761
0.0819516932870461	1191.51978057603	49.2299995422363	0.208976832548465
0.0822846594405925	1195.17358452135	49.4300003051758	0.209007925522609
0.0826199722336972	1198.91652169997	49.6300010681152	0.20899976728352
0.0829529383872437	1202.43706487531	49.8300018310547	0.208978225865702
0.0832835579012323	1206.11359120892	50.0299987792969	0.208936224684237
0.083618870694337	1209.82140199018	50.2299995422363	0.208978060867608
0.0839518368478835	1213.5697178984	50.4300003051758	0.209006422206642
0.0842848030014299	1217.1758816673	50.6300010681152	0.208992232370564
0.0846177691549768	1220.75646902813	50.8300018310547	0.208968160981972
0.0849507261419626	1224.34770407815	51.0299987792969	0.20894183461943
0.0852836922955091	1227.99558044392	51.2299995422363	0.208980040844735
0.0856143209760583	1231.62238097127	51.4300003051758	0.209004588894487
0.0859496246026024	1235.2282154302	51.6300010681152	0.20898423912957
0.0862825907561488	1238.85358894765	51.8300018310547	0.208966327669818
0.0866155569096953	1242.57973131754	52.0299987792969	0.208949882859789
0.0869485230632421	1246.2423168622	52.2299995422363	0.208994744008216
0.0872814892167886	1249.90753688666	52.4300003051758	0.208999913948493
0.087614455370335	1253.55343739257	52.6300010681152	0.20898389080026
0.0879474215238819	1257.35762622659	52.8300018310547	0.208963284371641
0.0882803876774283	1260.96960780505	53.0299987792969	0.208941376291391
0.0886133538309748	1264.56709974461	53.2299995422363	0.208992507367387
0.0889463108179606	1268.35800640962	53.4300003051758	0.209003873902747
0.0892792769715071	1272.14364411503	53.6300010681152	0.208987814088271
0.0896122431250539	1275.69514242804	53.8300018310547	0.208978537528768
0.0899475559181587	1279.3511417732	54.0299987792969	0.208940807964624
0.0902781754321468	1283.07025886361	54.2299995422363	0.208997457310206
0.0906134882252516	1286.76720241569	54.4300003051758	0.209008072187581
0.0909464543787984	1290.52726371302	54.6300010681152	0.20895853609316
0.0912770738927866	1294.23463541432	54.8300018310547	0.208967005995315
0.0916123866858913	1297.81632047506	55.0299987792969	0.208960662735259
0.0919453528394382	1301.49943300818	55.2299995422363	0.208991755709404
0.0922783098264236	1305.2037311497	55.4300003051758	0.208996705652222
0.0926112759799705	1308.99760160449	55.6300010681152	0.20895640945106
0.0929442421335169	1312.58389700489	55.8300018310547	0.208959507748602
0.0932772082870634	1316.30542903512	56.0299987792969	0.208966492667911
0.0936101744406102	1319.97986973889	56.2299995422363	0.208986182440454
0.0939431405941567	1323.68866845007	56.4300003051758	0.20899963895167
0.0942761067477032	1327.29033164931	56.6300010681152	0.208963211039155
0.0946067262616917	1330.88299370923	56.8300018310547	0.208952889491723
0.0949420390547965	1334.68388944349	57.0299987792969	0.208975824226779
0.0952750052083429	1338.20289583895	57.2299995422363	0.208993772352774
0.0956079713618898	1342.02596511154	57.4300003051758	0.208983194141641
0.0959409375154362	1345.61741970155	57.6300010681152	0.208962587713022
0.0962739036689827	1349.29515350507	57.8300018310547	0.208960332739072
0.0966068606559685	1352.89330406458	58.0299987792969	0.208970984282691
0.0969398268095154	1356.55182811954	58.2299995422363	0.208997603975178
0.0972727929630618	1360.3714945224	58.4300003051758	0.208978610861254
0.0976081057561665	1363.97041347184	58.6300010681152	0.208954264475839
0.0979434185492713	1367.6583558846	58.8300018310547	0.208961469392608
0.0982740380632595	1371.43191889091	59.0299987792969	0.208977749204542
0.0986070042168063	1375.14620610169	59.2299995422363	0.208995000671918
0.09894230784335	1378.68376362575	59.4300003051758	0.208979417518603
0.0992729365238992	1382.38915946719	59.6300010681152	0.208965099350674
0.0996082401504433	1386.12594952627	59.8300018310547	0.208968729308741
0.0999412063039898	1389.880741864	60.0299987792969	0.208980627504625
0.100274172457536	1393.46341485467	60.2299995422363	0.208997732307029
0.100604791971525	1397.17111586594	60.4300003051758	0.208964531023906
0.100937758125071	1400.71624751943	60.6300010681152	0.20894751788711
0.101273070918176	1404.34041356698	60.8300018310547	0.208962129384983
0.101603690432165	1408.01331749086	61.0299987792969	0.208997090647774
0.101936656585711	1411.77348855819	61.2299995422363	0.20898649410352
0.102269622739258	1415.37833508719	61.4300003051758	0.208979674182304
0.102602588892804	1419.17022968213	61.6300010681152	0.208970214291586
0.102935555046351	1422.84554854583	61.8300018310547	0.20890155675139
0.103268521199898	1426.33864922323	62.0299987792969	0.208964549357028
0.103601487353444	1430.0304335857	62.2299995422363	0.209036158529792
0.10393444434043	1433.79192189292	62.4300003051758	0.208939176316806
0.104267410493976	1437.44550629826	62.6300010681152	0.208978959190564
0.104600376647523	1441.06473269618	62.8300018310547	0.208987960753244
0.10493334280107	1444.68505679402	63.0299987792969	0.208969022638685
0.105266308954616	1448.40088078468	63.2299995422363	0.208995605664929
0.105601621747721	1452.07082091879	63.4300003051758	0.208954649471392
0.105934587901267	1455.81661211719	63.6300010681152	0.208954557805784
0.106267554054814	1459.39917533787	63.8300018310547	0.208982075821227
0.106602857681358	1463.0980947498	64.0299987792969	0.208988382415039
0.106935823834905	1466.69163496965	64.2300033569336	0.20898436746142
0.107268789988451	1470.34016995536	64.4300003051758	0.208968692642497
0.107601756141998	1474.01845260885	64.629997253418	0.208971259279514
0.107934722295544	1477.62110373801	64.8300018310547	0.208982644147995
0.108267688449091	1481.10663028598	65.0299987792969	0.208981562493824
0.108600654602637	1484.87174100294	65.2300033569336	0.208971955938133
0.108935967395742	1488.4943702706	65.4300003051758	0.208971515943216
0.109268933549289	1492.05783351271	65.629997253418	0.208974614240757
0.109601890536274	1495.80900344071	65.8300018310547	0.208978262531945
0.109934856689821	1499.30912939759	66.0299987792969	0.20900011561283
0.110267822843368	1502.93428337506	66.2300033569336	0.20898720909526
0.110598442357356	1506.48698915798	66.4300003051758	0.2089504878528
0.110933755150461	1510.17251663092	66.629997253418	0.208988474080647
0.111264374664449	1513.86978949297	66.8300018310547	0.20898282747921
0.111599687457554	1517.44587628414	67.0299987792969	0.208976869214707
0.111930306971543	1520.93359823194	67.2300033569336	0.208974870904459
0.112265619764647	1524.51188042294	67.4300003051758	0.208964714355121
0.112598585918194	1528.02539831881	67.629997253418	0.208982149153713
0.11293155207174	1531.7447349492	67.8300018310547	0.208989354070481
0.113266855698284	1535.38174408578	68.0299987792969	0.208983744135288
0.113597475212273	1538.98077280522	68.2300033569336	0.208980425840288
0.113930441365819	1542.49791311082	68.4300003051758	0.20895983774479
0.114265754158924	1546.14941188631	68.629997253418	0.20897358758595
0.11459872031247	1549.71485098828	68.8300018310547	0.208999308955481
0.114934033105575	1553.36931355355	69.0299987792969	0.208969755963547
0.115264652619564	1556.80741946508	69.2300033569336	0.208968032650122
0.11559761877311	1560.44574584157	69.4300003051758	0.208981012500177
0.115932931566215	1563.98132750578	69.629997253418	0.208977052545923
0.116265888553201	1567.61822687237	69.8300018310547	0.208996008993603
0.116598854706747	1571.16906656543	70.0299987792969	0.208976227555453
0.116931820860294	1574.75426426591	70.2300033569336	0.208956372784817
0.117264787013841	1578.35087804553	70.4300003051758	0.208982644147995
0.117597753167387	1581.93179471633	70.629997253418	0.208982735813603
0.117930719320933	1585.41446724451	70.8300018310547	0.208988382415039
0.118261338834922	1588.9756253168	71.0299987792969	0.208972230934956
0.118596651628027	1592.51460985075	71.2300033569336	0.208963027707939
0.118929617781573	1596.06984034348	71.4300003051758	0.20897287259421
0.11926258393512	1599.56392895081	71.629997253418	0.208972029270619
0.119595550088667	1603.16251859028	71.8300018310547	0.208995184003133
0.119928516242213	1606.72521344245	72.0299987792969	0.208960956065204
0.120261473229199	1610.35706338942	72.2300033569336	0.208970690952746
0.120594439382746	1613.95203061917	72.4300003051758	0.208990344059045
0.120927405536292	1617.36862161232	72.629997253418	0.208974925903824
0.121262718329397	1620.81693613309	72.8300018310547	0.208987465758962
0.121593337843385	1624.36162870661	73.0299987792969	0.208979197521144
0.12192865063649	1627.9174080493	73.2300033569336	0.208960479404044
0.122261616790037	1631.42609606553	73.4300003051758	0.208975182567525
0.122594582943583	1635.01963628538	73.629997253418	0.20897488923758
0.122929886570127	1638.55719380944	73.8300018310547	0.20897914252178
0.123260515250676	1642.0029836204	74.0299987792969	0.208970049293492
0.12359581887722	1645.67588754429	74.2300033569336	0.20897820753258
0.123928785030767	1649.02178666275	74.4300003051758	0.208969480966724
0.124261751184313	1652.66077165919	74.629997253418	0.208980260842194
0.12459471733786	1655.99799894831	74.8300018310547	0.208970177625343
0.124927683491406	1659.07463227702	75.0299987792969	0.20896387103153
0.125260649644953	1662.60801854139	75.2300033569336	0.208970085959735
0.1255936157985	1666.04019687337	75.4300003051758	0.208979069189293
0.125926581952046	1669.6060750553	75.629997253418	0.208981855823769
0.126259548105593	1673.0221171985	75.8300018310547	0.208966327669818
0.126592514259139	1676.64123382643	76.0299987792969	0.20896706099468
0.126925471246125	1680.02741853187	76.2300033569336	0.208980242509072
0.127258437399672	1683.577270295	76.4300003051758	0.208968069316365
0.127591403553219	1687.00933885699	76.629997253418	0.208995165670012
0.127922023067207	1690.51923434313	76.8300018310547	0.208970085959735
0.128257335860311	1694.0486688878	77.0299987792969	0.208954539472663
0.128590302013858	1697.50609431789	77.2300033569336	0.208978299198188
0.128925614806963	1701.09162132834	77.4300003051758	0.208967555988961
0.129256234320951	1704.47363477409	77.629997253418	0.208980645837746
0.129589200474498	1707.82359538226	77.8300018310547	0.208973184257276
0.129924513267602	1711.24918751473	78.0299987792969	0.208956226119845
0.130257470254588	1714.69387962577	78.2300033569336	0.208983579137194
0.130590436408135	1718.01562934606	78.4300003051758	0.208975347565619
0.130925749201239	1721.44319733839	78.629997253418	0.208964531023906
0.131256368715228	1724.90314747828	78.8300018310547	0.208973532586586
0.131591681508333	1728.40985963466	79.0299987792969	0.208969114304293
0.131924647661879	1731.76486966244	79.2300033569336	0.208996833984073
0.132257613815426	1735.31483119557	79.4300003051758	0.208975842559901
0.132590579968972	1738.61100450777	79.629997253418	0.208983542470951
0.132921199482961	1742.09356726597	79.8300018310547	0.208958609425646
0.133256503109505	1745.44605258394	80.0299987792969	0.208970159292221
0.133587131790054	1748.86429012697	80.2300033569336	0.20897927085363
0.133920097943601	1752.29646845895	80.4300003051758	0.2089734592541
0.134253054930587	1755.80065590552	80.629997253418	0.208985009120674
0.134586021084133	1759.1423837643	80.8300018310547	0.208973294256005
0.13491898723768	1762.71034757608	81.0299987792969	0.208970965949569
0.135254300030784	1766.09049493197	81.2300033569336	0.208979784181033
0.135584919544773	1769.44638311969	81.4300003051758	0.208973825916531
0.135917885698319	1773.02126244094	81.629997253418	0.208963284371641
0.136250851851866	1776.51820506805	81.8300018310547	0.208968160981972
0.136583818005413	1779.92469722197	82.0299987792969	0.20897026929095
0.136916784158959	1783.39298988123	82.2300033569336	0.208984550792636
0.137249750312506	1786.83856015221	82.4300003051758	0.208979949179128
0.137582716466052	1790.36470159713	82.629997253418	0.208965796009293
0.137918020092596	1793.72037024486	82.8300018310547	0.209003983901476
0.138248639606585	1797.24508467988	83.0299987792969	0.208974339243934
0.138583952399689	1800.70174172003	83.2300033569336	0.208951881170038
0.138916918553236	1804.04270118887	83.4300003051758	0.208991150716393
0.139249884706783	1807.51637257773	83.629997253418	0.208953476151613
0.139585197499887	1811.01748646453	83.8300018310547	0.208974302577691
0.139918163653434	1814.56898477754	84.0299987792969	0.208989757399156
0.14025112980698	1818.02553204769	84.2300033569336	0.208961176062663
0.140584095960527	1821.43290236154	84.4300003051758	0.20897927085363
0.140917052947513	1824.75146875206	84.629997253418	0.208959269418022
0.141252365740617	1828.09670925058	84.8300018310547	0.208964494357663
0.141582985254606	1831.48530889583	85.0299987792969	0.20898436746142
0.141918298047711	1834.83878214373	85.2300033569336	0.208967445990232
0.142251264201257	1838.22024673953	85.4300003051758	0.208974577574514
0.142581883715246	1841.67811124958	85.629997253418	0.208968765974983
0.14291719650835	1845.0579292955	85.8300018310547	0.208966859330343
0.143247816022339	1848.43379562171	86.0299987792969	0.208978867524956
0.143583128815443	1851.88430554231	86.2300033569336	0.208969352634873
0.143916085802429	1855.23448569046	86.4300003051758	0.208967262659017
0.144246714482979	1858.60135087735	86.629997253418	0.208962734377994
0.144579680636525	1862.09445155475	86.8300018310547	0.208970764285232
0.144914984263069	1865.36340190901	87.0299987792969	0.208988217416945
0.145250297056174	1868.53575467052	87.2300033569336	0.208964384358933
0.145580916570162	1871.76057748809	87.4300003051758	0.208962991041696
0.145913882723709	1875.17200929163	87.629997253418	0.208969370967995
0.146249195516813	1878.76763514133	87.8300018310547	0.208962386048685
0.146579815030802	1882.10486243045	88.0299987792969	0.208964512690784
0.146915127823907	1885.48358277645	88.2300033569336	0.20896849097816
0.147245747337895	1888.86801116202	88.4300003051758	0.208967867652028
0.147581050964439	1892.37757733818	88.629997253418	0.209037936842582
0.147914017117985	1895.83138035854	88.8300018310547	0.208990362392167
0.148246983271532	1899.18617084634	89.0299987792969	0.208943887929043
0.148579949425079	1902.50276137701	89.2300033569336	0.20901232547178
0.148912915578625	1906.04416085078	89.4300003051758	0.208951331176392
0.14924822837173	1909.42880877633	89.629997253418	0.208958682758132
0.149578847885719	1912.67075571262	89.8300018310547	0.208990399058409
0.149914160678823	1916.08789555573	90.0299987792969	0.208940881297109
0.150244780192812	1919.46793314163	90.2300033569336	0.208966657666006
0.150577746346358	1922.87607184542	90.4300003051758	0.208976942547194
0.150910712499905	1926.17685549728	90.629997253418	0.208957967766392
0.151243669486891	1929.51891266604	90.8300018310547	0.208985449115592
0.151576635640437	1932.8954376122	91.0299987792969	0.20898081083584
0.151911948433542	1936.08052369276	91.2300033569336	0.208953714482193
0.15224256794753	1939.30732237018	91.4300003051758	0.208958939421834
0.152575534101077	1942.78747018856	91.629997253418	0.208968032650122
0.152906153615065	1945.97299534908	91.8300018310547	0.208963596034707
0.153243813047728	1949.31175941808	92.0299987792969	0.208966511001033
0.153574432561717	1952.74668199986	92.2300033569336	0.208966529334155
0.153909745354821	1956.13396440522	92.4300003051758	0.208963926030895
0.154242711508368	1959.24089425165	92.629997253418	0.208971405944486
0.154575677661915	1962.64398353582	92.8300018310547	0.208977309209625
0.154908643815461	1965.96298900631	93.0299987792969	0.208959434416116
0.155243956608566	1969.31821857407	93.2300033569336	0.208970562620895
0.155576922762112	1972.51647705364	93.4300003051758	0.208959232751779
0.155909870582537	1975.76764466923	93.629997253418	0.208959929410398
0.156240508429647	1979.0111283854	93.8300018310547	0.208970984282691
0.156573456250072	1982.34396487485	94.0299987792969	0.208964347692691
0.156908769043177	1985.66253126537	94.2300033569336	0.208969572632331
0.157244081836282	1988.96002181748	94.4300003051758	0.20896647433479
0.15757470135027	1992.158938917	94.629997253418	0.20896671266537
0.157910014143375	1995.36378359607	94.8300018310547	0.208976575884763
0.158242980296922	1998.66061552822	95.0299987792969	0.208963467702856
0.15857359981091	2001.9385670218	95.2300033569336	0.208959214418657
0.158908912604015	2005.12672666213	95.4300003051758	0.20897653921852
0.159239532118003	2008.32827824145	95.629997253418	0.208968820974348
0.159574844911108	2011.6516745116	95.8300018310547	0.208963981030259
0.159905464425096	2014.9373099046	96.0299987792969	0.208973312589127
0.160238430578643	2018.27124409397	96.2300033569336	0.208962037719376
0.160571396732189	2021.40407965846	96.4300003051758	0.208970580954017
0.160904362885736	2024.71430352961	96.629997253418	0.208969114304293
0.161239675678841	2028.00169524247	96.8300018310547	0.208961982720011
0.161572641832387	2031.120699788	97.0299987792969	0.208967042661558
0.161905607985934	2034.38855244233	97.2300033569336	0.208961194395784
0.162240920779039	2037.57539484276	97.4300003051758	0.208968454311917
0.162571540293027	2040.58792249629	97.629997253418	0.208969517632967
0.16290683475301	2043.81296485384	97.8300018310547	0.208960956065204
0.163239800906557	2046.74777535321	98.0299987792969	0.208979490851089
0.163572767060104	2049.89575917656	98.2300033569336	0.20895545612874
0.16390573321365	2052.7950041986	98.4300003051758	0.208990105728465
0.164238699367196	2055.91796046383	98.629997253418	0.209003067245399
0.164574012160301	2059.08921552543	98.8300018310547	0.20893910298432
0.164906978313848	2062.01019500584	99.0299987792969	0.20896185438816
0.165239944467394	2065.17683972778	99.2300033569336	0.208963211039155
0.165572910620941	2068.15819270366	99.4300003051758	0.208955731125563
0.165905876774487	2071.30551790705	99.629997253418	0.208975585896199
0.166236496288476	2074.17402733141	99.8300018310547	0.2089504878528
0.166569462442022	2077.06031949443	100.029998779297	0.208962422714928
0.166902428595569	2080.1986435585	100.230003356934	0.20897369758468
0.167235394749116	2083.2155620117	100.430000305176	0.208944896250729
0.167568360902662	2086.09900015494	100.629997253418	0.208943704597828
0.167898980416651	2089.21932194036	100.830001831055	0.208963779365922
0.168234293209756	2092.25731623198	101.029998779297	0.208957839434541
0.168567259363302	2095.38971271649	101.230003356934	0.208965319348133
0.168900225516849	2098.48039660415	101.430000305176	0.208969700964182
0.169235538309953	2101.5644942923	101.629997253418	0.208961322727635
0.169566157823942	2104.6040253638	101.830001831055	0.208962642712387
0.169899123977489	2107.66507135368	102.029998779297	0.208960607735895
0.170232090131035	2110.70613920506	102.230003356934	0.208958719424376
0.17056503795146	2113.83502304985	102.430000305176	0.208961322727635
0.170900350744565	2116.98190917327	102.629997253418	0.208948416210066
0.171230970258553	2120.16150675424	102.830001831055	0.20897619088921
0.171566283051658	2123.38040199226	103.029998779297	0.208958004432635
0.171899249205204	2126.61005468947	103.230003356934	0.208960167740978
0.172232215358751	2129.8686866645	103.430000305176	0.208976887547829
0.172567528151856	2133.04301528586	103.629997253418	0.20895343948537
0.172900494305402	2136.19802438868	103.830001831055	0.208954172810232
0.173233460458949	2139.32229789381	104.029998779297	0.208974632573879
0.173566426612495	2142.46896447725	104.230003356934	0.208970910950204
0.173899392766042	2145.66590571692	104.430000305176	0.208970305957193
0.174232358919589	2148.84308835807	104.629997253418	0.208953787814679
0.174567671712693	2151.86637347079	104.830001831055	0.208957362773381
0.17490063786624	2155.11973648622	105.029998779297	0.208949332866143
0.175231257380228	2158.24400999135	105.230003356934	0.208962697711751
0.175564223533775	2161.46268568938	105.430000305176	0.208966162671724
0.175897189687322	2164.53668453829	105.629997253418	0.208957087776557
0.176232502480426	2167.59136386865	105.830001831055	0.208961561058215
0.176565450300851	2170.69895233503	106.029998779297	0.208963504369099
0.176898416454398	2173.79819828204	106.230003356934	0.208962404381806
0.177231382607945	2176.85704887209	106.430000305176	0.208960974398326
0.177562002121933	2179.89657994359	106.629997253418	0.208965576011834
0.17789496827548	2182.76201580817	106.830001831055	0.20895912275305
0.178230281068584	2185.64896659114	107.029998779297	0.208961799388795
0.178563247222131	2188.337892309	107.230003356934	0.208963266038519
0.178898560015235	2190.81101022308	107.430000305176	0.208948526208795
0.179229179529224	2193.69686330613	107.629997253418	0.208962037719376
0.179564492322328	2196.56032331087	107.830001831055	0.208980957500813
0.179897458475875	2199.418514356	108.029998779297	0.208979435851724
0.18023277126898	2202.2771444811	108.230003356934	0.208981984155619
0.180565737422526	2204.98517017752	108.430000305176	0.208992360702415
0.180898703576073	2207.82623710394	108.629997253418	0.20897547589747
0.18123166972962	2210.66862127026	108.830001831055	0.20895771110269
0.181564635883166	2213.67631904415	109.029998779297	0.208974779238851
0.181897602036713	2216.40607919894	109.230003356934	0.208964054362746
0.182230568190259	2219.23660820615	109.430000305176	0.20895959941421
0.182563534343806	2221.98942005921	109.629997253418	0.208974870904459
0.182896482164231	2224.79558012825	109.830001831055	0.208975805893658
0.183231794957335	2227.39076227315	110.029998779297	0.208977327542746
0.183562414471324	2230.16003962497	110.230003356934	0.208971149280785
0.18389538062487	2232.80637458603	110.430000305176	0.208967152660287
0.184228346778417	2235.64041623298	110.629997253418	0.20896671266537
0.184563659571522	2238.3750062674	110.830001831055	0.208949259533657
0.18489427908551	2240.75525876846	111.029998779297	0.208963522702221
0.185227245239057	2243.56339469736	111.230003356934	0.208970984282691
0.185560211392604	2245.98316439545	111.430000305176	0.208964897686337
0.185895524185708	2248.34080427821	111.629997253418	0.208986604102249
0.186226143699697	2249.18361827485	111.830001831055	0.208977052545923
0.186561456492801	2250.89646922608	112.029998779297	0.208966181004845
0.186894422646348	2252.85015553921	112.230003356934	0.208967867652028
0.187227388799894	2255.07387603204	112.430000305176	0.208965777676171
0.187562701592999	2257.51735604835	112.629997253418	0.208908615003186
0.187895667746546	2260.08575431527	112.830001831055	0.20899952895294
0.188228633900093	2262.38675288229	113.029998779297	0.208990582389625
0.188561600053639	2264.94571092991	113.230003356934	0.208926764793518
0.188892219567628	2267.3310128506	113.430000305176	0.208999785616642
0.189229860667168	2269.56110000295	113.629997253418	0.208958151097607
0.189560480181157	2271.76198833749	113.830001831055	0.208965337681254
0.189893446334704	2274.37649000094	114.029998779297	0.209002077256835
0.190228759127808	2276.85860905435	114.230003356934	0.208970104292856
0.190559378641797	2279.55390143172	114.430000305176	0.208984752456973
0.190894691434902	2282.36664770027	114.629997253418	0.208967959317635
0.19122531094889	2285.21078818646	114.830001831055	0.208959397749873
0.191560623741995	2287.9824804781	115.029998779297	0.208978537528768
0.191891243255983	2290.98249435257	115.230003356934	0.20895936108363
0.192226556049088	2293.78294638204	115.430000305176	0.208983817467774
0.192557175563076	2296.64179604712	115.629997253418	0.208994212347691
0.192890141716623	2299.59943870478	115.830001831055	0.20897690588095
0.19322310787017	2302.53732276392	116.029998779297	0.208981819157525
0.193558420663274	2305.64842387004	116.230003356934	0.208975292566254
0.193889040177263	2308.45085175936	116.430000305176	0.208969994294127
0.194224352970367	2311.29455316558	116.629997253418	0.208970929283326
0.194557319123914	2314.1130074737	116.830001831055	0.20896931596863
0.194890285277461	2317.10116618906	117.029998779297	0.208979820847277
0.195220904791449	2320.11479154251	117.230003356934	0.208979124188658
0.195558564224112	2323.18615591162	117.430000305176	0.208976575884763
0.195891530377658	2326.17277784709	117.629997253418	0.208986292439183
0.196224478198083	2329.19979513953	117.830001831055	0.208975255900011
0.19655744435163	2332.0867459225	118.029998779297	0.208974962570067
0.196888063865619	2334.99147944414	118.230003356934	0.208964971018823
0.197223376658723	2337.98644389899	118.430000305176	0.208969114304293
0.19755634281227	2340.89161650059	118.629997253418	0.208982809146089
0.197891655605374	2343.8883372753	118.830001831055	0.208973294256005
0.198224621758921	2346.76277427921	119.029998779297	0.208981085832663
0.198557587912468	2349.62052624438	119.230003356934	0.209023912004598
0.198890554066014	2352.54918962421	119.430000305176	0.208965007685066
0.199223520219561	2355.23043144265	119.629997253418	0.208950909514596
0.199556486373107	2357.85129976562	119.830001831055	0.208976300887939
0.199889452526654	2360.31541654038	120.029998779297	0.208951972835646
0.2002224186802	2362.42519578177	120.230003356934	0.20896410936211
0.200555384833747	2361.54242550814	120.430000305176	0.208978959190564
0.200888350987294	2362.22080405714	120.629997253418	0.208967207659652
0.201223663780398	2363.73409316337	120.830001831055	0.208976484219155
0.201626974121323	-10.4952512689753	121	0.209458865313314