File: CouponData/5-90T-1.txt
File Path: C:\Users\MTS\Desktop\SE171\Test Run 22 2-3-2017 3 07 22 PM\DAQ- Crosshead, … - (Timed).txt
Test: MTS EM Tension (Extensometer-Crosshead) 171-2017-W
Test Run: Test Run 22
Date: 2/3/2017 2:12:21 PM


Crosshead 	Load 	Time 	Extensometer
in	lbf	sec	in
0.000445517089676689	6.70762269609775	0.239999994635582	-8.46759082099118E-05
0.000844137624752209	15.5865584321675	0.439999997615814	-2.43678046419919E-05
0.00124275819563461	24.553458093851	0.639999985694885	3.7363597710096E-05
0.00164372361573119	33.2675488887585	0.839999973773956	9.43526990920685E-05
0.00203999933739941	41.9923697003592	1.03999996185303	0.000155155445586782
0.00244096461426848	50.4901107021563	1.24000000953674	0.000219514352172305
0.00284193003436507	59.0000190214757	1.44000005722046	0.000275859643649502
0.00324055053363371	67.4088531905814	1.63999998569489	0.000332032775657167
0.00363682639852943	75.7169116466379	1.8400000333786	0.000393094710238446
0.00403779181862602	84.0400017309393	2.03999996185303	0.000450853066446488
0.0044387572387226	92.2868016709759	2.24000000953674	0.000510593297546197
0.00483737745153622	100.578031015172	2.44000005722046	0.00056835451830448
0.00523599852371492	108.734359900135	2.64000010490417	0.000623318469944764
0.00563461902298354	116.950376218111	2.83999991416931	0.000685688895269618
0.00603792879099803	125.03991692372	3.03999996185303	0.000741967353208988
0.00643654986317673	132.917464332766	3.24000000953674	0.000794922932867862
0.00683517036244535	140.740140467187	3.44000005722046	0.000852386312014752
0.00723379086171402	148.760388865504	3.64000010490417	0.000910633933404095
0.00763710120263854	156.649475844932	3.83999991416931	0.000966718318064579
0.00803337678107925	164.343748531506	4.03999996185303	0.00102497023627928
0.00843199728034788	172.208082377795	4.23999977111816	0.001079176693415
0.00883061777961654	179.938537997899	4.44000005722046	0.00113692538176597
0.00923392812054106	187.802336715478	4.6399998664856	0.00119778454199701
0.0096348929677276	195.557655238712	4.84000015258789	0.00125252917650941
0.0100311691190783	203.129191353263	5.03999996185303	0.0013037216971082
0.0104321339662649	210.862446108156	5.23999977111816	0.00136502106709765
0.0108330999592715	218.54460293189	5.44000005722046	0.00141860863815363
0.011234064806458	226.027897694324	5.6399998664856	0.00147454456749783
0.0116303409578088	233.533681583818	5.84000015258789	0.00153212460545332
0.0120313058049954	241.051910646126	6.03999996185303	0.00158734869406243
0.0124299274500841	248.57046901841	6.23999977111816	0.00164708187120717
0.0128308922972706	256.056974553101	6.44000005722046	0.00169903779444541
0.0132295127965393	263.401684700953	6.6399998664856	0.00175737765435254
0.0136304787895459	270.83986399678	6.84000015258789	0.00181450566627987
0.0140314436367324	278.067833758407	7.03999996185303	0.00187192543264933
0.0144300641360011	285.390507580418	7.23999977111816	0.00192854441399869
0.0148286846352697	292.500447158419	7.44000005722046	0.001977687492127
0.0152273051345383	299.701742812051	7.6399998664856	0.00204233638071419
0.015628271127545	306.866073420965	7.84000015258789	0.00209527140722508
0.0160268916268136	314.069344934451	8.03999996185303	0.00215215750788448
0.0164278564740002	321.037187258133	8.23999977111816	0.00220751809231262
0.0168264769732688	328.249789220918	8.4399995803833	0.00226492239011078
0.0172297873141933	335.267851315826	8.64000034332275	0.00231910421211441
0.017628407813462	342.155149908065	8.84000015258789	0.00237683406604755
0.0180270283127306	349.03385899845	9.03999996185303	0.00243097678694038
0.0184256488119993	355.933479272262	9.23999977111816	0.002489671994305
0.0188266148050059	362.832742793601	9.4399995803833	0.00254765220992927
0.0192252341584544	369.666336417378	9.64000034332275	0.00260002506845521
0.0196215114556253	376.371691248293	9.84000015258789	0.00265120111789012
0.0200224751569917	383.005448602094	10.039999961853	0.00270806387246506
0.0204234411499984	389.875238880648	10.2399997711182	0.00275773832466321
0.020824407143005	396.454330778556	10.4399995803833	0.00281994518416926
0.0212230264964535	402.985425747573	10.6400003433228	0.00287600672404157
0.0216216481415423	409.52343622607	10.8400001525879	0.00292527727465563
0.0220226141345489	415.957247539901	11.039999961853	0.00298245169229688
0.0224235778359154	422.295174765939	11.2399997711182	0.00303481538426204
0.0228198551330862	428.668530256814	11.4399995803833	0.00308902212785278
0.0232208188344526	434.960985263771	11.6400003433228	0.00314358808604384
0.0236217848274593	441.342106981563	11.8400001525879	0.00319470168828348
0.024020406472548	447.609836297879	12.039999961853	0.00324655233930034
0.0244213701739145	453.805693712098	12.2399997711182	0.00330206703653148
0.0248199918190032	460.105091671032	12.4399995803833	0.00335323535168074
0.0252209578120098	466.127567383286	12.6400003433228	0.0034085097131466
0.0256195771654584	472.283742945487	12.8400001525879	0.00345542932737721
0.0260181988105471	478.16296881851	13.039999961853	0.00351104485677687
0.0264168181639957	484.257124335374	13.2399997711182	0.00356379096619932
0.0268177841570023	490.191399859257	13.4399995803833	0.00361670150080564
0.027216405802091	495.992469498156	13.6400003433228	0.00366758307447569
0.0276173695034575	501.915109402914	13.8400001525879	0.00371833230592457
0.0280159911485462	507.562391283371	14.039999961853	0.00376764238733197
0.0284193014894707	513.493648132483	14.2399997711182	0.00381538584621213
0.0288179208429193	519.033520076016	14.4399995803833	0.00386634934601909
0.0292141981400902	524.713074334048	14.6400003433228	0.00391611976065035
0.0296151618414566	530.236645433807	14.8400001525879	0.00396442037455252
0.0300161278344632	535.705715732663	15.039999961853	0.00401366285257421
0.030414749479552	541.113150181152	15.2399997711182	0.00406320209800098
0.0308133688330005	546.580134850164	15.4399995803833	0.00410537114211059
0.0312143348260071	551.893002450763	15.6400003433228	0.00415728137577244
0.0316153008190138	557.261742977161	15.8400001525879	0.00420314139286862
0.0320162645203802	562.477079940093	16.0400009155273	0.00425348271236307
0.0324125418175511	567.687532138391	16.2399997711182	0.00429749022481787
0.0328135055189175	572.696227091856	16.4400005340576	0.00434487017227232
0.0332144715119241	577.795482288513	16.6399993896484	0.00439480014235205
0.0336130931570129	582.878491526392	16.8400001525879	0.00443719204847047
0.0340140568583793	587.801511001297	17.0400009155273	0.00448089735087476
0.034412678503468	592.888417073883	17.2399997711182	0.00452881755250484
0.0348136444964747	597.824663832795	17.4400005340576	0.00457165174518059
0.0352122638499232	602.796750494011	17.6399993896484	0.0046159044631361
0.0356132298429298	607.605828717484	17.8400001525879	0.0046643462993652
0.0360118491963784	612.418254925704	18.0400009155273	0.00470805704441492
0.036412815189385	617.434798433578	18.2399997711182	0.00475159448417504
0.0368114368344738	622.223843633555	18.4400005340576	0.0047940024317748
0.0372100561879223	626.945435173605	18.6399993896484	0.00483697526868228
0.0376086778330111	631.725204809279	18.8400001525879	0.00488589262025154
0.0380119881739356	636.566500525328	19.0400009155273	0.00492991216381732
0.0384106075273841	641.290891200166	19.2399997711182	0.00497329635013953
0.0388092291724729	646.096292128915	19.4400005340576	0.00501740068439248
0.0392101928738393	650.62293216362	19.6399993896484	0.00506220339599441
0.039608814518928	655.458080760132	19.8400001525879	0.0051064595514102
0.0400121248598528	660.167762256076	20.0400009155273	0.00514832151573386
0.0404083998653831	664.847860739242	20.2399997711182	0.00518941578059276
0.040807021510472	669.225652665138	20.4400005340576	0.00522866298345571
0.0412079852118386	674.06623487624	20.6399993896484	0.00527745945100476
0.0416089534964854	678.699681112916	20.8400001525879	0.0053214285784863
0.0420075705582937	683.2718208092	21.0400009155273	0.00536590243972047
0.0424061922033823	687.914542610177	21.2399997711182	0.0054075117507128
0.0428095025443067	692.652544763992	21.4400005340576	0.00544963267037835
0.0432081241893957	697.159151775202	21.6399993896484	0.00549085354835791
0.0436067458344843	701.638645598451	21.8400001525879	0.00553191630316413
0.0440053628962925	706.228897343373	22.0400009155273	0.00557574506768386
0.0444086732372173	710.828753962572	22.2399997711182	0.00562110693949295
0.0448049528260284	715.263242089204	22.4400005340576	0.00566341290910413
0.0452059165273949	719.865074568257	22.6399993896484	0.00570957914662114
0.0456045381724835	724.403569762068	22.8400001525879	0.00575349728510839
0.04600550187385	728.962811484323	23.0400009155273	0.00579285391379059
0.0464064655752161	733.500208978217	23.2399997711182	0.00583926306516811
0.0468050872203051	737.996003645242	23.4400005340576	0.00587996316791374
0.0472013622258358	742.39487140955	23.6399993896484	0.00592277673582776
0.0476046725667602	746.916022944668	23.8400001525879	0.00596689138246158
0.0480056408514071	751.330093852835	24.0400009155273	0.00600541843739374
0.0484019158569378	755.83450546421	24.2399997711182	0.00604752274266787
0.0488028795583043	760.244953962649	24.4400005340576	0.00608870695440437
0.0492015012033929	764.498705797867	24.6399993896484	0.00613015355894299
0.0496048115443173	768.937914034144	24.8400001525879	0.00617347014187945
0.0500034331894063	773.006648548272	25.0400009155273	0.00621645844735823
0.0504020502512146	777.238775695118	25.2399997711182	0.00625385228621472
0.0508030185358614	781.349167921113	25.4400005340576	0.00629417025795807
0.051203982237228	785.449406422872	25.6399993896484	0.00633306454823126
0.0516026038823165	789.498327453491	25.8400001525879	0.00637204878538201
0.0519988788878472	793.523593050887	26.0400009155273	0.00641274258611709
0.0523998425892138	797.501438011847	26.2399997711182	0.00645443897943681
0.0527984642343024	801.699316921265	26.4400005340576	0.00648966779122055
0.0531994325189492	805.821180111399	26.6399993896484	0.00652976920296563
0.0535980495807575	809.885798250838	26.8400001525879	0.00657060737703287
0.0540013599216819	814.065729766606	27.0400009155273	0.00661381682579032
0.0543999815667709	818.148075759711	27.2399997711182	0.0066504211946002
0.0547986032118594	822.199631270129	27.4400005340576	0.00669364783065906
0.0551972248569484	826.326488994888	27.6399993896484	0.0067302493349187
0.0555981885583146	830.351370397312	27.8400001525879	0.00676801613821669
0.0559991522596811	834.341344942362	28.0400009155273	0.00681114194210709
0.0563977739047701	838.408542676605	28.2399997711182	0.00684760594795508
0.0567940489103004	842.352633365102	28.4400005340576	0.00688052134896358
0.0571973592512252	846.462257201157	28.6399993896484	0.00697506984006469
0.057598327535872	850.531156370272	28.8400001525879	0.00679798735448665
0.0579969445976803	854.511745581026	29.0400009155273	0.00736464179802949
0.0583955662427689	858.351719432351	29.2399997711182	0.0119117474986431
0.0587965345274158	862.384614044174	29.4400005340576	0.108666947170154
0.0591974982287823	866.329418237619	29.6399993896484	0.0639267056799075
0.0595961198738709	870.10506687378	29.8400001525879	0.0554630734525094
0.0599947369356795	873.786368202032	30.0400009155273	0.0588754723655193
0.0603957052203264	877.824586658454	30.2399997711182	0.0874085652487953
0.0607966689216925	881.635251921983	30.4400005340576	0.25710045162031
0.0611952905667815	885.698003971562	30.6399993896484	0.224161313802708
0.0615939122118701	889.400051828254	30.8400001525879	0.231089895429808
0.0619948759132366	893.381848508918	31.0400009155273	0.200827466690634
0.0623958396146031	897.405412671443	31.2399997711182	0.213945456817159
0.0627944612596917	901.232653203725	31.4400005340576	0.18431058916168
0.0631930829047803	905.080256069476	31.6399993896484	0.20054806991825
0.0635940466061469	909.014193033737	31.8400001525879	0.201121969955174
0.0639950148907937	913.028536516955	32.0400009155273	0.1797240821454
0.064393631952602	916.824876796559	32.2400016784668	0.186914607413172
0.0647922535976909	920.744104581927	32.439998626709	0.203679642075394
0.0651932218823378	924.826011495064	32.6399993896484	0.200370476969818
0.0655941855837039	928.87323109081	32.8400001525879	0.199685038221399
0.0659928072287929	932.969517872866	33.0400009155273	0.20384366851388
0.0663914242906012	936.705539542006	33.2400016784668	0.202183384360291
0.066792392575248	940.615875958042	33.439998626709	0.201689765062623
0.0671933562766146	944.598770338623	33.6399993896484	0.202505698970219
0.0675919779217032	948.413606861838	33.8400001525879	0.2020373060478
0.0679905995667921	952.134150962141	34.0400009155273	0.202219408944132
0.0683915632681583	955.995420191865	34.2400016784668	0.202405911789635
0.0687948736090831	959.95844620394	34.439998626709	0.202205347439905
0.0691911486146134	963.801274075051	34.6399993896484	0.20183212175144
0.0695897702597024	967.705792681524	34.8400001525879	0.202214843996867
0.0699907339610689	971.448620090152	35.0400009155273	0.202348694117285
0.0703917022457158	975.372348445181	35.2400016784668	0.202108695223106
0.070790319307524	979.13844709206	35.439998626709	0.202410550069387
0.0711889409526126	983.144832250875	35.6399993896484	0.201952093698847
0.0715899092372595	986.851435562226	35.8400001525879	0.202040111015397
0.071990872938626	990.783286896645	36.0400009155273	0.202425106567895
0.0723918366399925	994.648507846072	36.2400016784668	0.202281411561206
0.0727881116455228	998.48485928767	36.439998626709	0.202207859077557
0.0731914219864476	1002.27192400297	36.6399993896484	0.202061377436392
0.0735900436315362	1006.14340184193	36.8400001525879	0.202182944365374
0.0739886652766252	1009.96965444429	37.0400009155273	0.202280366573278
0.0743872869217138	1013.71017668309	37.2400016784668	0.20233619092839
0.0747905972626382	1017.55607811397	37.439998626709	0.202265040083664
0.0751892143244465	1021.36377958772	37.6399993896484	0.202027736158352
0.0755901826090933	1025.33613604909	37.8400001525879	0.202245863638525
0.075986457614624	1029.08961114692	38.0400009155273	0.202351719082341
0.0763897679555488	1032.95768611613	38.2400016784668	0.202268230046813
0.0767883896006374	1036.74639738131	38.439998626709	0.202230023821508
0.0771870066624457	1040.65903896717	38.6399993896484	0.202053787524071
0.0775879703638122	1044.46739906088	38.8400001525879	0.202190277613993
0.0779865965921815	1048.25139021641	39.0400009155273	0.202314704509936
0.0783875602935476	1052.0293440224	39.2400016784668	0.202299634684024
0.0787885239949142	1055.95175513752	39.439998626709	0.202124076712085
0.0791848035837252	1059.64353949999	39.6399993896484	0.202079655558575
0.0795857672850917	1063.43642202486	39.8400001525879	0.202236367081563
0.0799867309864583	1067.33215903199	40.0400009155273	0.202286049840957
0.0803876946878244	1071.17685299296	40.2400016784668	0.202251950234879
0.0807839742766354	1074.91002064231	40.439998626709	0.202097732016421
0.081184937978002	1078.72672325539	40.6399993896484	0.202116431800399
0.0815859016793685	1082.56933158652	40.8400001525879	0.202261648456178
0.081986865380735	1086.36627560108	41.0400009155273	0.202261300126868
0.0823831449695461	1090.1996632529	41.2400016784668	0.202244561986895
0.0827864553104705	1093.92361022294	41.439998626709	0.202119841761007
0.0831850723722787	1097.87961095555	41.6399993896484	0.202190790941396
0.0835860452402059	1101.64461190251	41.8400001525879	0.202256056854106
0.0839823156624563	1105.51532135152	42.0400009155273	0.202296554719604
0.0843856260033807	1109.37263886154	42.2400016784668	0.202237723732558
0.08478425223175	1113.21316156283	42.439998626709	0.202131391627582
0.0851852159331165	1117.08013883212	42.6399993896484	0.20222234224358
0.0855791397158087	1120.70210947984	42.8400001525879	0.202305281285461
0.0859824500567331	1124.6599763023	43.0400009155273	0.202249273599133
0.0863834229246602	1128.49797429377	43.2400016784668	0.202170166179655
0.0867820399864685	1132.4137992094	43.439998626709	0.202128806657444
0.0871806570482772	1136.08132440369	43.6399993896484	0.202214404001949
0.0875816299162043	1139.91591952542	43.8400001525879	0.202271548341813
0.0879849402571287	1143.75435659686	44.0400009155273	0.202227805513801
0.088383557318937	1147.61946777629	44.2400016784668	0.202151118066367
0.088779836907748	1151.31739925829	44.439998626709	0.20217271448355
0.0891808006091146	1155.20720868587	44.6399993896484	0.202243333667751
0.0895817643104811	1159.13302267075	44.8400001525879	0.202243223669022
0.0899827280118476	1162.83885759216	45.0400009155273	0.202200269165236
0.0903813450736559	1166.6786119035	45.2400016784668	0.202169964515318
0.0907823179415831	1170.49235072679	45.439998626709	0.202212625689159
0.0911832816429496	1174.44099686995	45.6399993896484	0.202239043717309
0.0915818987047579	1178.19853345747	45.8400001525879	0.202248851937337
0.0919805249331272	1181.8376282239	46.0400009155273	0.202186115995402
0.0923814886344933	1185.7630031288	46.2400016784668	0.202151411396312
0.0927801056963016	1189.54051785482	46.439998626709	0.202208152407502
0.0931810693976681	1193.33910841926	46.6399993896484	0.202226723859629
0.0935796956260374	1197.18127767042	46.8400001525879	0.202229327162889
0.0939806593274039	1201.00094407327	47.0400009155273	0.202156159674793
0.0943816230287701	1204.81062140688	47.2400016784668	0.202168241201893
0.0947802400905788	1208.6572912277	47.439998626709	0.202237063740182
0.0951788663189476	1212.47542085067	47.6399993896484	0.202248026946868
0.0955798300203142	1216.25205741675	47.8400001525879	0.202215998983524
0.0959807937216807	1220.06195429034	48.0400009155273	0.202152328052389
0.0963794199500496	1223.99106137496	48.2400016784668	0.202215632321093
0.0967780370118579	1227.57033149589	48.439998626709	0.202228337174326
0.0971790007132244	1231.45717713369	48.6399993896484	0.202215558988607
0.097579964414591	1235.25928033786	48.8400001525879	0.202171449498163
0.0979809372825181	1239.13042886684	49.0400009155273	0.202145691462389
0.0983772077047685	1242.87040225568	49.2400016784668	0.202205714102336
0.098778171406135	1246.59654462557	49.439998626709	0.202229290496646
0.0991791351075012	1250.59381887507	49.6399993896484	0.20223123380753
0.0995777613358705	1254.25267224001	49.8400001525879	0.202156563003467
0.0999763783976788	1258.02590593635	50.0400009155273	0.20218349435902
0.100377342099045	1261.81044594184	50.2400016784668	0.202254938533691
0.100775968327414	1265.61584224577	50.439998626709	0.202215338991148
0.101179278668339	1269.47579423559	50.6399993896484	0.202174511129462
0.101575549090589	1273.15155217926	50.8400001525879	0.202191249269435
0.101976521958517	1276.96551054254	51.0400009155273	0.202191982594297
0.102375139020325	1280.80855795364	51.2400016784668	0.202206905755236
0.102778449361249	1284.60396518831	51.439998626709	0.202226668860265
0.10317472895006	1288.44920799924	51.6399993896484	0.202146259789157
0.103575692651427	1292.16272682007	51.8400001525879	0.202173576140263
0.103974309713235	1295.90489560875	52.0400009155273	0.202231637136204
0.104375273414602	1299.73268499099	52.2400016784668	0.202197207533938
0.104771553003413	1303.42073717374	52.439998626709	0.202195722551093
0.105174863344337	1307.24940471591	52.6399993896484	0.202164079583301
0.105575827045704	1311.02659013196	52.8400001525879	0.202168534531837
0.105974444107512	1314.8637099635	53.0400009155273	0.202240620365762
0.106373070335881	1318.65812926825	53.2400016784668	0.202188774298026
0.106771687397689	1322.40809172634	53.439998626709	0.202163107927859
0.107174997738614	1326.25190752738	53.6399993896484	0.202200800825761
0.107573623966983	1330.08013598959	53.8400001525879	0.202186995985236
0.107969894389233	1333.52175454086	54.0400009155273	0.202194677563164
0.1083708580906	1337.35130024297	54.2400016784668	0.20220884906612
0.108771821791966	1341.04813402505	54.439998626709	0.202159459636671
0.109172794659893	1344.99436522839	54.6399993896484	0.202176509439711
0.109571411721702	1348.85014595853	54.8400001525879	0.202212662355402
0.10997002878351	1352.50351082388	55.0400009155273	0.202193907572059
0.110373339124435	1356.29727150868	55.2400016784668	0.202142721496698
0.110774311992362	1360.10113103272	55.439998626709	0.202182504370457
0.111170582414612	1363.79379355512	55.6399993896484	0.202183897687694
0.111571546115978	1367.59743353918	55.8400001525879	0.202200525828938
0.111970172344348	1371.30052421079	56.0400009155273	0.202212552356673
0.112371136045714	1375.05575562849	56.2400016784668	0.202157809655732
0.112769753107522	1378.80780371642	56.439998626709	0.202157717990124
0.113170716808889	1382.51989552736	56.6399993896484	0.202205567437363
0.113571689676816	1386.28346946443	56.8400001525879	0.202199847503441
0.113972653378183	1390.10609965706	57.0400009155273	0.202165271236202
0.114368923800433	1393.83696213659	57.2400016784668	0.202168131203163
0.11476989666836	1397.64049235065	57.439998626709	0.202181697713109
0.115170860369726	1401.39912663809	57.6399993896484	0.202183714356479
0.115569477431535	1405.04821047377	57.8400001525879	0.202188059306285
0.115968103659904	1408.70464889889	58.0400009155273	0.202158322983135
0.116366720721712	1412.42135104948	58.2400016784668	0.202174162800152
0.116770031062637	1416.18086349686	58.439998626709	0.202189764286589
0.117168648124445	1419.9221541256	58.6399993896484	0.202217648964463
0.117567274352814	1423.548296033	58.8400001525879	0.202157277995207
0.117968238054181	1427.20978387774	59.0400009155273	0.202145434798687
0.118369201755547	1431.05129450895	59.2400016784668	0.202193302579048
0.118767818817356	1434.69269444521	59.439998626709	0.2021792227417
0.119166445045725	1438.46153734188	59.6399993896484	0.202157277995207
0.119565062107533	1441.95979720889	59.8400001525879	0.202174804459407
0.1199660258089	1445.81404115915	60.0400009155273	0.202170404510235
0.120366998676827	1449.51559505088	60.2400016784668	0.202169377855429
0.120763269099077	1453.07335025342	60.439998626709	0.202202670804159
0.121166579440002	1456.62133592669	60.6399993896484	0.202183109363468
0.12156520566837	1460.51443845403	60.8400001525879	0.202150696404572
0.121966169369737	1464.1715354991	61.0400009155273	0.202175611116755
0.122364786431545	1467.9174364675	61.2400016784668	0.202192110926148
0.122763403493354	1471.51525771703	61.439998626709	0.202185639334241
0.123164376361281	1475.17509901189	61.6399993896484	0.202150934735152
0.123565340062647	1478.87687244361	61.8400001525879	0.202185419336783
0.123961610484898	1482.48259713254	62.0400009155273	0.202169176191092
0.124364920825822	1486.09424940103	62.2400016784668	0.202169542853522
0.124765893693749	1489.83235670002	62.439998626709	0.202183879354573
0.125164510755558	1493.41942049035	62.6399993896484	0.202143711485262
0.125563127817366	1497.06169858654	62.8400001525879	0.202168827861782
0.125961754045735	1500.77159499764	63.0400009155273	0.202168516198716
0.12636506438666	1504.3597564879	63.2400016784668	0.202158964642389
0.126763681448468	1507.95538233759	63.439998626709	0.202167984538191
0.127162298510276	1511.57186448572	63.6399993896484	0.20215612300855
0.127560924738646	1515.22874199081	63.8400001525879	0.20215399636645
0.127961888440012	1518.87310571684	64.0400009155273	0.202193009249104
0.128362852141378	1522.5743302986	64.2399978637695	0.202157351327693
0.128761478369748	1525.87346740058	64.4400024414063	0.2021375332233
0.129160095431556	1529.39433988589	64.6399993896484	0.202166517888467
0.129561059132922	1533.21224996888	64.8399963378906	0.202170532842086
0.129962022834289	1536.80557064875	65.0400009155273	0.202153226375345
0.130360649062658	1540.25366562953	65.2399978637695	0.202161274615705
0.130761612764024	1543.80812773232	65.4400024414063	0.202140594854599
0.131160229825833	1547.42845183016	65.6399993896484	0.202157607991395
0.131561193527199	1551.02363859989	65.8399963378906	0.20217507945623
0.131959819755568	1554.64308453779	66.0400009155273	0.202140264858411
0.132360783456935	1558.18031275187	66.2399978637695	0.202157149663356
0.132761747158301	1561.81666326851	66.4400024414063	0.202140099860317
0.133162710859668	1565.4561971149	66.6399993896484	0.202142684830455
0.133558990448479	1568.91537886485	66.8399963378906	0.202187674310733
0.133959954149845	1572.50749207481	67.0400009155273	0.202147488108301
0.134360917851211	1576.09159207537	67.2399978637695	0.202131978287472
0.134759544079581	1579.64166337849	67.4400024414063	0.202156214674158
0.135158161141389	1583.0961250188	67.6399993896484	0.202148148100676
0.135556778203197	1586.74542839446	67.8399963378906	0.20215150306192
0.135960088544122	1590.18792510566	68.0400009155273	0.202159037974876
0.136361061412049	1594.00462771874	68.2399978637695	0.202133004942278
0.136757331834299	1597.40167965336	68.4400024414063	0.202150843069544
0.137158295535666	1601.0072945723	68.6399993896484	0.202161659611257
0.137559268403593	1604.52871590758	68.8399963378906	0.202148496429986
0.137960232104959	1607.97637180839	69.0400009155273	0.202141089848881
0.13835650252721	1611.54828733987	69.2399978637695	0.202155756346119
0.138755128755579	1614.98935704118	69.4400024414063	0.202137624888908
0.139156092456945	1618.5580892429	69.6399993896484	0.202142593164848
0.13955940279787	1622.06063013959	69.8399963378906	0.202151118066367
0.13995567322012	1625.63990026052	70.0400009155273	0.202144609808218
0.140356646088047	1629.06263837321	70.2399978637695	0.202133994930842
0.140755263149856	1632.56638673981	70.4400024414063	0.202164611243826
0.14115857349078	1636.08253911548	70.6399993896484	0.202136561567858
0.141554853079591	1639.41098480526	70.8399963378906	0.202123141722886
0.141955816780957	1643.06358128067	71.0400009155273	0.202138853208052
0.142354433842766	1646.53802105947	71.2399978637695	0.202149633083522
0.142757744183691	1650.05768607488	71.4400024414063	0.202135608245538
0.143154023772502	1653.52773505401	71.6399993896484	0.202126331686035
0.143554987473868	1657.01117597214	71.8399963378906	0.202140741519571
0.143955951175235	1660.45125774353	72.0400009155273	0.202139934862223
0.144354577403604	1664.10725708868	72.2399978637695	0.202147378109572
0.14475554110497	1667.55140034977	72.4400024414063	0.202130859967057
0.14515181152722	1670.98478615166	72.6399993896484	0.202114030161476
0.145555121868145	1674.42695355289	72.8399963378906	0.202154913022528
0.145956085569511	1677.87054796401	73.0400009155273	0.202135021585648
0.146352365158322	1681.34992739245	73.2399978637695	0.202134361593273
0.146753328859689	1684.74588162715	73.4400024414063	0.202143784817748
0.147154292561055	1687.97443662444	73.6399993896484	0.202113516834073
0.147555265428982	1691.35425467036	73.8399963378906	0.202144078147693
0.147953882490791	1694.86327199656	74.0400009155273	0.202135828242996
0.148352499552599	1698.15176140935	74.2399978637695	0.20211560680993
0.148753472420526	1701.59239203069	74.4400024414063	0.202130804967693
0.149154436121893	1705.08878580785	74.6399993896484	0.202129539982306
0.149553053183701	1708.55773708707	74.8399963378906	0.202134856587555
0.149954016885068	1712.03656766554	75.0400009155273	0.202128549993742
0.150352643113437	1715.43757131987	75.2399978637695	0.20212781666888
0.150753606814803	1718.95130875572	75.4400024414063	0.202129503316063
0.151152223876611	1722.2943538544	75.6399993896484	0.202131354961339
0.151553187577978	1725.83410677829	75.8399963378906	0.202128219997554
0.151951813806347	1729.16672372776	76.0400009155273	0.202127376673963
0.152352777507713	1732.66377612486	76.2399978637695	0.202107613568935
0.152751394569522	1735.9449109482	76.4400024414063	0.202124296709543
0.153150020797891	1739.49366501142	76.6399993896484	0.202131574958798
0.153553331138815	1743.06162882319	76.8399963378906	0.202114836818824
0.153951948200624	1746.31839470836	77.0400009155273	0.202125121700013
0.15435291190199	1749.74080351108	77.2399978637695	0.202139549866671
0.154749182324241	1753.27506793538	77.4400024414063	0.202118613441863
0.155152492665165	1756.82239498871	77.6399993896484	0.202123728382775
0.155553474699653	1760.28113765869	77.8399963378906	0.202122756727333
0.155952091761461	1763.63922124625	78.0400009155273	0.202117128459018
0.15635070882327	1767.09554897641	78.2399978637695	0.202131904954985
0.156751672524636	1770.57448932488	78.4400024414063	0.202137239893356
0.157152636226003	1774.07615206164	78.6399993896484	0.202096045369238
0.157551253287811	1777.45706780747	78.8399963378906	0.202130621636477
0.157949870349619	1780.98287994242	79.0400009155273	0.202116945127803
0.158350852384107	1784.58377475171	79.2399978637695	0.202108768555593
0.158754162725032	1788.07303347941	79.4400024414063	0.202122628395482
0.159150433147282	1791.49214918237	79.6399993896484	0.202113553500316
0.159551396848648	1794.83640175096	79.8399963378906	0.202116688464101
0.159947667270899	1798.26067664354	80.0400009155273	0.202136176572306
0.160350977611823	1801.74148308186	80.2399978637695	0.202102553627388
0.160749594673632	1805.12854594724	80.4400024414063	0.202122445064267
0.161150558374998	1808.39453251171	80.6399993896484	0.202133573269046
0.161549193769928	1811.55612781403	80.8399963378906	0.20209736535399
0.161950157471294	1814.95252112871	81.0400009155273	0.202121620073797
0.162348774533103	1818.45561087536	81.2399978637695	0.202132399949267
0.162747391594911	1821.94377190313	81.4400024414063	0.202099986990371
0.163148355296278	1825.22929752614	81.6399993896484	0.202106531914763
0.163549318997644	1828.54039955722	81.8399963378906	0.202093240401642
0.163947954392574	1832.02965828491	82.0400009155273	0.202112710176725
0.164346571454382	1835.22659952458	82.2399978637695	0.202127633337665
0.164747535155749	1838.7034542432	82.4400024414063	0.202105450260592
0.165148498857115	1842.02520396348	82.6399993896484	0.202086218816089
0.165547115918924	1845.30974165656	82.8399963378906	0.202140099860317
0.165945732980732	1848.71568496052	83.0400009155273	0.202093827061531
0.166346696682098	1852.07837888772	83.2399978637695	0.202113278503493
0.166747660383465	1855.4880543714	83.4400024414063	0.202117201791504
0.167148642417953	1858.68916687075	83.6399993896484	0.202098355342554
0.167544912840203	1860.64724398355	83.8399963378906	0.202116688464101
0.167945876541569	1863.63737855876	84.0400009155273	0.202107778567029
0.168349186882494	1867.03146670361	84.2399978637695	0.202100518650896
0.168745457304744	1870.18932982621	84.4400024414063	0.20211419515957
0.169146421006111	1873.46289052012	84.6399993896484	0.20211074853272
0.169542709761483	4.48021161608519	84.8000030517578	0.20280650882857