File: CouponData/8-45T-1.txt
File Path: C:\Users\MTS\Desktop\SE171\Test Run 36 2-3-2017 3 08 22 PM\DAQ- Crosshead, … - (Timed).txt
Test: MTS EM Tension (Extensometer-Crosshead) 171-2017-W
Test Run: Test Run 36
Date: 2/3/2017 2:50:35 PM


Crosshead 	Load 	Time 	Extensometer
in	lbf	sec	in
0.000933241035526169	10.3952542368052	0.239999994635582	9.38650787892276E-06
0.00259806800773001	32.0954077653132	0.639999985694885	0.000262614357207057
0.00426523997237555	53.1098676039626	1.03999996185303	0.000526550274668169
0.00593241193702106	73.2700287605853	1.44000005722046	0.000794129237609614
0.00759958361521158	92.4886000795556	1.8400000333786	0.00107009134264058
0.00926675529340209	110.742224564817	2.24000000953674	0.00134486995873914
0.0109315820507646	127.93751539589	2.64000010490417	0.00161828927413421
0.0125987548747753	144.518862663116	3.03999996185303	0.00189405522908737
0.0142659265529658	160.225987994814	3.44000005722046	0.00218061910617701
0.0159307538832384	175.324781753493	3.83999991416931	0.00246880804261882
0.017593235719773	189.613802283049	4.23999977111816	0.00275506569928761
0.0192604085437836	203.145999883249	4.6399998664856	0.00305361829204925
0.020927579076154	216.275012303759	5.03999996185303	0.00334909235266602
0.0225970962480825	228.624548012868	5.44000005722046	0.00365450095997639
0.0242595780846172	240.407176599593	5.84000015258789	0.00395713811492783
0.0259244042690697	251.59852912577	6.23999977111816	0.00427121227317469
0.0275915770930803	262.100663316259	6.6399998664856	0.0045876198940485
0.0292587499170909	272.286769700506	7.03999996185303	0.00490802929161016
0.0309282647973792	281.88884484366	7.44000005722046	0.00523362553029461
0.0325930932734719	290.88235515256	7.84000015258789	0.00555536780308374
0.0342555751100065	299.587609463133	8.23999977111816	0.00589176855237024
0.0359227456423769	307.731225610927	8.64000034332275	0.00622633942696228
0.0375899184663875	315.596135749673	9.03999996185303	0.00656842229810843
0.039257088998758	323.1579983837	9.4399995803833	0.0069087766996387
0.0409242618227685	330.319255432844	9.84000015258789	0.00726042544986232
0.0425890880072213	337.128836870925	10.2399997711182	0.00761167889215256
0.0442562608312315	343.674201938869	10.6400003433228	0.0079660512567461
0.0459257757115201	350.011168677479	11.039999961853	0.00831997102240146
0.0475906064792528	356.202251097058	11.4399995803833	0.00867156591908051
0.0492577747199831	361.946350110237	11.8400001525879	0.0090229591514226
0.0509202588481579	367.590064465964	12.2399997711182	0.00936699965620398
0.0525874316721685	373.044809780898	12.6400003433228	0.00970953741792854
0.0542546044961791	378.250651639542	13.039999961853	0.0100533556336112
0.0559217727369094	383.349248216249	13.4399995803833	0.0103930867090088
0.0575866035046421	388.154045410041	13.8400001525879	0.0107276134695271
0.0592537717453724	393.030906603417	14.2399997711182	0.0110617586719532
0.0609209445693831	397.622667685726	14.6400003433228	0.0113740599600554
0.0625881173933937	401.967144419125	15.039999961853	0.0116544295337022
0.0642552902174043	406.463817246081	15.4399995803833	0.0119041931067454
0.0659201164018567	410.603545502372	15.8400001525879	0.012111478837163
0.0675849425863095	414.761824887269	16.2399997711182	0.0123158851216774
0.0692497687707618	418.703857388422	16.6399993896484	0.0125314173193311
0.0709192882343307	422.65113140668	17.0400009155273	0.0127614441412083
0.0725864564750606	426.608394494189	17.4400005340576	0.0130020170912557
0.0742512872427937	430.311732148286	17.8400001525879	0.0132597876551348
0.0759161134272461	433.937023338249	18.2399997711182	0.0135186708103279
0.0775832862512567	437.611271944532	18.6399993896484	0.0137992397566715
0.0792528011315453	441.213923073699	19.0400009155273	0.0141077999421579
0.080917631899278	444.592396437218	19.4400005340576	0.014383530090233
0.0825848001400083	448.016424347313	19.8400001525879	0.0146601505405233
0.0842496309077409	451.45771358861	20.2399997711182	0.0149532868416877
0.0859167991484713	454.704435519533	20.6399993896484	0.0152508746539279
0.0875839673892016	457.977365035988	21.0400009155273	0.0155246878449813
0.0892511447964925	461.212451347785	21.4400005340576	0.0158192896500494
0.0909159663976646	464.149621901981	21.8400001525879	0.0161097802526105
0.0925807971653976	467.291403720793	22.2399997711182	0.0164041276856172
0.0942503120456858	470.35464511051	22.6399993896484	0.0166973625273099
0.0959174894529768	473.458062317206	23.0400009155273	0.0169873627188696
0.0975846576937071	476.441171612947	23.4400005340576	0.0172792489303085
0.0992494884614402	479.217584014227	23.8400001525879	0.017570538169477
0.100914310062612	482.056181115833	24.2399997711182	0.0178569702772556
0.1025838249429	484.987149665494	24.6399993896484	0.0181590989745391
0.104251002350191	487.853902769982	25.0400009155273	0.0184752891760495
0.105913486478366	490.584266659723	25.4400005340576	0.018781966779117
0.107580654719096	493.119294849149	25.8400001525879	0.0191020206859937
0.109247822959827	495.954818390986	26.2399997711182	0.0194194827478115
0.110917347006676	498.72557763769	26.6399993896484	0.019739961753944
0.112584515247406	501.433109369149	27.0400009155273	0.0200693460738682
0.114249346015139	503.867258936159	27.4400005340576	0.0203869330300766
0.115914167616311	506.497732133408	27.8400001525879	0.0207065389212954
0.117581335857041	509.171619362396	28.2399997711182	0.021026699389441
0.11925085990389	511.713288636324	28.6399993896484	0.0213528983294964
0.12091802814462	514.274332313794	29.0400009155273	0.021671791520615
0.122582858912354	516.656670444699	29.4400005340576	0.0219888216082564
0.124247680513526	519.151522817145	29.8400001525879	0.0223033102669232
0.125912511281259	521.502082535438	30.2399997711182	0.0226198316104417
0.127582026161547	524.079427056684	30.6399993896484	0.0229456730546269
0.129249194402277	526.508197894098	31.0400009155273	0.023263612923425
0.13091402517001	528.982962358055	31.4400005340576	0.0235795521903343
0.132578855937743	531.190656432089	31.8400001525879	0.0238975974745814
0.134248370818031	533.567780488384	32.2400016784668	0.0242176800269604
0.135917885698319	535.990953056219	32.6399993896484	0.024531703482668
0.13758505393905	538.392610705672	33.0400009155273	0.0248482500342285
0.139247538067224	540.589163125544	33.439998626709	0.0251622780732165
0.140912368834957	542.947516513251	33.8400001525879	0.0254720390781643
0.142579537075687	545.151094212595	34.2400016784668	0.0257853590003325
0.144249051955976	547.480962287445	34.6399993896484	0.0260949481322658
0.145913882723709	549.70193853048	35.0400009155273	0.0264098492861674
0.147578713491442	551.945033426852	35.439998626709	0.0267211892312085
0.149245881732172	554.229182300139	35.8400001525879	0.0270369085006592
0.150913049972902	556.371179034111	36.2400016784668	0.0273459934717499
0.152580227380193	558.670421281262	36.6399993896484	0.0276587679835521
0.154247404787484	560.865217381267	37.0400009155273	0.0279644246609133
0.155912217222096	563.05655572653	37.439998626709	0.0282789843604262
0.157579394629387	565.214908189272	37.8400001525879	0.0285890157789168
0.159248918676235	567.427706567924	38.2400016784668	0.0288997759389889
0.160913731110847	569.615642043443	38.6399993896484	0.0292081321684981
0.16257856187858	571.641776551126	39.0400009155273	0.0295220800000793
0.164243392646313	573.776308925658	39.439998626709	0.0298268635625269
0.165910570053604	575.814847442409	39.8400001525879	0.0301354054148918
0.167577729127773	577.923638753878	40.2400016784668	0.0304508863537624
0.169244906535064	580.087754141188	40.6399993896484	0.0307494114468417
0.170912083942355	582.098026885064	41.0400009155273	0.0310636526083676
0.172576914710088	584.128222882442	41.439998626709	0.0313715390516372
0.174246420423816	586.266761861674	41.8400001525879	0.0316884728903904
0.175913597831107	588.299592338854	42.2400016784668	0.0319903506530728
0.177580775238398	590.337197810673	42.6399993896484	0.0322946140131965
0.179245587673009	592.304111407809	43.0400009155273	0.0326009902655785
0.180910418440742	594.210980819457	43.439998626709	0.032905180293216
0.182577595848033	596.267027649892	43.8400001525879	0.0332104382251837
0.184244773255324	598.17455568149	44.2400016784668	0.0335180450883496
0.185911932329493	600.231535556854	44.6399993896484	0.0338272721411323
0.187576763097226	602.188789394716	45.0400009155273	0.0341352273336076
0.189241593864959	604.009214937864	45.439998626709	0.0344425798247121
0.19090877127225	605.922615664021	45.8400001525879	0.0347425601093143
0.192578276985978	607.886345931394	46.2400016784668	0.0350490692768275
0.194245454393269	609.827298925481	46.6399993896484	0.0353532776375866
0.195910285161002	611.678240526334	47.0400009155273	0.0356583224470163
0.197577444235171	613.534341316799	47.439998626709	0.0359601497936143
0.199244621642462	615.240935378504	47.8400001525879	0.0362611292333408
0.200911799049753	617.190834626919	48.2400016784668	0.0365592509977461
0.202576629817486	618.956539829179	48.6399993896484	0.0368660007874797
0.204241442252097	620.818568199199	49.0400009155273	0.0371684995846544
0.20590627301983	622.633779667739	49.439998626709	0.0374763310285593
0.207575797066679	624.513041926463	49.8400001525879	0.0377830029025263
0.209245302780407	626.290272977856	50.2400016784668	0.0380890010342765
0.21091013354814	628.192202739878	50.6399993896484	0.0383916258716619
0.212577310955431	629.913121785504	51.0400009155273	0.0386957425668132
0.214242141723163	631.627729056607	51.439998626709	0.0390006865440743
0.215911647436891	633.332237488468	51.8400001525879	0.0393045809501269
0.217578824844182	635.269348532843	52.2400016784668	0.0396023612601433
0.219243655611915	636.934723962648	52.6399993896484	0.0398779722429283
0.220908486379648	638.804052037118	53.0400009155273	0.0402084588417858
0.222573298814259	640.313114998673	53.439998626709	0.0405111157621339
0.224242822861108	642.027941809759	53.8400001525879	0.0408225496644228
0.225910000268399	643.83074926923	54.2400016784668	0.0411270765631685
0.227574812703011	645.421700644629	54.6399993896484	0.0414284409984476
0.229239643470744	646.975988842782	55.0400009155273	0.0417359745291276
0.230906820878035	648.53142962585	55.439998626709	0.0420437876399106
0.232576344924883	650.214093829354	55.8400001525879	0.0423539244738504
0.234243503999053	651.926450815626	56.2400016784668	0.0426636304794335
0.235908334766786	653.522177185666	56.6399993896484	0.0429732081531658
0.237573165534519	655.054730925453	57.0400009155273	0.0432757229918216
0.23924034294181	656.604189243972	57.439998626709	0.0435860614900984
0.240909848655537	658.277522998177	57.8400001525879	0.0438969178990587
0.24257467942327	659.611996787856	58.2400016784668	0.0442044330966169
0.244239510191003	661.181323474879	58.6399993896484	0.0445137495233669
0.245904340958736	662.64614912976	59.0400009155273	0.0448235426112776
0.247573846672464	664.199504282984	59.439998626709	0.0451389960504658
0.249243370719313	665.655109258556	59.8400001525879	0.0454628414760425
0.250908201487046	667.072239852022	60.2400016784668	0.0457828506959354
0.252573013921657	668.553256580685	60.6399993896484	0.0461015949304413
0.254240191328948	669.951561620566	61.0400009155273	0.046415962132178
0.255907368736239	671.369460603974	61.439998626709	0.0467355176073126
0.257574527810408	672.759148699503	61.8400001525879	0.0470523781135795
0.259241705217699	674.249056797497	62.2400016784668	0.0473782951818909
0.260906535985432	675.500434703423	62.6399993896484	0.047695105272074
0.262571366753165	676.744018939935	63.0400009155273	0.0480262243636244
0.264238525827335	678.133707035464	63.439998626709	0.0483487910539732
0.265908049874184	679.401111360185	63.8400001525879	0.0486768989303098
0.267572880641917	680.688768248383	64.2399978637695	0.0490052130542638
0.26923771140965	681.876479559095	64.6399993896484	0.0493351175765118
0.270904870483819	683.082577343426	65.0400009155273	0.0496693074659217
0.27257204789111	684.383845710601	65.4400024414063	0.0500044460943717
0.274241571937959	685.541974008538	65.8399963378906	0.0503394930572138
0.27590638437257	686.636051516289	66.2399978637695	0.050678651222563
0.277571215140303	687.531994188936	66.6399993896484	0.0510145231758752
0.279238392547594	688.495610061494	67.0400009155273	0.0513601071003268
0.280907898261322	689.462464148809	67.4400024414063	0.0516995998451441
0.282575075668613	690.528934503637	67.8399963378906	0.0520496249682909
0.284239906436346	691.485854406698	68.2399978637695	0.0524058512698008
0.285907083843637	692.587560928877	68.6399993896484	0.0527598225973606
0.287571896278248	693.51401965923	69.0400009155273	0.0531230934008252
0.289241420325097	694.413968936574	69.4400024414063	0.0534918962237169
0.29090625109283	695.279889516478	69.8399963378906	0.0538631556848961
0.292573428500121	696.240322059275	70.2399978637695	0.0542361980421453
0.294238240934732	696.912443718748	70.6399993896484	0.0546179623819713
0.295907764981582	697.674576771453	71.0400009155273	0.0549984571531299
0.297574942388872	698.371396679069	71.4400024414063	0.0553927246818508
0.299242101463042	698.981772718185	71.8399963378906	0.0557780410639764
0.300906932230775	699.632763654244	72.2399978637695	0.0561682661393965
0.302571762998508	700.357959104728	72.6399993896484	0.0565603153604106
0.304241287045357	701.091497074582	73.0400009155273	0.0569581578478335
0.305908446119526	701.752531964888	73.4400024414063	0.0573498495729772
0.307575623526817	702.462908466486	73.8399963378906	0.057748319969813
0.309238107654992	703.088542534452	74.2399978637695	0.0581528357134795
0.310905285062283	703.724879176614	74.6399993896484	0.0585464707495071
0.312572462469574	704.29881157847	75.0400009155273	0.0589509819098933
0.31424194985018	704.837288272988	75.4400024414063	0.0593533755947402
0.315906780617913	705.432022088278	75.8399963378906	0.0597573092617976
0.317573958025204	705.849038286928	76.2399978637695	0.060163580401852
0.319238788792937	706.333782570487	76.6399993896484	0.0605679036477421
0.320908312839786	706.797944980594	77.0400009155273	0.0609760951822784
0.322575490247077	707.243446492102	77.4400024414063	0.0613882741707516
0.32424032101481	707.569792677568	77.8399963378906	0.0618032581268217
0.325905151782542	707.936150025028	78.2399978637695	0.062218874575585
0.327569945884033	708.078631474317	78.6399993896484	0.0626369384960748
0.329239469930882	708.384286016338	79.0400009155273	0.0630565790650177
0.330908993977731	708.491970378243	79.4400024414063	0.0634881178298453
0.332573824745463	708.597075145342	79.8399963378906	0.0639132583352524
0.334238655513196	708.71787702126	80.2399978637695	0.0643349201308461
0.335905832920487	708.718480756215	80.6399993896484	0.064771000926537
0.337575320301093	708.61266248417	81.0400009155273	0.0652158174546449
0.339242497708384	708.428687978001	81.4400024414063	0.0656493453631602
0.340907328476117	708.294384393096	81.8399963378906	0.0660973656042591
0.34257215924385	707.80190132512	82.2399978637695	0.066541957551628
0.344239336651141	707.572866237337	82.6399993896484	0.0669923977647709
0.345906514058432	707.27220622994	83.0400009155273	0.067446880431215
0.347576038105282	706.775442132286	83.4400024414063	0.0679033934908705
0.349240832206771	706.460676680947	83.8399963378906	0.0683599111338067
0.350905662974504	706.03191509318	84.2399978637695	0.0688241286877925
0.352575187021353	705.732243015708	84.6399993896484	0.0692836346295406
0.354242364428644	705.525765661231	85.0400009155273	0.0697420405839957
0.355909541835935	704.941020915189	85.4400024414063	0.0702175742572571
0.357574372603668	704.560777663775	85.8399963378906	0.0707036998914921
0.359241550010959	703.975099872805	86.2399978637695	0.0711945875540492
0.360906380778692	703.4018260909	86.6399993896484	0.071690278494452
0.362575868159298	702.956653889368	87.0400009155273	0.0721850802784594
0.364240698927031	702.441613088087	87.4400024414063	0.0727090729752512
0.365905529694764	701.843805713028	87.8399963378906	0.0735199652744209
0.367570360462496	701.21471389032	88.2399978637695	0.0645245671066949
0.369237537869787	700.644129473215	88.6399993896484	0.0694858031274063
0.370907061916637	699.982875042925	89.0400009155273	0.0464272415852102
0.372574239323928	699.319260557812	89.4400024414063	0.0617086042202717
0.374239033425417	698.636820519116	89.8399963378906	0.22236848118033
0.375906210832709	697.735444231879	90.2399978637695	0.233444088233972
0.37757338824	696.959480160213	90.6399993896484	0.198929218619358
0.379240565647291	696.282034656139	91.0400009155273	0.180141728987375
0.380907743054582	695.469846487197	91.4400024414063	0.193715700513031
0.382570227182756	694.665726412649	91.8399963378906	0.203380793861048
0.384237404590047	694.008478587057	92.2399978637695	0.19584226928006
0.385906891970653	693.313908964273	92.6399993896484	0.196183063676508
0.387574069377944	692.562039405795	93.0400009155273	0.195612133605274
0.389241246785235	691.927843278472	93.4400024414063	0.201206852307939
0.390906077552968	691.149080072016	93.8399963378906	0.196210893355017
0.392573254960259	690.517957504462	94.2399978637695	0.197178130514744
0.394242779007106	689.62832660634	94.6399993896484	0.197435252544448
0.395909919748157	688.933153248601	95.0400009155273	0.197973311328747
0.39757475051589	688.083313972488	95.4400024414063	0.19646966536566
0.399237234644063	687.254550534792	95.8399963378906	0.197864229255539
0.400904412051354	686.428037381927	96.2399978637695	0.196771318547604
0.402573936098205	685.567330876632	96.6399993896484	0.197507631708318
0.404238766865937	684.611837983461	97.0400009155273	0.198398804746744
0.405905944273228	683.749430043295	97.4400024414063	0.197129731073858
0.407570775040961	682.968581206995	97.8399963378906	0.19821477687265
0.409240262421567	681.920332670799	98.2399978637695	0.197432520909337
0.410909786468417	680.889482678295	98.6399993896484	0.197521601546937
0.41257461723615	679.939148974736	99.0400009155273	0.198036175602534
0.414241794643441	678.818726668965	99.4400024414063	0.197638731860504
0.415904278771614	677.817624344224	99.8399963378906	0.197843989489351
0.417573802818465	677.023218913945	100.23999786377	0.197738390709237
0.419240980225756	676.103456153089	100.639999389648	0.197755458845398
0.420908120966803	675.112946632553	101.040000915527	0.197605145581829
0.422572951734535	674.247026052648	101.440002441406	0.197791116766807
0.424237782502268	673.437966328472	101.839996337891	0.197587784115724
0.425907306549118	672.664746506599	102.23999786377	0.197841569517306
0.42757448395641	672.050473632778	102.639999389648	0.197723009220258
0.429241661363701	671.491415064806	103.040000915527	0.197680879706942
0.430906492131433	670.715121683165	103.440002441406	0.1978196981033
0.43257363287248	670.045908928473	103.839996337891	0.197555132826248
0.434240810279772	669.53141697715	104.23999786377	0.197809376555869
0.435910334326622	668.811655141259	104.639999389648	0.197650905053212
0.437575165094354	668.047930423674	105.040000915527	0.197733844095093
0.439239995862087	667.386621108388	105.440002441406	0.197768200364873
0.440904826629819	666.56998725478	105.839996337891	0.197655653331693
0.442574350676669	665.663835972901	106.23999786377	0.197762737094652
0.444241491417717	664.893085975842	106.639999389648	0.197630793618874
0.445906322185449	664.107132834927	107.040000915527	0.197752488879707
0.44757349959274	663.157896831289	107.440002441406	0.197661043269428
0.449240677000032	662.374193975203	107.839996337891	0.197743798980093
0.450910201046878	661.678526652502	108.23999786377	0.197711679351142
0.452575031814614	660.992628859064	108.639999389648	0.19768168636429
0.454239862582347	660.347730157545	109.040000915527	0.197753973862552
0.455907003323394	659.793172159235	109.440002441406	0.197616072122272
0.457571834091126	659.206616208331	109.839996337891	0.197763122090204
0.459241358137976	658.635812251242	110.23999786377	0.197649035074814
0.460908535545268	658.354142452417	110.639999389648	0.197717875946225
0.462573366313	657.959629102075	111.040000915527	0.197715712637883
0.464238197080732	657.528781884464	111.440002441406	0.197671658146804
0.465907721127583	657.007374423662	111.839996337891	0.197733587431391
0.46757486186863	656.601225454194	112.23999786377	0.197645533448598
0.469242039275921	656.236734196594	112.639999389648	0.197727830831226
0.470906870043654	655.793428084922	113.040000915527	0.197654131682604
0.472571700811386	655.358629147608	113.440002441406	0.197719965922081
0.474241224858236	655.005334429166	113.839996337891	0.197688469619263
0.475908402265528	654.509997341405	114.23999786377	0.197683758007025
0.47757323303326	654.006756814236	114.639999389648	0.197721359239319
0.479238063800992	653.425030742969	115.040000915527	0.197646468437798
0.480905204542039	652.977663141599	115.440002441406	0.197734430754983
0.482572381949331	652.329910420295	115.839996337891	0.197650905053212
0.484244252635736	651.910808591801	116.23999786377	0.197716519295231
0.485909083403472	651.570796042363	116.639999389648	0.197681998027357
0.487573914171205	651.088576468615	117.040000915527	0.19768428966755
0.489241091578496	650.711297006977	117.440002441406	0.197707664397523
0.490908268985787	650.222052153757	117.839996337891	0.19765739497824
0.492575409726835	649.92056887142	118.23999786377	0.197716757625811
0.494240240494567	649.610578414724	118.639999389648	0.19764674343462
0.495905071262299	649.198172555727	119.040000915527	0.197712394342882
0.49757459530915	648.853494781638	119.440002441406	0.197665058223047
0.499244119355996	648.705689487751	119.839996337891	0.197685811316639
0.500911296763287	648.567598838132	120.23999786377	0.197690999590037
0.50257612753102	648.327147671207	120.639999389648	0.197662803249096
0.504240921632512	647.885378339419	121.040000915527	0.197702824453435
0.505908099039803	647.463861571107	121.440002441406	0.197655213336776
0.507575276447095	646.910950122673	121.839996337891	0.197701101140009
0.509242453854386	646.358422869209	122.23999786377	0.197663059912798
0.510907284622118	646.020989914575	122.639999389648	0.197694336218158
0.51257211538985	645.599418261269	123.040000915527	0.197676754754594
0.514241639436701	644.954135364778	123.440002441406	0.197668156520588
0.515908780177748	644.688437099753	123.839996337891	0.197693199564622
0.517575957585039	644.419939699938	124.23999786377	0.197656166659096
0.519240788352772	644.026414279521	124.639999389648	0.197700734477578
0.520907965760063	643.659782507083	125.040000915527	0.197654993339317
0.522575143167354	643.429045984429	125.440002441406	0.197688139623075
0.524244667214201	643.202974686423	125.839996337891	0.197670686491362
0.525909497981933	642.884092860396	126.23999786377	0.197676314759677
0.527574292083425	642.398470416903	126.639999389648	0.19768771796128
0.529241469490716	642.107140858804	127.040000915527	0.197662583251638
0.530906300258449	641.584800353073	127.440002441406	0.19768962460592
0.532575824305299	641.181285863407	127.839996337891	0.1976545533444
0.534243001712591	640.615695980925	128.240005493164	0.197690082933959
0.535907832480323	640.104112934385	128.639999389648	0.197659961615256
0.537575009887614	639.576942549015	129.039993286133	0.197683483010202
0.53924449726822	639.259981697844	129.440002441406	0.197676534757135
0.540911674675508	638.713436908931	129.839996337891	0.197665498217964
0.542576505443244	638.101359434945	130.240005493164	0.197686049647219
0.544241336210976	637.606351657156	130.639999389648	0.197654920006831
0.545906166978709	636.825667475845	131.039993286133	0.197690541261998
0.547575691025559	635.897836620597	131.440002441406	0.197662436586665
0.54924286843285	634.738665507739	131.839996337891	0.197677579745064
0.550910009173898	631.883657792368	132.240005493164	0.197665259887384
0.55257483994163	625.558985292832	132.639999389648	0.197672391471666
0.554242017348921	622.626809273262	133.039993286133	0.197674738111224
0.555911541395768	620.760884068536	133.440002441406	0.197655873329151
0.557578718803059	619.388210321729	133.839996337891	0.197687057968904
0.559243549570791	618.332936506059	134.240005493164	0.197651656711195
0.560910726978083	617.188364802104	134.639999389648	0.19768168636429
0.562575521079575	616.280237660373	135.039993286133	0.197660291611444
0.564245045126421	614.937201811338	135.440002441406	0.197670411494539
0.565912222533713	613.882257305645	135.839996337891	0.197662106590478
0.56757470666189	612.816061375798	136.240005493164	0.197660419943295
0.569241884069181	612.020558245601	136.639999389648	0.197674408115036
0.570909061476472	611.080707576255	137.039993286133	0.197659594952826
0.572578585523319	610.374227909366	137.440002441406	0.197677799742522
0.574245726264366	609.045023079291	137.839996337891	0.197652041706748
0.575910557032102	607.701822575266	138.240005493164	0.197673216462135
0.577577734439394	606.401048173053	138.639999389648	0.197657706641306
0.579244911846681	605.012073582472	139.039993286133	0.197664764893102
0.580914435893532	603.82809445148	139.440002441406	0.197669623170312
0.582579266661264	602.850428019976	139.839996337891	0.197635395232383
0.584244097428996	601.722541354766	140.240005493164	0.197689202944125
0.585908891530488	600.501624621551	140.639999389648	0.197645973443516
0.587578415577335	598.793438894965	141.039993286133	0.197680274713931
0.589245592984626	595.354180398517	141.440002441406	0.197656313324069
0.590912770391917	590.835224263234	141.839996337891	0.197666359874676
0.592575254520095	584.786568407949	142.240005493164	0.19766461822813
0.594244778566941	574.520769009693	142.639999389648	0.197656478322163
0.595914302613791	563.636525477929	143.039993286133	0.197668834846085
0.597583789994398	524.947982116388	143.440002441406	0.197654260014455
0.598908614689909	63.5946684266925	143.759994506836	0.197695766201639